{"type":"subscribed","id":1,"msg":{"channel":"orderbook_delta","sid":1}}
{"type":"orderbook_snapshot","sid":1,"seq":1,"msg":{"market_ticker":"KXBTCD-26SEP1417-T76999.99","market_id":"9fc30aa6-9f6f-4d2c-abca-fd27bae6f05b","yes_dollars_fp":[["0.0100","236781.00"],["0.0200","3400.01"],["0.0300","63559.01"],["0.0400","17655.01"],["0.0500","40.01"],["0.0600","0.01"],["0.0700","0.01"],["0.0800","3703.01"],["0.0900","19692.01"],["0.1000","725.01"],["0.1100","101.01"],["0.1200","0.01"],["0.1300","1847.01"],["0.1400","0.01"],["0.1500","1633.01"],["0.1600","1.01"],["0.1700","320.01"],["0.1800","5429.01"],["0.1900","1.01"],["0.2000","0.01"],["0.2100","1.01"],["0.2200","0.01"],["0.2300","0.01"],["0.2400","0.01"],["0.2500","103.01"],["0.2600","0.01"],["0.2700","2.01"],["0.2800","0.01"],["0.2900","50.01"],["0.3000","51.01"],["0.3100","50.01"],["0.3200","50.01"],["0.3300","52.01"],["0.3400","150.01"],["0.3500","154.01"],["0.3600","50.01"],["0.3700","5050.01"],["0.3800","694.01"],["0.3900","3340.00"],["0.4000","3323.00"]],"no_dollars_fp":[["0.0100","296098.88"],["0.0200","4761.01"],["0.0300","80660.01"],["0.0400","0.01"],["0.0500","0.01"],["0.0600","33030.01"],["0.0700","46.42"],["0.0800","22799.01"],["0.0900","19985.01"],["0.1000","0.01"],["0.1100","3957.01"],["0.1200","0.01"],["0.1300","0.01"],["0.1400","0.01"],["0.1500","157.99"],["0.1600","0.01"],["0.1700","5223.01"],["0.1800","7599.01"],["0.1900","967.01"],["0.2000","0.01"],["0.2100","0.01"],["0.2200","0.01"],["0.2300","315.01"],["0.2400","1.01"],["0.2500","77.57"],["0.2600","0.01"],["0.2700","2624.01"],["0.2800","0.01"],["0.2900","304.01"],["0.3000","1.01"],["0.3100","245.01"],["0.3200","1264.01"],["0.3300","3597.00"],["0.3400","464.29"],["0.3500","106.00"],["0.4100","1.00"],["0.4800","50.00"],["0.4900","50.00"],["0.5000","50.00"],["0.5100","50.00"],["0.5200","549.99"],["0.5300","50.00"],["0.5400","50.00"],["0.5500","402.00"],["0.5600","1534.00"],["0.5700","2002.00"],["0.5800","5000.00"],["0.5900","100.00"]]}}
{"type":"orderbook_delta","sid":1,"seq":2,"msg":{"market_ticker":"KXBTCD-26SEP1417-T76999.99","market_id":"9fc30aa6-9f6f-4d2c-abca-fd27bae6f05b","price_dollars":"0.3400","delta_fp":"-100.00","side":"yes","ts":"2026-09-13T23:28:35.869218Z","ts_ms":1789342115869}}
{"type":"orderbook_delta","sid":1,"seq":3,"msg":{"market_ticker":"KXBTCD-26SEP1417-T76999.99","market_id":"9fc30aa6-9f6f-4d2c-abca-fd27bae6f05b","price_dollars":"0.4000","delta_fp":"100.00","side":"yes","ts":"2026-09-13T23:28:35.869218Z","ts_ms":1789342115869}}
{"type":"orderbook_delta","sid":1,"seq":4,"msg":{"market_ticker":"KXBTCD-26SEP1417-T76999.99","market_id":"9fc30aa6-9f6f-4d2c-abca-fd27bae6f05b","price_dollars":"0.5900","delta_fp":"-100.00","side":"no","ts":"2026-09-13T23:28:35.869617Z","ts_ms":1789342115869}}
{"type":"orderbook_delta","sid":1,"seq":5,"msg":{"market_ticker":"KXBTCD-26SEP1417-T76999.99","market_id":"9fc30aa6-9f6f-4d2c-abca-fd27bae6f05b","price_dollars":"0.5400","delta_fp":"100.00","side":"no","ts":"2026-09-13T23:28:35.869617Z","ts_ms":1789342115869}}
{"type":"orderbook_delta","sid":1,"seq":6,"msg":{"market_ticker":"KXBTCD-26SEP1417-T76999.99","market_id":"9fc30aa6-9f6f-4d2c-abca-fd27bae6f05b","price_dollars":"0.4000","delta_fp":"-100.00","side":"yes","ts":"2026-09-13T23:28:35.876226Z","ts_ms":1789342115876}}
{"type":"orderbook_delta","sid":1,"seq":7,"msg":{"market_ticker":"KXBTCD-26SEP1417-T76999.99","market_id":"9fc30aa6-9f6f-4d2c-abca-fd27bae6f05b","price_dollars":"0.3400","delta_fp":"100.00","side":"yes","ts":"2026-09-13T23:28:35.876226Z","ts_ms":1789342115876}}
{"type":"orderbook_delta","sid":1,"seq":8,"msg":{"market_ticker":"KXBTCD-26SEP1417-T76999.99","market_id":"9fc30aa6-9f6f-4d2c-abca-fd27bae6f05b","price_dollars":"0.3400","delta_fp":"-100.00","side":"yes","ts":"2026-09-13T23:28:36.001417Z","ts_ms":1789342116001}}
{"type":"orderbook_delta","sid":1,"seq":9,"msg":{"market_ticker":"KXBTCD-26SEP1417-T76999.99","market_id":"9fc30aa6-9f6f-4d2c-abca-fd27bae6f05b","price_dollars":"0.4000","delta_fp":"100.00","side":"yes","ts":"2026-09-13T23:28:36.001417Z","ts_ms":1789342116001}}
{"type":"orderbook_delta","sid":1,"seq":10,"msg":{"market_ticker":"KXBTCD-26SEP1417-T76999.99","market_id":"9fc30aa6-9f6f-4d2c-abca-fd27bae6f05b","price_dollars":"0.5400","delta_fp":"-100.00","side":"no","ts":"2026-09-13T23:28:36.001822Z","ts_ms":1789342116001}}
{"type":"orderbook_delta","sid":1,"seq":11,"msg":{"market_ticker":"KXBTCD-26SEP1417-T76999.99","market_id":"9fc30aa6-9f6f-4d2c-abca-fd27bae6f05b","price_dollars":"0.5800","delta_fp":"100.00","side":"no","ts":"2026-09-13T23:28:36.001822Z","ts_ms":1789342116001}}
{"type":"orderbook_delta","sid":1,"seq":12,"msg":{"market_ticker":"KXBTCD-26SEP1417-T76999.99","market_id":"9fc30aa6-9f6f-4d2c-abca-fd27bae6f05b","price_dollars":"0.4000","delta_fp":"-100.00","side":"yes","ts":"2026-09-13T23:28:36.074427Z","ts_ms":1789342116074}}
{"type":"orderbook_delta","sid":1,"seq":13,"msg":{"market_ticker":"KXBTCD-26SEP1417-T76999.99","market_id":"9fc30aa6-9f6f-4d2c-abca-fd27bae6f05b","price_dollars":"0.3400","delta_fp":"100.00","side":"yes","ts":"2026-09-13T23:28:36.074427Z","ts_ms":1789342116074}}
{"type":"orderbook_delta","sid":1,"seq":14,"msg":{"market_ticker":"KXBTCD-26SEP1417-T76999.99","market_id":"9fc30aa6-9f6f-4d2c-abca-fd27bae6f05b","price_dollars":"0.4000","delta_fp":"-310.00","side":"yes","ts":"2026-09-13T23:28:36.085473Z","ts_ms":1789342116085}}
{"type":"orderbook_delta","sid":1,"seq":15,"msg":{"market_ticker":"KXBTCD-26SEP1417-T76999.99","market_id":"9fc30aa6-9f6f-4d2c-abca-fd27bae6f05b","price_dollars":"0.3700","delta_fp":"310.00","side":"yes","ts":"2026-09-13T23:28:36.085953Z","ts_ms":1789342116085}}
{"type":"orderbook_delta","sid":1,"seq":16,"msg":{"market_ticker":"KXBTCD-26SEP1417-T76999.99","market_id":"9fc30aa6-9f6f-4d2c-abca-fd27bae6f05b","price_dollars":"0.4000","delta_fp":"-3000.00","side":"yes","ts":"2026-09-13T23:28:36.092421Z","ts_ms":1789342116092}}
{"type":"orderbook_delta","sid":1,"seq":17,"msg":{"market_ticker":"KXBTCD-26SEP1417-T76999.99","market_id":"9fc30aa6-9f6f-4d2c-abca-fd27bae6f05b","price_dollars":"0.3900","delta_fp":"3000.00","side":"yes","ts":"2026-09-13T23:28:36.092421Z","ts_ms":1789342116092}}
{"type":"orderbook_delta","sid":1,"seq":18,"msg":{"market_ticker":"KXBTCD-26SEP1417-T76999.99","market_id":"9fc30aa6-9f6f-4d2c-abca-fd27bae6f05b","price_dollars":"0.3400","delta_fp":"-100.00","side":"yes","ts":"2026-09-13T23:28:38.021386Z","ts_ms":1789342118021}}
{"type":"orderbook_delta","sid":1,"seq":19,"msg":{"market_ticker":"KXBTCD-26SEP1417-T76999.99","market_id":"9fc30aa6-9f6f-4d2c-abca-fd27bae6f05b","price_dollars":"0.5800","delta_fp":"-100.00","side":"no","ts":"2026-09-13T23:28:38.022241Z","ts_ms":1789342118022}}
{"type":"orderbook_delta","sid":1,"seq":20,"msg":{"market_ticker":"KXBTCD-26SEP1417-T76999.99","market_id":"9fc30aa6-9f6f-4d2c-abca-fd27bae6f05b","price_dollars":"0.3400","delta_fp":"100.00","side":"yes","ts":"2026-09-13T23:28:38.033092Z","ts_ms":1789342118033}}
{"type":"orderbook_delta","sid":1,"seq":21,"msg":{"market_ticker":"KXBTCD-26SEP1417-T76999.99","market_id":"9fc30aa6-9f6f-4d2c-abca-fd27bae6f05b","price_dollars":"0.5800","delta_fp":"100.00","side":"no","ts":"2026-09-13T23:28:38.036231Z","ts_ms":1789342118036}}
{"type":"orderbook_delta","sid":1,"seq":22,"msg":{"market_ticker":"KXBTCD-26SEP1417-T76999.99","market_id":"9fc30aa6-9f6f-4d2c-abca-fd27bae6f05b","price_dollars":"0.3400","delta_fp":"-100.00","side":"yes","ts":"2026-09-13T23:28:39.718635Z","ts_ms":1789342119718}}
{"type":"orderbook_delta","sid":1,"seq":23,"msg":{"market_ticker":"KXBTCD-26SEP1417-T76999.99","market_id":"9fc30aa6-9f6f-4d2c-abca-fd27bae6f05b","price_dollars":"0.5800","delta_fp":"-100.00","side":"no","ts":"2026-09-13T23:28:39.719619Z","ts_ms":1789342119719}}
{"type":"orderbook_delta","sid":1,"seq":24,"msg":{"market_ticker":"KXBTCD-26SEP1417-T76999.99","market_id":"9fc30aa6-9f6f-4d2c-abca-fd27bae6f05b","price_dollars":"0.3400","delta_fp":"100.00","side":"yes","ts":"2026-09-13T23:28:39.728551Z","ts_ms":1789342119728}}
{"type":"orderbook_delta","sid":1,"seq":25,"msg":{"market_ticker":"KXBTCD-26SEP1417-T76999.99","market_id":"9fc30aa6-9f6f-4d2c-abca-fd27bae6f05b","price_dollars":"0.5800","delta_fp":"100.00","side":"no","ts":"2026-09-13T23:28:39.729309Z","ts_ms":1789342119729}}
{"type":"orderbook_delta","sid":1,"seq":26,"msg":{"market_ticker":"KXBTCD-26SEP1417-T76999.99","market_id":"9fc30aa6-9f6f-4d2c-abca-fd27bae6f05b","price_dollars":"0.3700","delta_fp":"-310.00","side":"yes","ts":"2026-09-13T23:28:39.735906Z","ts_ms":1789342119735}}
{"type":"orderbook_delta","sid":1,"seq":27,"msg":{"market_ticker":"KXBTCD-26SEP1417-T76999.99","market_id":"9fc30aa6-9f6f-4d2c-abca-fd27bae6f05b","price_dollars":"0.4000","delta_fp":"310.00","side":"yes","ts":"2026-09-13T23:28:39.735963Z","ts_ms":1789342119735}}
{"type":"orderbook_delta","sid":1,"seq":28,"msg":{"market_ticker":"KXBTCD-26SEP1417-T76999.99","market_id":"9fc30aa6-9f6f-4d2c-abca-fd27bae6f05b","price_dollars":"0.3900","delta_fp":"-3000.00","side":"yes","ts":"2026-09-13T23:28:39.744804Z","ts_ms":1789342119744}}
{"type":"orderbook_delta","sid":1,"seq":29,"msg":{"market_ticker":"KXBTCD-26SEP1417-T76999.99","market_id":"9fc30aa6-9f6f-4d2c-abca-fd27bae6f05b","price_dollars":"0.4000","delta_fp":"3000.00","side":"yes","ts":"2026-09-13T23:28:39.744804Z","ts_ms":1789342119744}}
{"type":"orderbook_delta","sid":1,"seq":30,"msg":{"market_ticker":"KXBTCD-26SEP1417-T76999.99","market_id":"9fc30aa6-9f6f-4d2c-abca-fd27bae6f05b","price_dollars":"0.3400","delta_fp":"-100.00","side":"yes","ts":"2026-09-13T23:28:40.923655Z","ts_ms":1789342120923}}
{"type":"orderbook_delta","sid":1,"seq":31,"msg":{"market_ticker":"KXBTCD-26SEP1417-T76999.99","market_id":"9fc30aa6-9f6f-4d2c-abca-fd27bae6f05b","price_dollars":"0.4000","delta_fp":"100.00","side":"yes","ts":"2026-09-13T23:28:40.923655Z","ts_ms":1789342120923}}
{"type":"orderbook_delta","sid":1,"seq":32,"msg":{"market_ticker":"KXBTCD-26SEP1417-T76999.99","market_id":"9fc30aa6-9f6f-4d2c-abca-fd27bae6f05b","price_dollars":"0.4000","delta_fp":"-100.00","side":"yes","ts":"2026-09-13T23:28:41.927118Z","ts_ms":1789342121927}}
{"type":"orderbook_delta","sid":1,"seq":33,"msg":{"market_ticker":"KXBTCD-26SEP1417-T76999.99","market_id":"9fc30aa6-9f6f-4d2c-abca-fd27bae6f05b","price_dollars":"0.3400","delta_fp":"100.00","side":"yes","ts":"2026-09-13T23:28:41.927118Z","ts_ms":1789342121927}}
{"type":"orderbook_delta","sid":1,"seq":34,"msg":{"market_ticker":"KXBTCD-26SEP1417-T76999.99","market_id":"9fc30aa6-9f6f-4d2c-abca-fd27bae6f05b","price_dollars":"0.5800","delta_fp":"-100.00","side":"no","ts":"2026-09-13T23:28:41.92772Z","ts_ms":1789342121927}}
{"type":"orderbook_delta","sid":1,"seq":35,"msg":{"market_ticker":"KXBTCD-26SEP1417-T76999.99","market_id":"9fc30aa6-9f6f-4d2c-abca-fd27bae6f05b","price_dollars":"0.5900","delta_fp":"100.00","side":"no","ts":"2026-09-13T23:28:41.92772Z","ts_ms":1789342121927}}
{"type":"orderbook_delta","sid":1,"seq":36,"msg":{"market_ticker":"KXBTCD-26SEP1417-T76999.99","market_id":"9fc30aa6-9f6f-4d2c-abca-fd27bae6f05b","price_dollars":"0.5900","delta_fp":"-100.00","side":"no","ts":"2026-09-13T23:28:41.934176Z","ts_ms":1789342121934}}
{"type":"orderbook_delta","sid":1,"seq":37,"msg":{"market_ticker":"KXBTCD-26SEP1417-T76999.99","market_id":"9fc30aa6-9f6f-4d2c-abca-fd27bae6f05b","price_dollars":"0.5800","delta_fp":"100.00","side":"no","ts":"2026-09-13T23:28:41.934176Z","ts_ms":1789342121934}}
{"type":"orderbook_delta","sid":1,"seq":38,"msg":{"market_ticker":"KXBTCD-26SEP1417-T76999.99","market_id":"9fc30aa6-9f6f-4d2c-abca-fd27bae6f05b","price_dollars":"0.3400","delta_fp":"-100.00","side":"yes","ts":"2026-09-13T23:28:42.033266Z","ts_ms":1789342122033}}
{"type":"orderbook_delta","sid":1,"seq":39,"msg":{"market_ticker":"KXBTCD-26SEP1417-T76999.99","market_id":"9fc30aa6-9f6f-4d2c-abca-fd27bae6f05b","price_dollars":"0.4000","delta_fp":"100.00","side":"yes","ts":"2026-09-13T23:28:42.033266Z","ts_ms":1789342122033}}
{"type":"orderbook_delta","sid":1,"seq":40,"msg":{"market_ticker":"KXBTCD-26SEP1417-T76999.99","market_id":"9fc30aa6-9f6f-4d2c-abca-fd27bae6f05b","price_dollars":"0.4000","delta_fp":"-100.00","side":"yes","ts":"2026-09-13T23:28:42.06743Z","ts_ms":1789342122067}}
{"type":"orderbook_delta","sid":1,"seq":41,"msg":{"market_ticker":"KXBTCD-26SEP1417-T76999.99","market_id":"9fc30aa6-9f6f-4d2c-abca-fd27bae6f05b","price_dollars":"0.3400","delta_fp":"100.00","side":"yes","ts":"2026-09-13T23:28:42.06743Z","ts_ms":1789342122067}}
{"type":"orderbook_delta","sid":1,"seq":42,"msg":{"market_ticker":"KXBTCD-26SEP1417-T76999.99","market_id":"9fc30aa6-9f6f-4d2c-abca-fd27bae6f05b","price_dollars":"0.5800","delta_fp":"-100.00","side":"no","ts":"2026-09-13T23:28:42.068069Z","ts_ms":1789342122068}}
{"type":"orderbook_delta","sid":1,"seq":43,"msg":{"market_ticker":"KXBTCD-26SEP1417-T76999.99","market_id":"9fc30aa6-9f6f-4d2c-abca-fd27bae6f05b","price_dollars":"0.5900","delta_fp":"100.00","side":"no","ts":"2026-09-13T23:28:42.068069Z","ts_ms":1789342122068}}
{"type":"orderbook_delta","sid":1,"seq":44,"msg":{"market_ticker":"KXBTCD-26SEP1417-T76999.99","market_id":"9fc30aa6-9f6f-4d2c-abca-fd27bae6f05b","price_dollars":"0.3400","delta_fp":"-100.00","side":"yes","ts":"2026-09-13T23:28:42.294095Z","ts_ms":1789342122294}}
{"type":"orderbook_delta","sid":1,"seq":45,"msg":{"market_ticker":"KXBTCD-26SEP1417-T76999.99","market_id":"9fc30aa6-9f6f-4d2c-abca-fd27bae6f05b","price_dollars":"0.4000","delta_fp":"100.00","side":"yes","ts":"2026-09-13T23:28:42.294095Z","ts_ms":1789342122294}}
{"type":"orderbook_delta","sid":1,"seq":46,"msg":{"market_ticker":"KXBTCD-26SEP1417-T76999.99","market_id":"9fc30aa6-9f6f-4d2c-abca-fd27bae6f05b","price_dollars":"0.5900","delta_fp":"-100.00","side":"no","ts":"2026-09-13T23:28:42.294528Z","ts_ms":1789342122294}}
{"type":"orderbook_delta","sid":1,"seq":47,"msg":{"market_ticker":"KXBTCD-26SEP1417-T76999.99","market_id":"9fc30aa6-9f6f-4d2c-abca-fd27bae6f05b","price_dollars":"0.5400","delta_fp":"100.00","side":"no","ts":"2026-09-13T23:28:42.294528Z","ts_ms":1789342122294}}
{"type":"orderbook_delta","sid":1,"seq":48,"msg":{"market_ticker":"KXBTCD-26SEP1417-T76999.99","market_id":"9fc30aa6-9f6f-4d2c-abca-fd27bae6f05b","price_dollars":"0.4000","delta_fp":"-100.00","side":"yes","ts":"2026-09-13T23:28:42.332621Z","ts_ms":1789342122332}}
{"type":"orderbook_delta","sid":1,"seq":49,"msg":{"market_ticker":"KXBTCD-26SEP1417-T76999.99","market_id":"9fc30aa6-9f6f-4d2c-abca-fd27bae6f05b","price_dollars":"0.3400","delta_fp":"100.00","side":"yes","ts":"2026-09-13T23:28:42.332621Z","ts_ms":1789342122332}}
{"type":"orderbook_delta","sid":1,"seq":50,"msg":{"market_ticker":"KXBTCD-26SEP1417-T76999.99","market_id":"9fc30aa6-9f6f-4d2c-abca-fd27bae6f05b","price_dollars":"0.5400","delta_fp":"-100.00","side":"no","ts":"2026-09-13T23:28:42.404358Z","ts_ms":1789342122404}}
{"type":"orderbook_delta","sid":1,"seq":51,"msg":{"market_ticker":"KXBTCD-26SEP1417-T76999.99","market_id":"9fc30aa6-9f6f-4d2c-abca-fd27bae6f05b","price_dollars":"0.5900","delta_fp":"100.00","side":"no","ts":"2026-09-13T23:28:42.404358Z","ts_ms":1789342122404}}
{"type":"orderbook_delta","sid":1,"seq":52,"msg":{"market_ticker":"KXBTCD-26SEP1417-T76999.99","market_id":"9fc30aa6-9f6f-4d2c-abca-fd27bae6f05b","price_dollars":"0.3400","delta_fp":"-100.00","side":"yes","ts":"2026-09-13T23:28:42.861138Z","ts_ms":1789342122861}}
{"type":"orderbook_delta","sid":1,"seq":53,"msg":{"market_ticker":"KXBTCD-26SEP1417-T76999.99","market_id":"9fc30aa6-9f6f-4d2c-abca-fd27bae6f05b","price_dollars":"0.4000","delta_fp":"100.00","side":"yes","ts":"2026-09-13T23:28:42.861138Z","ts_ms":1789342122861}}
{"type":"orderbook_delta","sid":1,"seq":54,"msg":{"market_ticker":"KXBTCD-26SEP1417-T76999.99","market_id":"9fc30aa6-9f6f-4d2c-abca-fd27bae6f05b","price_dollars":"0.5900","delta_fp":"-100.00","side":"no","ts":"2026-09-13T23:28:42.861769Z","ts_ms":1789342122861}}
{"type":"orderbook_delta","sid":1,"seq":55,"msg":{"market_ticker":"KXBTCD-26SEP1417-T76999.99","market_id":"9fc30aa6-9f6f-4d2c-abca-fd27bae6f05b","price_dollars":"0.5400","delta_fp":"100.00","side":"no","ts":"2026-09-13T23:28:42.861769Z","ts_ms":1789342122861}}
{"type":"orderbook_delta","sid":1,"seq":56,"msg":{"market_ticker":"KXBTCD-26SEP1417-T76999.99","market_id":"9fc30aa6-9f6f-4d2c-abca-fd27bae6f05b","price_dollars":"0.4000","delta_fp":"-100.00","side":"yes","ts":"2026-09-13T23:28:42.878216Z","ts_ms":1789342122878}}
{"type":"orderbook_delta","sid":1,"seq":57,"msg":{"market_ticker":"KXBTCD-26SEP1417-T76999.99","market_id":"9fc30aa6-9f6f-4d2c-abca-fd27bae6f05b","price_dollars":"0.3400","delta_fp":"100.00","side":"yes","ts":"2026-09-13T23:28:42.878216Z","ts_ms":1789342122878}}
{"type":"orderbook_delta","sid":1,"seq":58,"msg":{"market_ticker":"KXBTCD-26SEP1417-T76999.99","market_id":"9fc30aa6-9f6f-4d2c-abca-fd27bae6f05b","price_dollars":"0.5400","delta_fp":"-100.00","side":"no","ts":"2026-09-13T23:28:42.990669Z","ts_ms":1789342122990}}
{"type":"orderbook_delta","sid":1,"seq":59,"msg":{"market_ticker":"KXBTCD-26SEP1417-T76999.99","market_id":"9fc30aa6-9f6f-4d2c-abca-fd27bae6f05b","price_dollars":"0.5900","delta_fp":"100.00","side":"no","ts":"2026-09-13T23:28:42.990669Z","ts_ms":1789342122990}}
{"type":"orderbook_delta","sid":1,"seq":60,"msg":{"market_ticker":"KXBTCD-26SEP1417-T76999.99","market_id":"9fc30aa6-9f6f-4d2c-abca-fd27bae6f05b","price_dollars":"0.3400","delta_fp":"-100.00","side":"yes","ts":"2026-09-13T23:28:43.150942Z","ts_ms":1789342123150}}
{"type":"orderbook_delta","sid":1,"seq":61,"msg":{"market_ticker":"KXBTCD-26SEP1417-T76999.99","market_id":"9fc30aa6-9f6f-4d2c-abca-fd27bae6f05b","price_dollars":"0.4000","delta_fp":"100.00","side":"yes","ts":"2026-09-13T23:28:43.150942Z","ts_ms":1789342123150}}
{"type":"orderbook_delta","sid":1,"seq":62,"msg":{"market_ticker":"KXBTCD-26SEP1417-T76999.99","market_id":"9fc30aa6-9f6f-4d2c-abca-fd27bae6f05b","price_dollars":"0.5900","delta_fp":"-100.00","side":"no","ts":"2026-09-13T23:28:43.151523Z","ts_ms":1789342123151}}
{"type":"orderbook_delta","sid":1,"seq":63,"msg":{"market_ticker":"KXBTCD-26SEP1417-T76999.99","market_id":"9fc30aa6-9f6f-4d2c-abca-fd27bae6f05b","price_dollars":"0.5400","delta_fp":"100.00","side":"no","ts":"2026-09-13T23:28:43.151523Z","ts_ms":1789342123151}}
{"type":"orderbook_delta","sid":1,"seq":64,"msg":{"market_ticker":"KXBTCD-26SEP1417-T76999.99","market_id":"9fc30aa6-9f6f-4d2c-abca-fd27bae6f05b","price_dollars":"0.4000","delta_fp":"-100.00","side":"yes","ts":"2026-09-13T23:28:43.215553Z","ts_ms":1789342123215}}
{"type":"orderbook_delta","sid":1,"seq":65,"msg":{"market_ticker":"KXBTCD-26SEP1417-T76999.99","market_id":"9fc30aa6-9f6f-4d2c-abca-fd27bae6f05b","price_dollars":"0.3400","delta_fp":"100.00","side":"yes","ts":"2026-09-13T23:28:43.215553Z","ts_ms":1789342123215}}
{"type":"orderbook_delta","sid":1,"seq":66,"msg":{"market_ticker":"KXBTCD-26SEP1417-T76999.99","market_id":"9fc30aa6-9f6f-4d2c-abca-fd27bae6f05b","price_dollars":"0.5400","delta_fp":"-100.00","side":"no","ts":"2026-09-13T23:28:43.266008Z","ts_ms":1789342123266}}
{"type":"orderbook_delta","sid":1,"seq":67,"msg":{"market_ticker":"KXBTCD-26SEP1417-T76999.99","market_id":"9fc30aa6-9f6f-4d2c-abca-fd27bae6f05b","price_dollars":"0.5900","delta_fp":"100.00","side":"no","ts":"2026-09-13T23:28:43.266008Z","ts_ms":1789342123266}}
{"type":"orderbook_delta","sid":1,"seq":68,"msg":{"market_ticker":"KXBTCD-26SEP1417-T76999.99","market_id":"9fc30aa6-9f6f-4d2c-abca-fd27bae6f05b","price_dollars":"0.5900","delta_fp":"-100.00","side":"no","ts":"2026-09-13T23:28:43.308999Z","ts_ms":1789342123308}}
{"type":"orderbook_delta","sid":1,"seq":69,"msg":{"market_ticker":"KXBTCD-26SEP1417-T76999.99","market_id":"9fc30aa6-9f6f-4d2c-abca-fd27bae6f05b","price_dollars":"0.5400","delta_fp":"100.00","side":"no","ts":"2026-09-13T23:28:43.308999Z","ts_ms":1789342123308}}
{"type":"orderbook_delta","sid":1,"seq":70,"msg":{"market_ticker":"KXBTCD-26SEP1417-T76999.99","market_id":"9fc30aa6-9f6f-4d2c-abca-fd27bae6f05b","price_dollars":"0.3400","delta_fp":"-100.00","side":"yes","ts":"2026-09-13T23:28:43.31712Z","ts_ms":1789342123317}}
{"type":"orderbook_delta","sid":1,"seq":71,"msg":{"market_ticker":"KXBTCD-26SEP1417-T76999.99","market_id":"9fc30aa6-9f6f-4d2c-abca-fd27bae6f05b","price_dollars":"0.4000","delta_fp":"100.00","side":"yes","ts":"2026-09-13T23:28:43.31712Z","ts_ms":1789342123317}}
{"type":"orderbook_delta","sid":1,"seq":72,"msg":{"market_ticker":"KXBTCD-26SEP1417-T76999.99","market_id":"9fc30aa6-9f6f-4d2c-abca-fd27bae6f05b","price_dollars":"0.5400","delta_fp":"-100.00","side":"no","ts":"2026-09-13T23:28:43.426869Z","ts_ms":1789342123426}}
{"type":"orderbook_delta","sid":1,"seq":73,"msg":{"market_ticker":"KXBTCD-26SEP1417-T76999.99","market_id":"9fc30aa6-9f6f-4d2c-abca-fd27bae6f05b","price_dollars":"0.5800","delta_fp":"100.00","side":"no","ts":"2026-09-13T23:28:43.426869Z","ts_ms":1789342123426}}
{"type":"orderbook_delta","sid":1,"seq":74,"msg":{"market_ticker":"KXBTCD-26SEP1417-T76999.99","market_id":"9fc30aa6-9f6f-4d2c-abca-fd27bae6f05b","price_dollars":"0.4000","delta_fp":"-100.00","side":"yes","ts":"2026-09-13T23:28:43.593715Z","ts_ms":1789342123593}}
{"type":"orderbook_delta","sid":1,"seq":75,"msg":{"market_ticker":"KXBTCD-26SEP1417-T76999.99","market_id":"9fc30aa6-9f6f-4d2c-abca-fd27bae6f05b","price_dollars":"0.3400","delta_fp":"100.00","side":"yes","ts":"2026-09-13T23:28:43.593715Z","ts_ms":1789342123593}}
{"type":"orderbook_delta","sid":1,"seq":76,"msg":{"market_ticker":"KXBTCD-26SEP1417-T76999.99","market_id":"9fc30aa6-9f6f-4d2c-abca-fd27bae6f05b","price_dollars":"0.5800","delta_fp":"-100.00","side":"no","ts":"2026-09-13T23:28:43.594331Z","ts_ms":1789342123594}}
{"type":"orderbook_delta","sid":1,"seq":77,"msg":{"market_ticker":"KXBTCD-26SEP1417-T76999.99","market_id":"9fc30aa6-9f6f-4d2c-abca-fd27bae6f05b","price_dollars":"0.5900","delta_fp":"100.00","side":"no","ts":"2026-09-13T23:28:43.594331Z","ts_ms":1789342123594}}
{"type":"orderbook_delta","sid":1,"seq":78,"msg":{"market_ticker":"KXBTCD-26SEP1417-T76999.99","market_id":"9fc30aa6-9f6f-4d2c-abca-fd27bae6f05b","price_dollars":"0.5900","delta_fp":"-100.00","side":"no","ts":"2026-09-13T23:28:43.600686Z","ts_ms":1789342123600}}
{"type":"orderbook_delta","sid":1,"seq":79,"msg":{"market_ticker":"KXBTCD-26SEP1417-T76999.99","market_id":"9fc30aa6-9f6f-4d2c-abca-fd27bae6f05b","price_dollars":"0.5800","delta_fp":"100.00","side":"no","ts":"2026-09-13T23:28:43.600686Z","ts_ms":1789342123600}}
{"type":"orderbook_delta","sid":1,"seq":80,"msg":{"market_ticker":"KXBTCD-26SEP1417-T76999.99","market_id":"9fc30aa6-9f6f-4d2c-abca-fd27bae6f05b","price_dollars":"0.3400","delta_fp":"-100.00","side":"yes","ts":"2026-09-13T23:28:43.695952Z","ts_ms":1789342123695}}
{"type":"orderbook_delta","sid":1,"seq":81,"msg":{"market_ticker":"KXBTCD-26SEP1417-T76999.99","market_id":"9fc30aa6-9f6f-4d2c-abca-fd27bae6f05b","price_dollars":"0.4000","delta_fp":"100.00","side":"yes","ts":"2026-09-13T23:28:43.695952Z","ts_ms":1789342123695}}
{"type":"orderbook_delta","sid":1,"seq":82,"msg":{"market_ticker":"KXBTCD-26SEP1417-T76999.99","market_id":"9fc30aa6-9f6f-4d2c-abca-fd27bae6f05b","price_dollars":"0.4000","delta_fp":"-100.00","side":"yes","ts":"2026-09-13T23:28:43.983695Z","ts_ms":1789342123983}}
{"type":"orderbook_delta","sid":1,"seq":83,"msg":{"market_ticker":"KXBTCD-26SEP1417-T76999.99","market_id":"9fc30aa6-9f6f-4d2c-abca-fd27bae6f05b","price_dollars":"0.3400","delta_fp":"100.00","side":"yes","ts":"2026-09-13T23:28:43.983695Z","ts_ms":1789342123983}}
{"type":"orderbook_delta","sid":1,"seq":84,"msg":{"market_ticker":"KXBTCD-26SEP1417-T76999.99","market_id":"9fc30aa6-9f6f-4d2c-abca-fd27bae6f05b","price_dollars":"0.5800","delta_fp":"-100.00","side":"no","ts":"2026-09-13T23:28:43.984319Z","ts_ms":1789342123984}}
{"type":"orderbook_delta","sid":1,"seq":85,"msg":{"market_ticker":"KXBTCD-26SEP1417-T76999.99","market_id":"9fc30aa6-9f6f-4d2c-abca-fd27bae6f05b","price_dollars":"0.5900","delta_fp":"100.00","side":"no","ts":"2026-09-13T23:28:43.984319Z","ts_ms":1789342123984}}
{"type":"orderbook_delta","sid":1,"seq":86,"msg":{"market_ticker":"KXBTCD-26SEP1417-T76999.99","market_id":"9fc30aa6-9f6f-4d2c-abca-fd27bae6f05b","price_dollars":"0.4000","delta_fp":"-3000.00","side":"yes","ts":"2026-09-13T23:28:44.060168Z","ts_ms":1789342124060}}
{"type":"orderbook_delta","sid":1,"seq":87,"msg":{"market_ticker":"KXBTCD-26SEP1417-T76999.99","market_id":"9fc30aa6-9f6f-4d2c-abca-fd27bae6f05b","price_dollars":"0.3900","delta_fp":"3000.00","side":"yes","ts":"2026-09-13T23:28:44.060168Z","ts_ms":1789342124060}}
{"type":"orderbook_delta","sid":1,"seq":88,"msg":{"market_ticker":"KXBTCD-26SEP1417-T76999.99","market_id":"9fc30aa6-9f6f-4d2c-abca-fd27bae6f05b","price_dollars":"0.4000","delta_fp":"-310.00","side":"yes","ts":"2026-09-13T23:28:44.915832Z","ts_ms":1789342124915}}
{"type":"orderbook_delta","sid":1,"seq":89,"msg":{"market_ticker":"KXBTCD-26SEP1417-T76999.99","market_id":"9fc30aa6-9f6f-4d2c-abca-fd27bae6f05b","price_dollars":"0.3900","delta_fp":"-310.00","side":"yes","ts":"2026-09-13T23:28:44.916248Z","ts_ms":1789342124916}}
{"type":"orderbook_delta","sid":1,"seq":90,"msg":{"market_ticker":"KXBTCD-26SEP1417-T76999.99","market_id":"9fc30aa6-9f6f-4d2c-abca-fd27bae6f05b","price_dollars":"0.3800","delta_fp":"-310.00","side":"yes","ts":"2026-09-13T23:28:44.916711Z","ts_ms":1789342124916}}
{"type":"orderbook_delta","sid":1,"seq":91,"msg":{"market_ticker":"KXBTCD-26SEP1417-T76999.99","market_id":"9fc30aa6-9f6f-4d2c-abca-fd27bae6f05b","price_dollars":"0.5900","delta_fp":"-100.00","side":"no","ts":"2026-09-13T23:28:44.921733Z","ts_ms":1789342124921}}
{"type":"orderbook_delta","sid":1,"seq":92,"msg":{"market_ticker":"KXBTCD-26SEP1417-T76999.99","market_id":"9fc30aa6-9f6f-4d2c-abca-fd27bae6f05b","price_dollars":"0.5400","delta_fp":"100.00","side":"no","ts":"2026-09-13T23:28:44.921733Z","ts_ms":1789342124921}}
{"type":"orderbook_delta","sid":1,"seq":93,"msg":{"market_ticker":"KXBTCD-26SEP1417-T76999.99","market_id":"9fc30aa6-9f6f-4d2c-abca-fd27bae6f05b","price_dollars":"0.4000","delta_fp":"-11.00","side":"yes","ts":"2026-09-13T23:28:44.92884Z","ts_ms":1789342124928}}
{"type":"orderbook_delta","sid":1,"seq":94,"msg":{"market_ticker":"KXBTCD-26SEP1417-T76999.99","market_id":"9fc30aa6-9f6f-4d2c-abca-fd27bae6f05b","price_dollars":"0.3800","delta_fp":"11.00","side":"yes","ts":"2026-09-13T23:28:44.92884Z","ts_ms":1789342124928}}
{"type":"orderbook_delta","sid":1,"seq":95,"msg":{"market_ticker":"KXBTCD-26SEP1417-T76999.99","market_id":"9fc30aa6-9f6f-4d2c-abca-fd27bae6f05b","price_dollars":"0.5400","delta_fp":"-100.00","side":"no","ts":"2026-09-13T23:28:45.025663Z","ts_ms":1789342125025}}
{"type":"orderbook_delta","sid":1,"seq":96,"msg":{"market_ticker":"KXBTCD-26SEP1417-T76999.99","market_id":"9fc30aa6-9f6f-4d2c-abca-fd27bae6f05b","price_dollars":"0.5800","delta_fp":"100.00","side":"no","ts":"2026-09-13T23:28:45.025663Z","ts_ms":1789342125025}}
{"type":"orderbook_delta","sid":1,"seq":97,"msg":{"market_ticker":"KXBTCD-26SEP1417-T76999.99","market_id":"9fc30aa6-9f6f-4d2c-abca-fd27bae6f05b","price_dollars":"0.3900","delta_fp":"310.00","side":"yes","ts":"2026-09-13T23:28:45.056021Z","ts_ms":1789342125056}}
{"type":"orderbook_delta","sid":1,"seq":98,"msg":{"market_ticker":"KXBTCD-26SEP1417-T76999.99","market_id":"9fc30aa6-9f6f-4d2c-abca-fd27bae6f05b","price_dollars":"0.3800","delta_fp":"310.00","side":"yes","ts":"2026-09-13T23:28:45.056635Z","ts_ms":1789342125056}}
{"type":"orderbook_delta","sid":1,"seq":99,"msg":{"market_ticker":"KXBTCD-26SEP1417-T76999.99","market_id":"9fc30aa6-9f6f-4d2c-abca-fd27bae6f05b","price_dollars":"0.3700","delta_fp":"310.00","side":"yes","ts":"2026-09-13T23:28:45.057647Z","ts_ms":1789342125057}}
{"type":"orderbook_delta","sid":1,"seq":100,"msg":{"market_ticker":"KXBTCD-26SEP1417-T76999.99","market_id":"9fc30aa6-9f6f-4d2c-abca-fd27bae6f05b","price_dollars":"0.3800","delta_fp":"-11.00","side":"yes","ts":"2026-09-13T23:28:45.062486Z","ts_ms":1789342125062}}
{"type":"orderbook_delta","sid":1,"seq":101,"msg":{"market_ticker":"KXBTCD-26SEP1417-T76999.99","market_id":"9fc30aa6-9f6f-4d2c-abca-fd27bae6f05b","price_dollars":"0.4000","delta_fp":"-2.00","side":"yes","ts":"2026-09-13T23:28:45.062812Z","ts_ms":1789342125062}}
{"type":"orderbook_delta","sid":1,"seq":102,"msg":{"market_ticker":"KXBTCD-26SEP1417-T76999.99","market_id":"9fc30aa6-9f6f-4d2c-abca-fd27bae6f05b","price_dollars":"0.3900","delta_fp":"2.00","side":"yes","ts":"2026-09-13T23:28:45.063222Z","ts_ms":1789342125063}}
{"type":"orderbook_delta","sid":1,"seq":103,"msg":{"market_ticker":"KXBTCD-26SEP1417-T76999.99","market_id":"9fc30aa6-9f6f-4d2c-abca-fd27bae6f05b","price_dollars":"0.5700","delta_fp":"-2.00","side":"no","ts":"2026-09-13T23:28:45.063632Z","ts_ms":1789342125063}}
{"type":"orderbook_delta","sid":1,"seq":104,"msg":{"market_ticker":"KXBTCD-26SEP1417-T76999.99","market_id":"9fc30aa6-9f6f-4d2c-abca-fd27bae6f05b","price_dollars":"0.5800","delta_fp":"2.00","side":"no","ts":"2026-09-13T23:28:45.06426Z","ts_ms":1789342125064}}
{"type":"orderbook_delta","sid":1,"seq":105,"msg":{"market_ticker":"KXBTCD-26SEP1417-T76999.99","market_id":"9fc30aa6-9f6f-4d2c-abca-fd27bae6f05b","price_dollars":"0.3400","delta_fp":"-100.00","side":"yes","ts":"2026-09-13T23:28:45.069834Z","ts_ms":1789342125069}}
{"type":"orderbook_delta","sid":1,"seq":106,"msg":{"market_ticker":"KXBTCD-26SEP1417-T76999.99","market_id":"9fc30aa6-9f6f-4d2c-abca-fd27bae6f05b","price_dollars":"0.3900","delta_fp":"100.00","side":"yes","ts":"2026-09-13T23:28:45.069834Z","ts_ms":1789342125069}}
{"type":"orderbook_delta","sid":1,"seq":107,"msg":{"market_ticker":"KXBTCD-26SEP1417-T76999.99","market_id":"9fc30aa6-9f6f-4d2c-abca-fd27bae6f05b","price_dollars":"0.3900","delta_fp":"-310.00","side":"yes","ts":"2026-09-13T23:28:45.251042Z","ts_ms":1789342125251}}
{"type":"orderbook_delta","sid":1,"seq":108,"msg":{"market_ticker":"KXBTCD-26SEP1417-T76999.99","market_id":"9fc30aa6-9f6f-4d2c-abca-fd27bae6f05b","price_dollars":"0.3800","delta_fp":"-310.00","side":"yes","ts":"2026-09-13T23:28:45.251455Z","ts_ms":1789342125251}}
{"type":"orderbook_delta","sid":1,"seq":109,"msg":{"market_ticker":"KXBTCD-26SEP1417-T76999.99","market_id":"9fc30aa6-9f6f-4d2c-abca-fd27bae6f05b","price_dollars":"0.3700","delta_fp":"-310.00","side":"yes","ts":"2026-09-13T23:28:45.251863Z","ts_ms":1789342125251}}
{"type":"orderbook_delta","sid":1,"seq":110,"msg":{"market_ticker":"KXBTCD-26SEP1417-T76999.99","market_id":"9fc30aa6-9f6f-4d2c-abca-fd27bae6f05b","price_dollars":"0.3900","delta_fp":"-100.00","side":"yes","ts":"2026-09-13T23:28:49.787876Z","ts_ms":1789342129787}}
{"type":"orderbook_delta","sid":1,"seq":111,"msg":{"market_ticker":"KXBTCD-26SEP1417-T76999.99","market_id":"9fc30aa6-9f6f-4d2c-abca-fd27bae6f05b","price_dollars":"0.5800","delta_fp":"-100.00","side":"no","ts":"2026-09-13T23:28:49.788751Z","ts_ms":1789342129788}}
{"type":"orderbook_delta","sid":1,"seq":112,"msg":{"market_ticker":"KXBTCD-26SEP1417-T76999.99","market_id":"9fc30aa6-9f6f-4d2c-abca-fd27bae6f05b","price_dollars":"0.3900","delta_fp":"100.00","side":"yes","ts":"2026-09-13T23:28:49.797122Z","ts_ms":1789342129797}}
{"type":"orderbook_delta","sid":1,"seq":113,"msg":{"market_ticker":"KXBTCD-26SEP1417-T76999.99","market_id":"9fc30aa6-9f6f-4d2c-abca-fd27bae6f05b","price_dollars":"0.5800","delta_fp":"100.00","side":"no","ts":"2026-09-13T23:28:49.798576Z","ts_ms":1789342129798}}
{"type":"orderbook_delta","sid":1,"seq":114,"msg":{"market_ticker":"KXBTCD-26SEP1417-T76999.99","market_id":"9fc30aa6-9f6f-4d2c-abca-fd27bae6f05b","price_dollars":"0.5800","delta_fp":"-2.00","side":"no","ts":"2026-09-13T23:28:53.083713Z","ts_ms":1789342133083}}
{"type":"orderbook_delta","sid":1,"seq":115,"msg":{"market_ticker":"KXBTCD-26SEP1417-T76999.99","market_id":"9fc30aa6-9f6f-4d2c-abca-fd27bae6f05b","price_dollars":"0.5700","delta_fp":"2.00","side":"no","ts":"2026-09-13T23:28:53.084117Z","ts_ms":1789342133084}}
{"type":"orderbook_delta","sid":1,"seq":116,"msg":{"market_ticker":"KXBTCD-26SEP1417-T76999.99","market_id":"9fc30aa6-9f6f-4d2c-abca-fd27bae6f05b","price_dollars":"0.0100","delta_fp":"-182397.00","side":"yes","ts":"2026-09-13T23:28:56.000402Z","ts_ms":1789342136000}}
{"type":"orderbook_delta","sid":1,"seq":117,"msg":{"market_ticker":"KXBTCD-26SEP1417-T76999.99","market_id":"9fc30aa6-9f6f-4d2c-abca-fd27bae6f05b","price_dollars":"0.0100","delta_fp":"182397.00","side":"yes","ts":"2026-09-13T23:28:56.179673Z","ts_ms":1789342136179}}
{"type":"orderbook_delta","sid":1,"seq":118,"msg":{"market_ticker":"KXBTCD-26SEP1417-T76999.99","market_id":"9fc30aa6-9f6f-4d2c-abca-fd27bae6f05b","price_dollars":"0.3900","delta_fp":"-100.00","side":"yes","ts":"2026-09-13T23:28:59.258614Z","ts_ms":1789342139258}}
{"type":"orderbook_delta","sid":1,"seq":119,"msg":{"market_ticker":"KXBTCD-26SEP1417-T76999.99","market_id":"9fc30aa6-9f6f-4d2c-abca-fd27bae6f05b","price_dollars":"0.5800","delta_fp":"-100.00","side":"no","ts":"2026-09-13T23:28:59.259461Z","ts_ms":1789342139259}}
{"type":"orderbook_delta","sid":1,"seq":120,"msg":{"market_ticker":"KXBTCD-26SEP1417-T76999.99","market_id":"9fc30aa6-9f6f-4d2c-abca-fd27bae6f05b","price_dollars":"0.3900","delta_fp":"100.00","side":"yes","ts":"2026-09-13T23:28:59.26785Z","ts_ms":1789342139267}}
{"type":"orderbook_delta","sid":1,"seq":121,"msg":{"market_ticker":"KXBTCD-26SEP1417-T76999.99","market_id":"9fc30aa6-9f6f-4d2c-abca-fd27bae6f05b","price_dollars":"0.5800","delta_fp":"100.00","side":"no","ts":"2026-09-13T23:28:59.268785Z","ts_ms":1789342139268}}
{"type":"orderbook_delta","sid":1,"seq":122,"msg":{"market_ticker":"KXBTCD-26SEP1417-T76999.99","market_id":"9fc30aa6-9f6f-4d2c-abca-fd27bae6f05b","price_dollars":"0.5700","delta_fp":"-1000.00","side":"no","ts":"2026-09-13T23:29:01.949514Z","ts_ms":1789342141949}}
{"type":"orderbook_delta","sid":1,"seq":123,"msg":{"market_ticker":"KXBTCD-26SEP1417-T76999.99","market_id":"9fc30aa6-9f6f-4d2c-abca-fd27bae6f05b","price_dollars":"0.5800","delta_fp":"1000.00","side":"no","ts":"2026-09-13T23:29:01.949514Z","ts_ms":1789342141949}}
{"type":"orderbook_delta","sid":1,"seq":124,"msg":{"market_ticker":"KXBTCD-26SEP1417-T76999.99","market_id":"9fc30aa6-9f6f-4d2c-abca-fd27bae6f05b","price_dollars":"0.3900","delta_fp":"-1000.00","side":"yes","ts":"2026-09-13T23:29:01.971108Z","ts_ms":1789342141971}}
{"type":"orderbook_delta","sid":1,"seq":125,"msg":{"market_ticker":"KXBTCD-26SEP1417-T76999.99","market_id":"9fc30aa6-9f6f-4d2c-abca-fd27bae6f05b","price_dollars":"0.3800","delta_fp":"1000.00","side":"yes","ts":"2026-09-13T23:29:01.971108Z","ts_ms":1789342141971}}
{"type":"orderbook_delta","sid":1,"seq":126,"msg":{"market_ticker":"KXBTCD-26SEP1417-T76999.99","market_id":"9fc30aa6-9f6f-4d2c-abca-fd27bae6f05b","price_dollars":"0.3800","delta_fp":"-1000.00","side":"yes","ts":"2026-09-13T23:29:02.823777Z","ts_ms":1789342142823}}
{"type":"orderbook_delta","sid":1,"seq":127,"msg":{"market_ticker":"KXBTCD-26SEP1417-T76999.99","market_id":"9fc30aa6-9f6f-4d2c-abca-fd27bae6f05b","price_dollars":"0.3900","delta_fp":"1000.00","side":"yes","ts":"2026-09-13T23:29:02.823777Z","ts_ms":1789342142823}}
{"type":"orderbook_delta","sid":1,"seq":128,"msg":{"market_ticker":"KXBTCD-26SEP1417-T76999.99","market_id":"9fc30aa6-9f6f-4d2c-abca-fd27bae6f05b","price_dollars":"0.5800","delta_fp":"-1000.00","side":"no","ts":"2026-09-13T23:29:02.836587Z","ts_ms":1789342142836}}
{"type":"orderbook_delta","sid":1,"seq":129,"msg":{"market_ticker":"KXBTCD-26SEP1417-T76999.99","market_id":"9fc30aa6-9f6f-4d2c-abca-fd27bae6f05b","price_dollars":"0.5700","delta_fp":"1000.00","side":"no","ts":"2026-09-13T23:29:02.836587Z","ts_ms":1789342142836}}
{"type":"orderbook_delta","sid":1,"seq":130,"msg":{"market_ticker":"KXBTCD-26SEP1417-T76999.99","market_id":"9fc30aa6-9f6f-4d2c-abca-fd27bae6f05b","price_dollars":"0.3900","delta_fp":"-100.00","side":"yes","ts":"2026-09-13T23:29:02.840126Z","ts_ms":1789342142840}}
{"type":"orderbook_delta","sid":1,"seq":131,"msg":{"market_ticker":"KXBTCD-26SEP1417-T76999.99","market_id":"9fc30aa6-9f6f-4d2c-abca-fd27bae6f05b","price_dollars":"0.4000","delta_fp":"100.00","side":"yes","ts":"2026-09-13T23:29:02.840126Z","ts_ms":1789342142840}}
{"type":"orderbook_delta","sid":1,"seq":132,"msg":{"market_ticker":"KXBTCD-26SEP1417-T76999.99","market_id":"9fc30aa6-9f6f-4d2c-abca-fd27bae6f05b","price_dollars":"0.3900","delta_fp":"-2.00","side":"yes","ts":"2026-09-13T23:29:02.856057Z","ts_ms":1789342142856}}
{"type":"orderbook_delta","sid":1,"seq":133,"msg":{"market_ticker":"KXBTCD-26SEP1417-T76999.99","market_id":"9fc30aa6-9f6f-4d2c-abca-fd27bae6f05b","price_dollars":"0.4000","delta_fp":"2.00","side":"yes","ts":"2026-09-13T23:29:02.856652Z","ts_ms":1789342142856}}
{"type":"orderbook_delta","sid":1,"seq":134,"msg":{"market_ticker":"KXBTCD-26SEP1417-T76999.99","market_id":"9fc30aa6-9f6f-4d2c-abca-fd27bae6f05b","price_dollars":"0.4000","delta_fp":"310.00","side":"yes","ts":"2026-09-13T23:29:02.872571Z","ts_ms":1789342142872}}
{"type":"orderbook_delta","sid":1,"seq":135,"msg":{"market_ticker":"KXBTCD-26SEP1417-T76999.99","market_id":"9fc30aa6-9f6f-4d2c-abca-fd27bae6f05b","price_dollars":"0.3900","delta_fp":"310.00","side":"yes","ts":"2026-09-13T23:29:02.873189Z","ts_ms":1789342142873}}
{"type":"orderbook_delta","sid":1,"seq":136,"msg":{"market_ticker":"KXBTCD-26SEP1417-T76999.99","market_id":"9fc30aa6-9f6f-4d2c-abca-fd27bae6f05b","price_dollars":"0.3800","delta_fp":"310.00","side":"yes","ts":"2026-09-13T23:29:02.873603Z","ts_ms":1789342142873}}
{"type":"orderbook_delta","sid":1,"seq":137,"msg":{"market_ticker":"KXBTCD-26SEP1417-T76999.99","market_id":"9fc30aa6-9f6f-4d2c-abca-fd27bae6f05b","price_dollars":"0.3900","delta_fp":"-3000.00","side":"yes","ts":"2026-09-13T23:29:02.879271Z","ts_ms":1789342142879}}
{"type":"orderbook_delta","sid":1,"seq":138,"msg":{"market_ticker":"KXBTCD-26SEP1417-T76999.99","market_id":"9fc30aa6-9f6f-4d2c-abca-fd27bae6f05b","price_dollars":"0.4000","delta_fp":"3000.00","side":"yes","ts":"2026-09-13T23:29:02.879271Z","ts_ms":1789342142879}}
{"type":"orderbook_delta","sid":1,"seq":139,"msg":{"market_ticker":"KXBTCD-26SEP1417-T76999.99","market_id":"9fc30aa6-9f6f-4d2c-abca-fd27bae6f05b","price_dollars":"0.4000","delta_fp":"-310.00","side":"yes","ts":"2026-09-13T23:29:02.903319Z","ts_ms":1789342142903}}
{"type":"orderbook_delta","sid":1,"seq":140,"msg":{"market_ticker":"KXBTCD-26SEP1417-T76999.99","market_id":"9fc30aa6-9f6f-4d2c-abca-fd27bae6f05b","price_dollars":"0.3900","delta_fp":"-310.00","side":"yes","ts":"2026-09-13T23:29:02.903741Z","ts_ms":1789342142903}}
{"type":"orderbook_delta","sid":1,"seq":141,"msg":{"market_ticker":"KXBTCD-26SEP1417-T76999.99","market_id":"9fc30aa6-9f6f-4d2c-abca-fd27bae6f05b","price_dollars":"0.3800","delta_fp":"-310.00","side":"yes","ts":"2026-09-13T23:29:02.904746Z","ts_ms":1789342142904}}
{"type":"orderbook_delta","sid":1,"seq":142,"msg":{"market_ticker":"KXBTCD-26SEP1417-T76999.99","market_id":"9fc30aa6-9f6f-4d2c-abca-fd27bae6f05b","price_dollars":"0.4000","delta_fp":"-3000.00","side":"yes","ts":"2026-09-13T23:29:02.911535Z","ts_ms":1789342142911}}
{"type":"orderbook_delta","sid":1,"seq":143,"msg":{"market_ticker":"KXBTCD-26SEP1417-T76999.99","market_id":"9fc30aa6-9f6f-4d2c-abca-fd27bae6f05b","price_dollars":"0.3900","delta_fp":"3000.00","side":"yes","ts":"2026-09-13T23:29:02.911535Z","ts_ms":1789342142911}}
{"type":"orderbook_delta","sid":1,"seq":144,"msg":{"market_ticker":"KXBTCD-26SEP1417-T76999.99","market_id":"9fc30aa6-9f6f-4d2c-abca-fd27bae6f05b","price_dollars":"0.4000","delta_fp":"-100.00","side":"yes","ts":"2026-09-13T23:29:02.918389Z","ts_ms":1789342142918}}
{"type":"orderbook_delta","sid":1,"seq":145,"msg":{"market_ticker":"KXBTCD-26SEP1417-T76999.99","market_id":"9fc30aa6-9f6f-4d2c-abca-fd27bae6f05b","price_dollars":"0.3400","delta_fp":"100.00","side":"yes","ts":"2026-09-13T23:29:02.918389Z","ts_ms":1789342142918}}
{"type":"orderbook_delta","sid":1,"seq":146,"msg":{"market_ticker":"KXBTCD-26SEP1417-T76999.99","market_id":"9fc30aa6-9f6f-4d2c-abca-fd27bae6f05b","price_dollars":"0.4000","delta_fp":"310.00","side":"yes","ts":"2026-09-13T23:29:02.930617Z","ts_ms":1789342142930}}
{"type":"orderbook_delta","sid":1,"seq":147,"msg":{"market_ticker":"KXBTCD-26SEP1417-T76999.99","market_id":"9fc30aa6-9f6f-4d2c-abca-fd27bae6f05b","price_dollars":"0.3900","delta_fp":"310.00","side":"yes","ts":"2026-09-13T23:29:02.931423Z","ts_ms":1789342142931}}
{"type":"orderbook_delta","sid":1,"seq":148,"msg":{"market_ticker":"KXBTCD-26SEP1417-T76999.99","market_id":"9fc30aa6-9f6f-4d2c-abca-fd27bae6f05b","price_dollars":"0.3800","delta_fp":"310.00","side":"yes","ts":"2026-09-13T23:29:02.932034Z","ts_ms":1789342142932}}
{"type":"orderbook_delta","sid":1,"seq":149,"msg":{"market_ticker":"KXBTCD-26SEP1417-T76999.99","market_id":"9fc30aa6-9f6f-4d2c-abca-fd27bae6f05b","price_dollars":"0.3400","delta_fp":"-100.00","side":"yes","ts":"2026-09-13T23:29:03.023162Z","ts_ms":1789342143023}}
{"type":"orderbook_delta","sid":1,"seq":150,"msg":{"market_ticker":"KXBTCD-26SEP1417-T76999.99","market_id":"9fc30aa6-9f6f-4d2c-abca-fd27bae6f05b","price_dollars":"0.4000","delta_fp":"100.00","side":"yes","ts":"2026-09-13T23:29:03.023162Z","ts_ms":1789342143023}}
{"type":"orderbook_delta","sid":1,"seq":151,"msg":{"market_ticker":"KXBTCD-26SEP1417-T76999.99","market_id":"9fc30aa6-9f6f-4d2c-abca-fd27bae6f05b","price_dollars":"0.3900","delta_fp":"-3000.00","side":"yes","ts":"2026-09-13T23:29:03.446557Z","ts_ms":1789342143446}}
{"type":"orderbook_delta","sid":1,"seq":152,"msg":{"market_ticker":"KXBTCD-26SEP1417-T76999.99","market_id":"9fc30aa6-9f6f-4d2c-abca-fd27bae6f05b","price_dollars":"0.4000","delta_fp":"3000.00","side":"yes","ts":"2026-09-13T23:29:03.446557Z","ts_ms":1789342143446}}
{"type":"orderbook_delta","sid":1,"seq":153,"msg":{"market_ticker":"KXBTCD-26SEP1417-T76999.99","market_id":"9fc30aa6-9f6f-4d2c-abca-fd27bae6f05b","price_dollars":"0.1500","delta_fp":"-6.00","side":"yes","ts":"2026-09-13T23:29:03.489607Z","ts_ms":1789342143489}}
{"type":"orderbook_delta","sid":1,"seq":154,"msg":{"market_ticker":"KXBTCD-26SEP1417-T76999.99","market_id":"9fc30aa6-9f6f-4d2c-abca-fd27bae6f05b","price_dollars":"0.2900","delta_fp":"-50.00","side":"yes","ts":"2026-09-13T23:29:04.27237Z","ts_ms":1789342144272}}
{"type":"orderbook_delta","sid":1,"seq":155,"msg":{"market_ticker":"KXBTCD-26SEP1417-T76999.99","market_id":"9fc30aa6-9f6f-4d2c-abca-fd27bae6f05b","price_dollars":"0.3800","delta_fp":"50.00","side":"yes","ts":"2026-09-13T23:29:04.273507Z","ts_ms":1789342144273}}
{"type":"orderbook_delta","sid":1,"seq":156,"msg":{"market_ticker":"KXBTCD-26SEP1417-T76999.99","market_id":"9fc30aa6-9f6f-4d2c-abca-fd27bae6f05b","price_dollars":"0.5600","delta_fp":"-50.00","side":"no","ts":"2026-09-13T23:29:04.275611Z","ts_ms":1789342144275}}
{"type":"orderbook_delta","sid":1,"seq":157,"msg":{"market_ticker":"KXBTCD-26SEP1417-T76999.99","market_id":"9fc30aa6-9f6f-4d2c-abca-fd27bae6f05b","price_dollars":"0.4700","delta_fp":"50.00","side":"no","ts":"2026-09-13T23:29:04.278929Z","ts_ms":1789342144278}}
