{"type":"subscribed","id":1,"msg":{"channel":"orderbook_delta","sid":1}}
{"type":"orderbook_snapshot","sid":1,"seq":1,"msg":{"market_ticker":"KXBTCD-26SEP1417-T76999.99","market_id":"9fc30aa6-9f6f-4d2c-abca-fd27bae6f05b","yes_dollars_fp":[["0.0100","182397.00"],["0.0200","100.01"],["0.0300","45599.01"],["0.0400","0.01"],["0.0500","40.01"],["0.0600","0.01"],["0.0700","0.01"],["0.0800","0.01"],["0.0900","0.01"],["0.1000","0.01"],["0.1100","101.01"],["0.1200","8142.01"],["0.1300","0.01"],["0.1400","0.01"],["0.1500","12.01"],["0.1600","2.01"],["0.1700","0.01"],["0.1800","1.01"],["0.1900","1.01"],["0.2000","0.01"],["0.2100","1.01"],["0.2200","0.01"],["0.2300","0.01"],["0.2400","0.01"],["0.2500","103.01"],["0.2600","0.01"],["0.2700","2.01"],["0.2800","0.01"],["0.2900","0.01"],["0.3000","1.01"],["0.3100","0.01"],["0.3200","50.01"],["0.3300","52.01"],["0.3400","50.01"],["0.3500","150.01"],["0.3600","50.01"],["0.3700","50.01"],["0.3800","50.01"],["0.3900","54.00"],["0.4000","5620.00"],["0.4100","2384.00"],["0.4200","4521.00"]],"no_dollars_fp":[["0.0100","109.88"],["0.0200","117256.01"],["0.0300","0.01"],["0.0400","0.01"],["0.0500","0.01"],["0.0600","0.01"],["0.0700","46.42"],["0.0800","22799.01"],["0.0900","0.01"],["0.1000","0.01"],["0.1100","0.01"],["0.1200","0.01"],["0.1300","0.01"],["0.1400","0.01"],["0.1500","157.99"],["0.1600","8549.01"],["0.1700","0.01"],["0.1800","0.01"],["0.1900","0.01"],["0.2000","1.01"],["0.2100","0.01"],["0.2200","0.01"],["0.2300","0.01"],["0.2400","1.01"],["0.2500","77.57"],["0.2600","0.01"],["0.2700","205.01"],["0.2800","140.01"],["0.2900","3369.01"],["0.3000","0.01"],["0.3100","1.01"],["0.3200","0.01"],["0.3300","0.01"],["0.3400","6.29"],["0.4100","1.00"],["0.4500","50.00"],["0.4600","50.00"],["0.4700","50.00"],["0.4800","50.00"],["0.4900","50.00"],["0.5000","50.00"],["0.5100","50.00"],["0.5200","1011.99"],["0.5300","1050.00"],["0.5400","5004.00"],["0.5500","2105.00"]]}}
{"type":"orderbook_delta","sid":1,"seq":2,"msg":{"market_ticker":"KXBTCD-26SEP1417-T76999.99","market_id":"9fc30aa6-9f6f-4d2c-abca-fd27bae6f05b","price_dollars":"0.4100","delta_fp":"-1000.00","side":"yes","ts":"2026-09-13T23:45:19.238833Z","ts_ms":1789343119238}}
{"type":"orderbook_delta","sid":1,"seq":3,"msg":{"market_ticker":"KXBTCD-26SEP1417-T76999.99","market_id":"9fc30aa6-9f6f-4d2c-abca-fd27bae6f05b","price_dollars":"0.4200","delta_fp":"1000.00","side":"yes","ts":"2026-09-13T23:45:19.238833Z","ts_ms":1789343119238}}
{"type":"orderbook_delta","sid":1,"seq":4,"msg":{"market_ticker":"KXBTCD-26SEP1417-T76999.99","market_id":"9fc30aa6-9f6f-4d2c-abca-fd27bae6f05b","price_dollars":"0.5500","delta_fp":"-1000.00","side":"no","ts":"2026-09-13T23:45:19.239272Z","ts_ms":1789343119239}}
{"type":"orderbook_delta","sid":1,"seq":5,"msg":{"market_ticker":"KXBTCD-26SEP1417-T76999.99","market_id":"9fc30aa6-9f6f-4d2c-abca-fd27bae6f05b","price_dollars":"0.5400","delta_fp":"1000.00","side":"no","ts":"2026-09-13T23:45:19.239272Z","ts_ms":1789343119239}}
{"type":"orderbook_delta","sid":1,"seq":6,"msg":{"market_ticker":"KXBTCD-26SEP1417-T76999.99","market_id":"9fc30aa6-9f6f-4d2c-abca-fd27bae6f05b","price_dollars":"0.5500","delta_fp":"-1000.00","side":"no","ts":"2026-09-13T23:45:19.241817Z","ts_ms":1789343119241}}
{"type":"orderbook_delta","sid":1,"seq":7,"msg":{"market_ticker":"KXBTCD-26SEP1417-T76999.99","market_id":"9fc30aa6-9f6f-4d2c-abca-fd27bae6f05b","price_dollars":"0.5400","delta_fp":"1000.00","side":"no","ts":"2026-09-13T23:45:19.241817Z","ts_ms":1789343119241}}
{"type":"orderbook_delta","sid":1,"seq":8,"msg":{"market_ticker":"KXBTCD-26SEP1417-T76999.99","market_id":"9fc30aa6-9f6f-4d2c-abca-fd27bae6f05b","price_dollars":"0.4100","delta_fp":"-1000.00","side":"yes","ts":"2026-09-13T23:45:19.24489Z","ts_ms":1789343119244}}
{"type":"orderbook_delta","sid":1,"seq":9,"msg":{"market_ticker":"KXBTCD-26SEP1417-T76999.99","market_id":"9fc30aa6-9f6f-4d2c-abca-fd27bae6f05b","price_dollars":"0.4200","delta_fp":"1000.00","side":"yes","ts":"2026-09-13T23:45:19.24489Z","ts_ms":1789343119244}}
{"type":"orderbook_delta","sid":1,"seq":10,"msg":{"market_ticker":"KXBTCD-26SEP1417-T76999.99","market_id":"9fc30aa6-9f6f-4d2c-abca-fd27bae6f05b","price_dollars":"0.4200","delta_fp":"-1000.00","side":"yes","ts":"2026-09-13T23:45:19.290122Z","ts_ms":1789343119290}}
{"type":"orderbook_delta","sid":1,"seq":11,"msg":{"market_ticker":"KXBTCD-26SEP1417-T76999.99","market_id":"9fc30aa6-9f6f-4d2c-abca-fd27bae6f05b","price_dollars":"0.5400","delta_fp":"-1000.00","side":"no","ts":"2026-09-13T23:45:19.291386Z","ts_ms":1789343119291}}
{"type":"orderbook_delta","sid":1,"seq":12,"msg":{"market_ticker":"KXBTCD-26SEP1417-T76999.99","market_id":"9fc30aa6-9f6f-4d2c-abca-fd27bae6f05b","price_dollars":"0.5400","delta_fp":"-1000.00","side":"no","ts":"2026-09-13T23:45:19.301599Z","ts_ms":1789343119301}}
{"type":"orderbook_delta","sid":1,"seq":13,"msg":{"market_ticker":"KXBTCD-26SEP1417-T76999.99","market_id":"9fc30aa6-9f6f-4d2c-abca-fd27bae6f05b","price_dollars":"0.4200","delta_fp":"-1000.00","side":"yes","ts":"2026-09-13T23:45:19.308765Z","ts_ms":1789343119308}}
{"type":"orderbook_delta","sid":1,"seq":14,"msg":{"market_ticker":"KXBTCD-26SEP1417-T76999.99","market_id":"9fc30aa6-9f6f-4d2c-abca-fd27bae6f05b","price_dollars":"0.4100","delta_fp":"1000.00","side":"yes","ts":"2026-09-13T23:45:19.308765Z","ts_ms":1789343119308}}
{"type":"orderbook_delta","sid":1,"seq":15,"msg":{"market_ticker":"KXBTCD-26SEP1417-T76999.99","market_id":"9fc30aa6-9f6f-4d2c-abca-fd27bae6f05b","price_dollars":"0.5500","delta_fp":"1000.00","side":"no","ts":"2026-09-13T23:45:19.419837Z","ts_ms":1789343119419}}
{"type":"orderbook_delta","sid":1,"seq":16,"msg":{"market_ticker":"KXBTCD-26SEP1417-T76999.99","market_id":"9fc30aa6-9f6f-4d2c-abca-fd27bae6f05b","price_dollars":"0.4100","delta_fp":"1000.00","side":"yes","ts":"2026-09-13T23:45:19.420241Z","ts_ms":1789343119420}}
{"type":"orderbook_delta","sid":1,"seq":17,"msg":{"market_ticker":"KXBTCD-26SEP1417-T76999.99","market_id":"9fc30aa6-9f6f-4d2c-abca-fd27bae6f05b","price_dollars":"0.5500","delta_fp":"1000.00","side":"no","ts":"2026-09-13T23:45:19.431822Z","ts_ms":1789343119431}}
{"type":"orderbook_delta","sid":1,"seq":18,"msg":{"market_ticker":"KXBTCD-26SEP1417-T76999.99","market_id":"9fc30aa6-9f6f-4d2c-abca-fd27bae6f05b","price_dollars":"0.5500","delta_fp":"-1000.00","side":"no","ts":"2026-09-13T23:45:19.61977Z","ts_ms":1789343119619}}
{"type":"orderbook_delta","sid":1,"seq":19,"msg":{"market_ticker":"KXBTCD-26SEP1417-T76999.99","market_id":"9fc30aa6-9f6f-4d2c-abca-fd27bae6f05b","price_dollars":"0.5400","delta_fp":"1000.00","side":"no","ts":"2026-09-13T23:45:19.61977Z","ts_ms":1789343119619}}
{"type":"orderbook_delta","sid":1,"seq":20,"msg":{"market_ticker":"KXBTCD-26SEP1417-T76999.99","market_id":"9fc30aa6-9f6f-4d2c-abca-fd27bae6f05b","price_dollars":"0.4100","delta_fp":"-1000.00","side":"yes","ts":"2026-09-13T23:45:19.625824Z","ts_ms":1789343119625}}
{"type":"orderbook_delta","sid":1,"seq":21,"msg":{"market_ticker":"KXBTCD-26SEP1417-T76999.99","market_id":"9fc30aa6-9f6f-4d2c-abca-fd27bae6f05b","price_dollars":"0.4200","delta_fp":"1000.00","side":"yes","ts":"2026-09-13T23:45:19.625824Z","ts_ms":1789343119625}}
{"type":"orderbook_delta","sid":1,"seq":22,"msg":{"market_ticker":"KXBTCD-26SEP1417-T76999.99","market_id":"9fc30aa6-9f6f-4d2c-abca-fd27bae6f05b","price_dollars":"0.4100","delta_fp":"-1000.00","side":"yes","ts":"2026-09-13T23:45:19.628074Z","ts_ms":1789343119628}}
{"type":"orderbook_delta","sid":1,"seq":23,"msg":{"market_ticker":"KXBTCD-26SEP1417-T76999.99","market_id":"9fc30aa6-9f6f-4d2c-abca-fd27bae6f05b","price_dollars":"0.4200","delta_fp":"1000.00","side":"yes","ts":"2026-09-13T23:45:19.628074Z","ts_ms":1789343119628}}
{"type":"orderbook_delta","sid":1,"seq":24,"msg":{"market_ticker":"KXBTCD-26SEP1417-T76999.99","market_id":"9fc30aa6-9f6f-4d2c-abca-fd27bae6f05b","price_dollars":"0.5500","delta_fp":"-1000.00","side":"no","ts":"2026-09-13T23:45:19.628168Z","ts_ms":1789343119628}}
{"type":"orderbook_delta","sid":1,"seq":25,"msg":{"market_ticker":"KXBTCD-26SEP1417-T76999.99","market_id":"9fc30aa6-9f6f-4d2c-abca-fd27bae6f05b","price_dollars":"0.5400","delta_fp":"1000.00","side":"no","ts":"2026-09-13T23:45:19.628168Z","ts_ms":1789343119628}}
{"type":"orderbook_delta","sid":1,"seq":26,"msg":{"market_ticker":"KXBTCD-26SEP1417-T76999.99","market_id":"9fc30aa6-9f6f-4d2c-abca-fd27bae6f05b","price_dollars":"0.5400","delta_fp":"-1000.00","side":"no","ts":"2026-09-13T23:45:19.905861Z","ts_ms":1789343119905}}
{"type":"orderbook_delta","sid":1,"seq":27,"msg":{"market_ticker":"KXBTCD-26SEP1417-T76999.99","market_id":"9fc30aa6-9f6f-4d2c-abca-fd27bae6f05b","price_dollars":"0.5500","delta_fp":"1000.00","side":"no","ts":"2026-09-13T23:45:19.905861Z","ts_ms":1789343119905}}
{"type":"orderbook_delta","sid":1,"seq":28,"msg":{"market_ticker":"KXBTCD-26SEP1417-T76999.99","market_id":"9fc30aa6-9f6f-4d2c-abca-fd27bae6f05b","price_dollars":"0.4200","delta_fp":"-1000.00","side":"yes","ts":"2026-09-13T23:45:19.909226Z","ts_ms":1789343119909}}
{"type":"orderbook_delta","sid":1,"seq":29,"msg":{"market_ticker":"KXBTCD-26SEP1417-T76999.99","market_id":"9fc30aa6-9f6f-4d2c-abca-fd27bae6f05b","price_dollars":"0.4100","delta_fp":"1000.00","side":"yes","ts":"2026-09-13T23:45:19.909226Z","ts_ms":1789343119909}}
{"type":"orderbook_delta","sid":1,"seq":30,"msg":{"market_ticker":"KXBTCD-26SEP1417-T76999.99","market_id":"9fc30aa6-9f6f-4d2c-abca-fd27bae6f05b","price_dollars":"0.5500","delta_fp":"-100.00","side":"no","ts":"2026-09-13T23:45:20.289241Z","ts_ms":1789343120289}}
{"type":"orderbook_delta","sid":1,"seq":31,"msg":{"market_ticker":"KXBTCD-26SEP1417-T76999.99","market_id":"9fc30aa6-9f6f-4d2c-abca-fd27bae6f05b","price_dollars":"0.5600","delta_fp":"100.00","side":"no","ts":"2026-09-13T23:45:20.289241Z","ts_ms":1789343120289}}
{"type":"orderbook_delta","sid":1,"seq":32,"msg":{"market_ticker":"KXBTCD-26SEP1417-T76999.99","market_id":"9fc30aa6-9f6f-4d2c-abca-fd27bae6f05b","price_dollars":"0.4200","delta_fp":"-1000.00","side":"yes","ts":"2026-09-13T23:45:20.322861Z","ts_ms":1789343120322}}
{"type":"orderbook_delta","sid":1,"seq":33,"msg":{"market_ticker":"KXBTCD-26SEP1417-T76999.99","market_id":"9fc30aa6-9f6f-4d2c-abca-fd27bae6f05b","price_dollars":"0.4100","delta_fp":"1000.00","side":"yes","ts":"2026-09-13T23:45:20.322861Z","ts_ms":1789343120322}}
{"type":"orderbook_delta","sid":1,"seq":34,"msg":{"market_ticker":"KXBTCD-26SEP1417-T76999.99","market_id":"9fc30aa6-9f6f-4d2c-abca-fd27bae6f05b","price_dollars":"0.5400","delta_fp":"-1000.00","side":"no","ts":"2026-09-13T23:45:20.324395Z","ts_ms":1789343120324}}
{"type":"orderbook_delta","sid":1,"seq":35,"msg":{"market_ticker":"KXBTCD-26SEP1417-T76999.99","market_id":"9fc30aa6-9f6f-4d2c-abca-fd27bae6f05b","price_dollars":"0.5500","delta_fp":"1000.00","side":"no","ts":"2026-09-13T23:45:20.324395Z","ts_ms":1789343120324}}
{"type":"orderbook_delta","sid":1,"seq":36,"msg":{"market_ticker":"KXBTCD-26SEP1417-T76999.99","market_id":"9fc30aa6-9f6f-4d2c-abca-fd27bae6f05b","price_dollars":"0.5600","delta_fp":"-100.00","side":"no","ts":"2026-09-13T23:45:20.370735Z","ts_ms":1789343120370}}
{"type":"orderbook_delta","sid":1,"seq":37,"msg":{"market_ticker":"KXBTCD-26SEP1417-T76999.99","market_id":"9fc30aa6-9f6f-4d2c-abca-fd27bae6f05b","price_dollars":"0.5100","delta_fp":"100.00","side":"no","ts":"2026-09-13T23:45:20.370735Z","ts_ms":1789343120370}}
{"type":"orderbook_delta","sid":1,"seq":38,"msg":{"market_ticker":"KXBTCD-26SEP1417-T76999.99","market_id":"9fc30aa6-9f6f-4d2c-abca-fd27bae6f05b","price_dollars":"0.5100","delta_fp":"-100.00","side":"no","ts":"2026-09-13T23:45:20.473798Z","ts_ms":1789343120473}}
{"type":"orderbook_delta","sid":1,"seq":39,"msg":{"market_ticker":"KXBTCD-26SEP1417-T76999.99","market_id":"9fc30aa6-9f6f-4d2c-abca-fd27bae6f05b","price_dollars":"0.5600","delta_fp":"100.00","side":"no","ts":"2026-09-13T23:45:20.473798Z","ts_ms":1789343120473}}
{"type":"orderbook_delta","sid":1,"seq":40,"msg":{"market_ticker":"KXBTCD-26SEP1417-T76999.99","market_id":"9fc30aa6-9f6f-4d2c-abca-fd27bae6f05b","price_dollars":"0.5600","delta_fp":"-100.00","side":"no","ts":"2026-09-13T23:45:21.394169Z","ts_ms":1789343121394}}
{"type":"orderbook_delta","sid":1,"seq":41,"msg":{"market_ticker":"KXBTCD-26SEP1417-T76999.99","market_id":"9fc30aa6-9f6f-4d2c-abca-fd27bae6f05b","price_dollars":"0.5100","delta_fp":"100.00","side":"no","ts":"2026-09-13T23:45:21.394169Z","ts_ms":1789343121394}}
{"type":"orderbook_delta","sid":1,"seq":42,"msg":{"market_ticker":"KXBTCD-26SEP1417-T76999.99","market_id":"9fc30aa6-9f6f-4d2c-abca-fd27bae6f05b","price_dollars":"0.5100","delta_fp":"-100.00","side":"no","ts":"2026-09-13T23:45:21.496999Z","ts_ms":1789343121496}}
{"type":"orderbook_delta","sid":1,"seq":43,"msg":{"market_ticker":"KXBTCD-26SEP1417-T76999.99","market_id":"9fc30aa6-9f6f-4d2c-abca-fd27bae6f05b","price_dollars":"0.5500","delta_fp":"100.00","side":"no","ts":"2026-09-13T23:45:21.496999Z","ts_ms":1789343121496}}
{"type":"orderbook_delta","sid":1,"seq":44,"msg":{"market_ticker":"KXBTCD-26SEP1417-T76999.99","market_id":"9fc30aa6-9f6f-4d2c-abca-fd27bae6f05b","price_dollars":"0.5500","delta_fp":"-1000.00","side":"no","ts":"2026-09-13T23:45:21.658643Z","ts_ms":1789343121658}}
{"type":"orderbook_delta","sid":1,"seq":45,"msg":{"market_ticker":"KXBTCD-26SEP1417-T76999.99","market_id":"9fc30aa6-9f6f-4d2c-abca-fd27bae6f05b","price_dollars":"0.5400","delta_fp":"1000.00","side":"no","ts":"2026-09-13T23:45:21.658643Z","ts_ms":1789343121658}}
{"type":"orderbook_delta","sid":1,"seq":46,"msg":{"market_ticker":"KXBTCD-26SEP1417-T76999.99","market_id":"9fc30aa6-9f6f-4d2c-abca-fd27bae6f05b","price_dollars":"0.4100","delta_fp":"-1000.00","side":"yes","ts":"2026-09-13T23:45:21.66064Z","ts_ms":1789343121660}}
{"type":"orderbook_delta","sid":1,"seq":47,"msg":{"market_ticker":"KXBTCD-26SEP1417-T76999.99","market_id":"9fc30aa6-9f6f-4d2c-abca-fd27bae6f05b","price_dollars":"0.4200","delta_fp":"1000.00","side":"yes","ts":"2026-09-13T23:45:21.66064Z","ts_ms":1789343121660}}
{"type":"orderbook_delta","sid":1,"seq":48,"msg":{"market_ticker":"KXBTCD-26SEP1417-T76999.99","market_id":"9fc30aa6-9f6f-4d2c-abca-fd27bae6f05b","price_dollars":"0.5500","delta_fp":"-1000.00","side":"no","ts":"2026-09-13T23:45:21.661595Z","ts_ms":1789343121661}}
{"type":"orderbook_delta","sid":1,"seq":49,"msg":{"market_ticker":"KXBTCD-26SEP1417-T76999.99","market_id":"9fc30aa6-9f6f-4d2c-abca-fd27bae6f05b","price_dollars":"0.5400","delta_fp":"1000.00","side":"no","ts":"2026-09-13T23:45:21.661595Z","ts_ms":1789343121661}}
{"type":"orderbook_delta","sid":1,"seq":50,"msg":{"market_ticker":"KXBTCD-26SEP1417-T76999.99","market_id":"9fc30aa6-9f6f-4d2c-abca-fd27bae6f05b","price_dollars":"0.4100","delta_fp":"-1000.00","side":"yes","ts":"2026-09-13T23:45:21.670907Z","ts_ms":1789343121670}}
{"type":"orderbook_delta","sid":1,"seq":51,"msg":{"market_ticker":"KXBTCD-26SEP1417-T76999.99","market_id":"9fc30aa6-9f6f-4d2c-abca-fd27bae6f05b","price_dollars":"0.4200","delta_fp":"1000.00","side":"yes","ts":"2026-09-13T23:45:21.670907Z","ts_ms":1789343121670}}
{"type":"orderbook_delta","sid":1,"seq":52,"msg":{"market_ticker":"KXBTCD-26SEP1417-T76999.99","market_id":"9fc30aa6-9f6f-4d2c-abca-fd27bae6f05b","price_dollars":"0.5500","delta_fp":"-5.00","side":"no","ts":"2026-09-13T23:45:22.030333Z","ts_ms":1789343122030}}
{"type":"orderbook_delta","sid":1,"seq":53,"msg":{"market_ticker":"KXBTCD-26SEP1417-T76999.99","market_id":"9fc30aa6-9f6f-4d2c-abca-fd27bae6f05b","price_dollars":"0.3200","delta_fp":"-50.00","side":"yes","ts":"2026-09-13T23:45:22.07529Z","ts_ms":1789343122075}}
{"type":"orderbook_delta","sid":1,"seq":54,"msg":{"market_ticker":"KXBTCD-26SEP1417-T76999.99","market_id":"9fc30aa6-9f6f-4d2c-abca-fd27bae6f05b","price_dollars":"0.4100","delta_fp":"50.00","side":"yes","ts":"2026-09-13T23:45:22.07672Z","ts_ms":1789343122076}}
{"type":"orderbook_delta","sid":1,"seq":55,"msg":{"market_ticker":"KXBTCD-26SEP1417-T76999.99","market_id":"9fc30aa6-9f6f-4d2c-abca-fd27bae6f05b","price_dollars":"0.5300","delta_fp":"-50.00","side":"no","ts":"2026-09-13T23:45:22.078243Z","ts_ms":1789343122078}}
{"type":"orderbook_delta","sid":1,"seq":56,"msg":{"market_ticker":"KXBTCD-26SEP1417-T76999.99","market_id":"9fc30aa6-9f6f-4d2c-abca-fd27bae6f05b","price_dollars":"0.4400","delta_fp":"50.00","side":"no","ts":"2026-09-13T23:45:22.079695Z","ts_ms":1789343122079}}
{"type":"orderbook_delta","sid":1,"seq":57,"msg":{"market_ticker":"KXBTCD-26SEP1417-T76999.99","market_id":"9fc30aa6-9f6f-4d2c-abca-fd27bae6f05b","price_dollars":"0.2800","delta_fp":"-140.00","side":"no","ts":"2026-09-13T23:45:22.083383Z","ts_ms":1789343122083}}
{"type":"orderbook_delta","sid":1,"seq":58,"msg":{"market_ticker":"KXBTCD-26SEP1417-T76999.99","market_id":"9fc30aa6-9f6f-4d2c-abca-fd27bae6f05b","price_dollars":"0.2700","delta_fp":"-205.00","side":"no","ts":"2026-09-13T23:45:22.084812Z","ts_ms":1789343122084}}
{"type":"orderbook_delta","sid":1,"seq":59,"msg":{"market_ticker":"KXBTCD-26SEP1417-T76999.99","market_id":"9fc30aa6-9f6f-4d2c-abca-fd27bae6f05b","price_dollars":"0.3000","delta_fp":"193.00","side":"no","ts":"2026-09-13T23:45:22.085438Z","ts_ms":1789343122085}}
{"type":"orderbook_delta","sid":1,"seq":60,"msg":{"market_ticker":"KXBTCD-26SEP1417-T76999.99","market_id":"9fc30aa6-9f6f-4d2c-abca-fd27bae6f05b","price_dollars":"0.3100","delta_fp":"182.00","side":"no","ts":"2026-09-13T23:45:22.085852Z","ts_ms":1789343122085}}
{"type":"orderbook_delta","sid":1,"seq":61,"msg":{"market_ticker":"KXBTCD-26SEP1417-T76999.99","market_id":"9fc30aa6-9f6f-4d2c-abca-fd27bae6f05b","price_dollars":"0.4300","delta_fp":"568.00","side":"yes","ts":"2026-09-13T23:45:22.133421Z","ts_ms":1789343122133}}
{"type":"orderbook_delta","sid":1,"seq":62,"msg":{"market_ticker":"KXBTCD-26SEP1417-T76999.99","market_id":"9fc30aa6-9f6f-4d2c-abca-fd27bae6f05b","price_dollars":"0.4200","delta_fp":"-191.00","side":"yes","ts":"2026-09-13T23:45:22.13824Z","ts_ms":1789343122138}}
{"type":"orderbook_delta","sid":1,"seq":63,"msg":{"market_ticker":"KXBTCD-26SEP1417-T76999.99","market_id":"9fc30aa6-9f6f-4d2c-abca-fd27bae6f05b","price_dollars":"0.4200","delta_fp":"-3000.00","side":"yes","ts":"2026-09-13T23:45:22.139307Z","ts_ms":1789343122139}}
{"type":"orderbook_delta","sid":1,"seq":64,"msg":{"market_ticker":"KXBTCD-26SEP1417-T76999.99","market_id":"9fc30aa6-9f6f-4d2c-abca-fd27bae6f05b","price_dollars":"0.4300","delta_fp":"3000.00","side":"yes","ts":"2026-09-13T23:45:22.139307Z","ts_ms":1789343122139}}
{"type":"orderbook_delta","sid":1,"seq":65,"msg":{"market_ticker":"KXBTCD-26SEP1417-T76999.99","market_id":"9fc30aa6-9f6f-4d2c-abca-fd27bae6f05b","price_dollars":"0.4200","delta_fp":"-11.00","side":"yes","ts":"2026-09-13T23:45:22.139651Z","ts_ms":1789343122139}}
{"type":"orderbook_delta","sid":1,"seq":66,"msg":{"market_ticker":"KXBTCD-26SEP1417-T76999.99","market_id":"9fc30aa6-9f6f-4d2c-abca-fd27bae6f05b","price_dollars":"0.4300","delta_fp":"-3000.00","side":"yes","ts":"2026-09-13T23:45:22.144668Z","ts_ms":1789343122144}}
{"type":"orderbook_delta","sid":1,"seq":67,"msg":{"market_ticker":"KXBTCD-26SEP1417-T76999.99","market_id":"9fc30aa6-9f6f-4d2c-abca-fd27bae6f05b","price_dollars":"0.4200","delta_fp":"3000.00","side":"yes","ts":"2026-09-13T23:45:22.144668Z","ts_ms":1789343122144}}
{"type":"orderbook_delta","sid":1,"seq":68,"msg":{"market_ticker":"KXBTCD-26SEP1417-T76999.99","market_id":"9fc30aa6-9f6f-4d2c-abca-fd27bae6f05b","price_dollars":"0.4200","delta_fp":"-30.00","side":"yes","ts":"2026-09-13T23:45:22.207611Z","ts_ms":1789343122207}}
{"type":"orderbook_delta","sid":1,"seq":69,"msg":{"market_ticker":"KXBTCD-26SEP1417-T76999.99","market_id":"9fc30aa6-9f6f-4d2c-abca-fd27bae6f05b","price_dollars":"0.4300","delta_fp":"5.00","side":"yes","ts":"2026-09-13T23:45:22.210079Z","ts_ms":1789343122210}}
{"type":"orderbook_delta","sid":1,"seq":70,"msg":{"market_ticker":"KXBTCD-26SEP1417-T76999.99","market_id":"9fc30aa6-9f6f-4d2c-abca-fd27bae6f05b","price_dollars":"0.0200","delta_fp":"-26057.00","side":"no","ts":"2026-09-13T23:45:22.365011Z","ts_ms":1789343122365}}
{"type":"orderbook_delta","sid":1,"seq":71,"msg":{"market_ticker":"KXBTCD-26SEP1417-T76999.99","market_id":"9fc30aa6-9f6f-4d2c-abca-fd27bae6f05b","price_dollars":"0.0800","delta_fp":"-5700.00","side":"no","ts":"2026-09-13T23:45:22.365624Z","ts_ms":1789343122365}}
{"type":"orderbook_delta","sid":1,"seq":72,"msg":{"market_ticker":"KXBTCD-26SEP1417-T76999.99","market_id":"9fc30aa6-9f6f-4d2c-abca-fd27bae6f05b","price_dollars":"0.1600","delta_fp":"-8549.00","side":"no","ts":"2026-09-13T23:45:22.36608Z","ts_ms":1789343122366}}
{"type":"orderbook_delta","sid":1,"seq":73,"msg":{"market_ticker":"KXBTCD-26SEP1417-T76999.99","market_id":"9fc30aa6-9f6f-4d2c-abca-fd27bae6f05b","price_dollars":"0.4200","delta_fp":"-100.00","side":"yes","ts":"2026-09-13T23:45:22.368234Z","ts_ms":1789343122368}}
{"type":"orderbook_delta","sid":1,"seq":74,"msg":{"market_ticker":"KXBTCD-26SEP1417-T76999.99","market_id":"9fc30aa6-9f6f-4d2c-abca-fd27bae6f05b","price_dollars":"0.4300","delta_fp":"100.00","side":"yes","ts":"2026-09-13T23:45:22.368234Z","ts_ms":1789343122368}}
{"type":"orderbook_delta","sid":1,"seq":75,"msg":{"market_ticker":"KXBTCD-26SEP1417-T76999.99","market_id":"9fc30aa6-9f6f-4d2c-abca-fd27bae6f05b","price_dollars":"0.2900","delta_fp":"-3369.00","side":"no","ts":"2026-09-13T23:45:22.373054Z","ts_ms":1789343122373}}
{"type":"orderbook_delta","sid":1,"seq":76,"msg":{"market_ticker":"KXBTCD-26SEP1417-T76999.99","market_id":"9fc30aa6-9f6f-4d2c-abca-fd27bae6f05b","price_dollars":"0.2600","delta_fp":"3758.00","side":"no","ts":"2026-09-13T23:45:22.373054Z","ts_ms":1789343122373}}
{"type":"orderbook_delta","sid":1,"seq":77,"msg":{"market_ticker":"KXBTCD-26SEP1417-T76999.99","market_id":"9fc30aa6-9f6f-4d2c-abca-fd27bae6f05b","price_dollars":"0.4200","delta_fp":"-3000.00","side":"yes","ts":"2026-09-13T23:45:22.672753Z","ts_ms":1789343122672}}
{"type":"orderbook_delta","sid":1,"seq":78,"msg":{"market_ticker":"KXBTCD-26SEP1417-T76999.99","market_id":"9fc30aa6-9f6f-4d2c-abca-fd27bae6f05b","price_dollars":"0.4300","delta_fp":"3000.00","side":"yes","ts":"2026-09-13T23:45:22.672753Z","ts_ms":1789343122672}}
{"type":"orderbook_delta","sid":1,"seq":79,"msg":{"market_ticker":"KXBTCD-26SEP1417-T76999.99","market_id":"9fc30aa6-9f6f-4d2c-abca-fd27bae6f05b","price_dollars":"0.5500","delta_fp":"5.00","side":"no","ts":"2026-09-13T23:45:22.790949Z","ts_ms":1789343122790}}
{"type":"orderbook_delta","sid":1,"seq":80,"msg":{"market_ticker":"KXBTCD-26SEP1417-T76999.99","market_id":"9fc30aa6-9f6f-4d2c-abca-fd27bae6f05b","price_dollars":"0.5500","delta_fp":"-5.00","side":"no","ts":"2026-09-13T23:45:22.825455Z","ts_ms":1789343122825}}
{"type":"orderbook_delta","sid":1,"seq":81,"msg":{"market_ticker":"KXBTCD-26SEP1417-T76999.99","market_id":"9fc30aa6-9f6f-4d2c-abca-fd27bae6f05b","price_dollars":"0.5500","delta_fp":"5.00","side":"no","ts":"2026-09-13T23:45:22.934928Z","ts_ms":1789343122934}}
{"type":"orderbook_delta","sid":1,"seq":82,"msg":{"market_ticker":"KXBTCD-26SEP1417-T76999.99","market_id":"9fc30aa6-9f6f-4d2c-abca-fd27bae6f05b","price_dollars":"0.4200","delta_fp":"-2.00","side":"yes","ts":"2026-09-13T23:45:23.050038Z","ts_ms":1789343123050}}
{"type":"orderbook_delta","sid":1,"seq":83,"msg":{"market_ticker":"KXBTCD-26SEP1417-T76999.99","market_id":"9fc30aa6-9f6f-4d2c-abca-fd27bae6f05b","price_dollars":"0.4300","delta_fp":"2.00","side":"yes","ts":"2026-09-13T23:45:23.050488Z","ts_ms":1789343123050}}
{"type":"orderbook_delta","sid":1,"seq":84,"msg":{"market_ticker":"KXBTCD-26SEP1417-T76999.99","market_id":"9fc30aa6-9f6f-4d2c-abca-fd27bae6f05b","price_dollars":"0.4300","delta_fp":"-5.00","side":"yes","ts":"2026-09-13T23:45:23.121109Z","ts_ms":1789343123121}}
{"type":"orderbook_delta","sid":1,"seq":85,"msg":{"market_ticker":"KXBTCD-26SEP1417-T76999.99","market_id":"9fc30aa6-9f6f-4d2c-abca-fd27bae6f05b","price_dollars":"0.4300","delta_fp":"5.00","side":"yes","ts":"2026-09-13T23:45:23.136085Z","ts_ms":1789343123136}}
{"type":"orderbook_delta","sid":1,"seq":86,"msg":{"market_ticker":"KXBTCD-26SEP1417-T76999.99","market_id":"9fc30aa6-9f6f-4d2c-abca-fd27bae6f05b","price_dollars":"0.5400","delta_fp":"-4.00","side":"no","ts":"2026-09-13T23:45:23.721224Z","ts_ms":1789343123721}}
{"type":"orderbook_delta","sid":1,"seq":87,"msg":{"market_ticker":"KXBTCD-26SEP1417-T76999.99","market_id":"9fc30aa6-9f6f-4d2c-abca-fd27bae6f05b","price_dollars":"0.5300","delta_fp":"4.00","side":"no","ts":"2026-09-13T23:45:23.721224Z","ts_ms":1789343123721}}
{"type":"orderbook_delta","sid":1,"seq":88,"msg":{"market_ticker":"KXBTCD-26SEP1417-T76999.99","market_id":"9fc30aa6-9f6f-4d2c-abca-fd27bae6f05b","price_dollars":"0.4300","delta_fp":"-100.00","side":"yes","ts":"2026-09-13T23:45:24.101644Z","ts_ms":1789343124101}}
{"type":"orderbook_delta","sid":1,"seq":89,"msg":{"market_ticker":"KXBTCD-26SEP1417-T76999.99","market_id":"9fc30aa6-9f6f-4d2c-abca-fd27bae6f05b","price_dollars":"0.3700","delta_fp":"100.00","side":"yes","ts":"2026-09-13T23:45:24.101644Z","ts_ms":1789343124101}}
{"type":"orderbook_delta","sid":1,"seq":90,"msg":{"market_ticker":"KXBTCD-26SEP1417-T76999.99","market_id":"9fc30aa6-9f6f-4d2c-abca-fd27bae6f05b","price_dollars":"0.3700","delta_fp":"-100.00","side":"yes","ts":"2026-09-13T23:45:24.202271Z","ts_ms":1789343124202}}
{"type":"orderbook_delta","sid":1,"seq":91,"msg":{"market_ticker":"KXBTCD-26SEP1417-T76999.99","market_id":"9fc30aa6-9f6f-4d2c-abca-fd27bae6f05b","price_dollars":"0.4300","delta_fp":"100.00","side":"yes","ts":"2026-09-13T23:45:24.202271Z","ts_ms":1789343124202}}
{"type":"orderbook_delta","sid":1,"seq":92,"msg":{"market_ticker":"KXBTCD-26SEP1417-T76999.99","market_id":"9fc30aa6-9f6f-4d2c-abca-fd27bae6f05b","price_dollars":"0.4300","delta_fp":"-100.00","side":"yes","ts":"2026-09-13T23:45:24.217929Z","ts_ms":1789343124217}}
{"type":"orderbook_delta","sid":1,"seq":93,"msg":{"market_ticker":"KXBTCD-26SEP1417-T76999.99","market_id":"9fc30aa6-9f6f-4d2c-abca-fd27bae6f05b","price_dollars":"0.3700","delta_fp":"100.00","side":"yes","ts":"2026-09-13T23:45:24.217929Z","ts_ms":1789343124217}}
{"type":"orderbook_delta","sid":1,"seq":94,"msg":{"market_ticker":"KXBTCD-26SEP1417-T76999.99","market_id":"9fc30aa6-9f6f-4d2c-abca-fd27bae6f05b","price_dollars":"0.3700","delta_fp":"-100.00","side":"yes","ts":"2026-09-13T23:45:24.320207Z","ts_ms":1789343124320}}
{"type":"orderbook_delta","sid":1,"seq":95,"msg":{"market_ticker":"KXBTCD-26SEP1417-T76999.99","market_id":"9fc30aa6-9f6f-4d2c-abca-fd27bae6f05b","price_dollars":"0.4300","delta_fp":"100.00","side":"yes","ts":"2026-09-13T23:45:24.320207Z","ts_ms":1789343124320}}
{"type":"orderbook_delta","sid":1,"seq":96,"msg":{"market_ticker":"KXBTCD-26SEP1417-T76999.99","market_id":"9fc30aa6-9f6f-4d2c-abca-fd27bae6f05b","price_dollars":"0.2600","delta_fp":"-3758.00","side":"no","ts":"2026-09-13T23:45:25.517168Z","ts_ms":1789343125517}}
{"type":"orderbook_delta","sid":1,"seq":97,"msg":{"market_ticker":"KXBTCD-26SEP1417-T76999.99","market_id":"9fc30aa6-9f6f-4d2c-abca-fd27bae6f05b","price_dollars":"0.0200","delta_fp":"26057.00","side":"no","ts":"2026-09-13T23:45:25.517168Z","ts_ms":1789343125517}}
{"type":"orderbook_delta","sid":1,"seq":98,"msg":{"market_ticker":"KXBTCD-26SEP1417-T76999.99","market_id":"9fc30aa6-9f6f-4d2c-abca-fd27bae6f05b","price_dollars":"0.0800","delta_fp":"5700.00","side":"no","ts":"2026-09-13T23:45:25.524167Z","ts_ms":1789343125524}}
{"type":"orderbook_delta","sid":1,"seq":99,"msg":{"market_ticker":"KXBTCD-26SEP1417-T76999.99","market_id":"9fc30aa6-9f6f-4d2c-abca-fd27bae6f05b","price_dollars":"0.1600","delta_fp":"8549.00","side":"no","ts":"2026-09-13T23:45:25.525033Z","ts_ms":1789343125525}}
{"type":"orderbook_delta","sid":1,"seq":100,"msg":{"market_ticker":"KXBTCD-26SEP1417-T76999.99","market_id":"9fc30aa6-9f6f-4d2c-abca-fd27bae6f05b","price_dollars":"0.3000","delta_fp":"3257.00","side":"no","ts":"2026-09-13T23:45:25.525484Z","ts_ms":1789343125525}}
{"type":"orderbook_delta","sid":1,"seq":101,"msg":{"market_ticker":"KXBTCD-26SEP1417-T76999.99","market_id":"9fc30aa6-9f6f-4d2c-abca-fd27bae6f05b","price_dollars":"0.0200","delta_fp":"-26057.00","side":"no","ts":"2026-09-13T23:45:26.234018Z","ts_ms":1789343126234}}
{"type":"orderbook_delta","sid":1,"seq":102,"msg":{"market_ticker":"KXBTCD-26SEP1417-T76999.99","market_id":"9fc30aa6-9f6f-4d2c-abca-fd27bae6f05b","price_dollars":"0.0800","delta_fp":"-5700.00","side":"no","ts":"2026-09-13T23:45:26.234599Z","ts_ms":1789343126234}}
{"type":"orderbook_delta","sid":1,"seq":103,"msg":{"market_ticker":"KXBTCD-26SEP1417-T76999.99","market_id":"9fc30aa6-9f6f-4d2c-abca-fd27bae6f05b","price_dollars":"0.1600","delta_fp":"-8549.00","side":"no","ts":"2026-09-13T23:45:26.23521Z","ts_ms":1789343126235}}
{"type":"orderbook_delta","sid":1,"seq":104,"msg":{"market_ticker":"KXBTCD-26SEP1417-T76999.99","market_id":"9fc30aa6-9f6f-4d2c-abca-fd27bae6f05b","price_dollars":"0.3000","delta_fp":"-3257.00","side":"no","ts":"2026-09-13T23:45:26.242606Z","ts_ms":1789343126242}}
{"type":"orderbook_delta","sid":1,"seq":105,"msg":{"market_ticker":"KXBTCD-26SEP1417-T76999.99","market_id":"9fc30aa6-9f6f-4d2c-abca-fd27bae6f05b","price_dollars":"0.2600","delta_fp":"3758.00","side":"no","ts":"2026-09-13T23:45:26.242606Z","ts_ms":1789343126242}}
{"type":"orderbook_delta","sid":1,"seq":106,"msg":{"market_ticker":"KXBTCD-26SEP1417-T76999.99","market_id":"9fc30aa6-9f6f-4d2c-abca-fd27bae6f05b","price_dollars":"0.4300","delta_fp":"-100.00","side":"yes","ts":"2026-09-13T23:45:26.297052Z","ts_ms":1789343126297}}
{"type":"orderbook_delta","sid":1,"seq":107,"msg":{"market_ticker":"KXBTCD-26SEP1417-T76999.99","market_id":"9fc30aa6-9f6f-4d2c-abca-fd27bae6f05b","price_dollars":"0.3700","delta_fp":"100.00","side":"yes","ts":"2026-09-13T23:45:26.297052Z","ts_ms":1789343126297}}
{"type":"orderbook_delta","sid":1,"seq":108,"msg":{"market_ticker":"KXBTCD-26SEP1417-T76999.99","market_id":"9fc30aa6-9f6f-4d2c-abca-fd27bae6f05b","price_dollars":"0.3700","delta_fp":"-100.00","side":"yes","ts":"2026-09-13T23:45:26.406213Z","ts_ms":1789343126406}}
{"type":"orderbook_delta","sid":1,"seq":109,"msg":{"market_ticker":"KXBTCD-26SEP1417-T76999.99","market_id":"9fc30aa6-9f6f-4d2c-abca-fd27bae6f05b","price_dollars":"0.4300","delta_fp":"100.00","side":"yes","ts":"2026-09-13T23:45:26.406213Z","ts_ms":1789343126406}}
{"type":"orderbook_delta","sid":1,"seq":110,"msg":{"market_ticker":"KXBTCD-26SEP1417-T76999.99","market_id":"9fc30aa6-9f6f-4d2c-abca-fd27bae6f05b","price_dollars":"0.4300","delta_fp":"-100.00","side":"yes","ts":"2026-09-13T23:45:27.076692Z","ts_ms":1789343127076}}
{"type":"orderbook_delta","sid":1,"seq":111,"msg":{"market_ticker":"KXBTCD-26SEP1417-T76999.99","market_id":"9fc30aa6-9f6f-4d2c-abca-fd27bae6f05b","price_dollars":"0.3700","delta_fp":"100.00","side":"yes","ts":"2026-09-13T23:45:27.076692Z","ts_ms":1789343127076}}
{"type":"orderbook_delta","sid":1,"seq":112,"msg":{"market_ticker":"KXBTCD-26SEP1417-T76999.99","market_id":"9fc30aa6-9f6f-4d2c-abca-fd27bae6f05b","price_dollars":"0.3700","delta_fp":"-100.00","side":"yes","ts":"2026-09-13T23:45:27.231844Z","ts_ms":1789343127231}}
{"type":"orderbook_delta","sid":1,"seq":113,"msg":{"market_ticker":"KXBTCD-26SEP1417-T76999.99","market_id":"9fc30aa6-9f6f-4d2c-abca-fd27bae6f05b","price_dollars":"0.4300","delta_fp":"100.00","side":"yes","ts":"2026-09-13T23:45:27.231844Z","ts_ms":1789343127231}}
{"type":"orderbook_delta","sid":1,"seq":114,"msg":{"market_ticker":"KXBTCD-26SEP1417-T76999.99","market_id":"9fc30aa6-9f6f-4d2c-abca-fd27bae6f05b","price_dollars":"0.4300","delta_fp":"-100.00","side":"yes","ts":"2026-09-13T23:45:27.239766Z","ts_ms":1789343127239}}
{"type":"orderbook_delta","sid":1,"seq":115,"msg":{"market_ticker":"KXBTCD-26SEP1417-T76999.99","market_id":"9fc30aa6-9f6f-4d2c-abca-fd27bae6f05b","price_dollars":"0.3700","delta_fp":"100.00","side":"yes","ts":"2026-09-13T23:45:27.239766Z","ts_ms":1789343127239}}
{"type":"orderbook_delta","sid":1,"seq":116,"msg":{"market_ticker":"KXBTCD-26SEP1417-T76999.99","market_id":"9fc30aa6-9f6f-4d2c-abca-fd27bae6f05b","price_dollars":"0.3700","delta_fp":"-100.00","side":"yes","ts":"2026-09-13T23:45:27.430614Z","ts_ms":1789343127430}}
{"type":"orderbook_delta","sid":1,"seq":117,"msg":{"market_ticker":"KXBTCD-26SEP1417-T76999.99","market_id":"9fc30aa6-9f6f-4d2c-abca-fd27bae6f05b","price_dollars":"0.4300","delta_fp":"100.00","side":"yes","ts":"2026-09-13T23:45:27.430614Z","ts_ms":1789343127430}}
{"type":"orderbook_delta","sid":1,"seq":118,"msg":{"market_ticker":"KXBTCD-26SEP1417-T76999.99","market_id":"9fc30aa6-9f6f-4d2c-abca-fd27bae6f05b","price_dollars":"0.4300","delta_fp":"-100.00","side":"yes","ts":"2026-09-13T23:45:27.438392Z","ts_ms":1789343127438}}
{"type":"orderbook_delta","sid":1,"seq":119,"msg":{"market_ticker":"KXBTCD-26SEP1417-T76999.99","market_id":"9fc30aa6-9f6f-4d2c-abca-fd27bae6f05b","price_dollars":"0.3700","delta_fp":"100.00","side":"yes","ts":"2026-09-13T23:45:27.438392Z","ts_ms":1789343127438}}
{"type":"orderbook_delta","sid":1,"seq":120,"msg":{"market_ticker":"KXBTCD-26SEP1417-T76999.99","market_id":"9fc30aa6-9f6f-4d2c-abca-fd27bae6f05b","price_dollars":"0.3700","delta_fp":"-100.00","side":"yes","ts":"2026-09-13T23:45:28.301549Z","ts_ms":1789343128301}}
{"type":"orderbook_delta","sid":1,"seq":121,"msg":{"market_ticker":"KXBTCD-26SEP1417-T76999.99","market_id":"9fc30aa6-9f6f-4d2c-abca-fd27bae6f05b","price_dollars":"0.4300","delta_fp":"100.00","side":"yes","ts":"2026-09-13T23:45:28.301549Z","ts_ms":1789343128301}}
{"type":"orderbook_delta","sid":1,"seq":122,"msg":{"market_ticker":"KXBTCD-26SEP1417-T76999.99","market_id":"9fc30aa6-9f6f-4d2c-abca-fd27bae6f05b","price_dollars":"0.4300","delta_fp":"-100.00","side":"yes","ts":"2026-09-13T23:45:28.38295Z","ts_ms":1789343128382}}
{"type":"orderbook_delta","sid":1,"seq":123,"msg":{"market_ticker":"KXBTCD-26SEP1417-T76999.99","market_id":"9fc30aa6-9f6f-4d2c-abca-fd27bae6f05b","price_dollars":"0.3700","delta_fp":"100.00","side":"yes","ts":"2026-09-13T23:45:28.38295Z","ts_ms":1789343128382}}
{"type":"orderbook_delta","sid":1,"seq":124,"msg":{"market_ticker":"KXBTCD-26SEP1417-T76999.99","market_id":"9fc30aa6-9f6f-4d2c-abca-fd27bae6f05b","price_dollars":"0.4300","delta_fp":"-2.00","side":"yes","ts":"2026-09-13T23:45:30.087915Z","ts_ms":1789343130087}}
{"type":"orderbook_delta","sid":1,"seq":125,"msg":{"market_ticker":"KXBTCD-26SEP1417-T76999.99","market_id":"9fc30aa6-9f6f-4d2c-abca-fd27bae6f05b","price_dollars":"0.4200","delta_fp":"2.00","side":"yes","ts":"2026-09-13T23:45:30.088525Z","ts_ms":1789343130088}}
{"type":"orderbook_delta","sid":1,"seq":126,"msg":{"market_ticker":"KXBTCD-26SEP1417-T76999.99","market_id":"9fc30aa6-9f6f-4d2c-abca-fd27bae6f05b","price_dollars":"0.3700","delta_fp":"-100.00","side":"yes","ts":"2026-09-13T23:45:30.745545Z","ts_ms":1789343130745}}
{"type":"orderbook_delta","sid":1,"seq":127,"msg":{"market_ticker":"KXBTCD-26SEP1417-T76999.99","market_id":"9fc30aa6-9f6f-4d2c-abca-fd27bae6f05b","price_dollars":"0.4300","delta_fp":"100.00","side":"yes","ts":"2026-09-13T23:45:30.745545Z","ts_ms":1789343130745}}
{"type":"orderbook_delta","sid":1,"seq":128,"msg":{"market_ticker":"KXBTCD-26SEP1417-T76999.99","market_id":"9fc30aa6-9f6f-4d2c-abca-fd27bae6f05b","price_dollars":"0.4300","delta_fp":"-100.00","side":"yes","ts":"2026-09-13T23:45:30.753639Z","ts_ms":1789343130753}}
{"type":"orderbook_delta","sid":1,"seq":129,"msg":{"market_ticker":"KXBTCD-26SEP1417-T76999.99","market_id":"9fc30aa6-9f6f-4d2c-abca-fd27bae6f05b","price_dollars":"0.3700","delta_fp":"100.00","side":"yes","ts":"2026-09-13T23:45:30.753639Z","ts_ms":1789343130753}}
{"type":"orderbook_delta","sid":1,"seq":130,"msg":{"market_ticker":"KXBTCD-26SEP1417-T76999.99","market_id":"9fc30aa6-9f6f-4d2c-abca-fd27bae6f05b","price_dollars":"0.3700","delta_fp":"-100.00","side":"yes","ts":"2026-09-13T23:45:30.867949Z","ts_ms":1789343130867}}
{"type":"orderbook_delta","sid":1,"seq":131,"msg":{"market_ticker":"KXBTCD-26SEP1417-T76999.99","market_id":"9fc30aa6-9f6f-4d2c-abca-fd27bae6f05b","price_dollars":"0.4300","delta_fp":"100.00","side":"yes","ts":"2026-09-13T23:45:30.867949Z","ts_ms":1789343130867}}
{"type":"orderbook_delta","sid":1,"seq":132,"msg":{"market_ticker":"KXBTCD-26SEP1417-T76999.99","market_id":"9fc30aa6-9f6f-4d2c-abca-fd27bae6f05b","price_dollars":"0.4200","delta_fp":"-2.00","side":"yes","ts":"2026-09-13T23:45:31.038176Z","ts_ms":1789343131038}}
{"type":"orderbook_delta","sid":1,"seq":133,"msg":{"market_ticker":"KXBTCD-26SEP1417-T76999.99","market_id":"9fc30aa6-9f6f-4d2c-abca-fd27bae6f05b","price_dollars":"0.4300","delta_fp":"2.00","side":"yes","ts":"2026-09-13T23:45:31.03888Z","ts_ms":1789343131038}}
{"type":"orderbook_delta","sid":1,"seq":134,"msg":{"market_ticker":"KXBTCD-26SEP1417-T76999.99","market_id":"9fc30aa6-9f6f-4d2c-abca-fd27bae6f05b","price_dollars":"0.4300","delta_fp":"-100.00","side":"yes","ts":"2026-09-13T23:45:32.361778Z","ts_ms":1789343132361}}
{"type":"orderbook_delta","sid":1,"seq":135,"msg":{"market_ticker":"KXBTCD-26SEP1417-T76999.99","market_id":"9fc30aa6-9f6f-4d2c-abca-fd27bae6f05b","price_dollars":"0.3700","delta_fp":"100.00","side":"yes","ts":"2026-09-13T23:45:32.361778Z","ts_ms":1789343132361}}
{"type":"orderbook_delta","sid":1,"seq":136,"msg":{"market_ticker":"KXBTCD-26SEP1417-T76999.99","market_id":"9fc30aa6-9f6f-4d2c-abca-fd27bae6f05b","price_dollars":"0.3700","delta_fp":"-100.00","side":"yes","ts":"2026-09-13T23:45:32.463007Z","ts_ms":1789343132463}}
{"type":"orderbook_delta","sid":1,"seq":137,"msg":{"market_ticker":"KXBTCD-26SEP1417-T76999.99","market_id":"9fc30aa6-9f6f-4d2c-abca-fd27bae6f05b","price_dollars":"0.4300","delta_fp":"100.00","side":"yes","ts":"2026-09-13T23:45:32.463007Z","ts_ms":1789343132463}}
{"type":"orderbook_delta","sid":1,"seq":138,"msg":{"market_ticker":"KXBTCD-26SEP1417-T76999.99","market_id":"9fc30aa6-9f6f-4d2c-abca-fd27bae6f05b","price_dollars":"0.4300","delta_fp":"-100.00","side":"yes","ts":"2026-09-13T23:45:32.558909Z","ts_ms":1789343132558}}
{"type":"orderbook_delta","sid":1,"seq":139,"msg":{"market_ticker":"KXBTCD-26SEP1417-T76999.99","market_id":"9fc30aa6-9f6f-4d2c-abca-fd27bae6f05b","price_dollars":"0.3700","delta_fp":"100.00","side":"yes","ts":"2026-09-13T23:45:32.558909Z","ts_ms":1789343132558}}
{"type":"orderbook_delta","sid":1,"seq":140,"msg":{"market_ticker":"KXBTCD-26SEP1417-T76999.99","market_id":"9fc30aa6-9f6f-4d2c-abca-fd27bae6f05b","price_dollars":"0.5400","delta_fp":"-1000.00","side":"no","ts":"2026-09-13T23:45:32.653313Z","ts_ms":1789343132653}}
{"type":"orderbook_delta","sid":1,"seq":141,"msg":{"market_ticker":"KXBTCD-26SEP1417-T76999.99","market_id":"9fc30aa6-9f6f-4d2c-abca-fd27bae6f05b","price_dollars":"0.5500","delta_fp":"1000.00","side":"no","ts":"2026-09-13T23:45:32.653313Z","ts_ms":1789343132653}}
{"type":"orderbook_delta","sid":1,"seq":142,"msg":{"market_ticker":"KXBTCD-26SEP1417-T76999.99","market_id":"9fc30aa6-9f6f-4d2c-abca-fd27bae6f05b","price_dollars":"0.3700","delta_fp":"-100.00","side":"yes","ts":"2026-09-13T23:45:32.659569Z","ts_ms":1789343132659}}
{"type":"orderbook_delta","sid":1,"seq":143,"msg":{"market_ticker":"KXBTCD-26SEP1417-T76999.99","market_id":"9fc30aa6-9f6f-4d2c-abca-fd27bae6f05b","price_dollars":"0.4300","delta_fp":"100.00","side":"yes","ts":"2026-09-13T23:45:32.659569Z","ts_ms":1789343132659}}
{"type":"orderbook_delta","sid":1,"seq":144,"msg":{"market_ticker":"KXBTCD-26SEP1417-T76999.99","market_id":"9fc30aa6-9f6f-4d2c-abca-fd27bae6f05b","price_dollars":"0.5500","delta_fp":"-1000.00","side":"no","ts":"2026-09-13T23:45:32.663765Z","ts_ms":1789343132663}}
{"type":"orderbook_delta","sid":1,"seq":145,"msg":{"market_ticker":"KXBTCD-26SEP1417-T76999.99","market_id":"9fc30aa6-9f6f-4d2c-abca-fd27bae6f05b","price_dollars":"0.4300","delta_fp":"-3000.00","side":"yes","ts":"2026-09-13T23:45:32.664031Z","ts_ms":1789343132664}}
{"type":"orderbook_delta","sid":1,"seq":146,"msg":{"market_ticker":"KXBTCD-26SEP1417-T76999.99","market_id":"9fc30aa6-9f6f-4d2c-abca-fd27bae6f05b","price_dollars":"0.4200","delta_fp":"3000.00","side":"yes","ts":"2026-09-13T23:45:32.664031Z","ts_ms":1789343132664}}
{"type":"orderbook_delta","sid":1,"seq":147,"msg":{"market_ticker":"KXBTCD-26SEP1417-T76999.99","market_id":"9fc30aa6-9f6f-4d2c-abca-fd27bae6f05b","price_dollars":"0.4300","delta_fp":"-100.00","side":"yes","ts":"2026-09-13T23:45:32.672562Z","ts_ms":1789343132672}}
{"type":"orderbook_delta","sid":1,"seq":148,"msg":{"market_ticker":"KXBTCD-26SEP1417-T76999.99","market_id":"9fc30aa6-9f6f-4d2c-abca-fd27bae6f05b","price_dollars":"0.3700","delta_fp":"100.00","side":"yes","ts":"2026-09-13T23:45:32.672562Z","ts_ms":1789343132672}}
{"type":"orderbook_delta","sid":1,"seq":149,"msg":{"market_ticker":"KXBTCD-26SEP1417-T76999.99","market_id":"9fc30aa6-9f6f-4d2c-abca-fd27bae6f05b","price_dollars":"0.4300","delta_fp":"241.00","side":"yes","ts":"2026-09-13T23:45:32.691471Z","ts_ms":1789343132691}}
{"type":"orderbook_delta","sid":1,"seq":150,"msg":{"market_ticker":"KXBTCD-26SEP1417-T76999.99","market_id":"9fc30aa6-9f6f-4d2c-abca-fd27bae6f05b","price_dollars":"0.4200","delta_fp":"-1000.00","side":"yes","ts":"2026-09-13T23:45:32.717333Z","ts_ms":1789343132717}}
{"type":"orderbook_delta","sid":1,"seq":151,"msg":{"market_ticker":"KXBTCD-26SEP1417-T76999.99","market_id":"9fc30aa6-9f6f-4d2c-abca-fd27bae6f05b","price_dollars":"0.4100","delta_fp":"1000.00","side":"yes","ts":"2026-09-13T23:45:32.717333Z","ts_ms":1789343132717}}
{"type":"orderbook_delta","sid":1,"seq":152,"msg":{"market_ticker":"KXBTCD-26SEP1417-T76999.99","market_id":"9fc30aa6-9f6f-4d2c-abca-fd27bae6f05b","price_dollars":"0.4100","delta_fp":"-384.00","side":"yes","ts":"2026-09-13T23:45:32.719918Z","ts_ms":1789343132719}}
{"type":"orderbook_delta","sid":1,"seq":153,"msg":{"market_ticker":"KXBTCD-26SEP1417-T76999.99","market_id":"9fc30aa6-9f6f-4d2c-abca-fd27bae6f05b","price_dollars":"0.4300","delta_fp":"-241.00","side":"yes","ts":"2026-09-13T23:45:32.723939Z","ts_ms":1789343132723}}
{"type":"orderbook_delta","sid":1,"seq":154,"msg":{"market_ticker":"KXBTCD-26SEP1417-T76999.99","market_id":"9fc30aa6-9f6f-4d2c-abca-fd27bae6f05b","price_dollars":"0.5500","delta_fp":"1000.00","side":"no","ts":"2026-09-13T23:45:32.728669Z","ts_ms":1789343132728}}
{"type":"orderbook_delta","sid":1,"seq":155,"msg":{"market_ticker":"KXBTCD-26SEP1417-T76999.99","market_id":"9fc30aa6-9f6f-4d2c-abca-fd27bae6f05b","price_dollars":"0.4200","delta_fp":"-1000.00","side":"yes","ts":"2026-09-13T23:45:32.738577Z","ts_ms":1789343132738}}
{"type":"orderbook_delta","sid":1,"seq":156,"msg":{"market_ticker":"KXBTCD-26SEP1417-T76999.99","market_id":"9fc30aa6-9f6f-4d2c-abca-fd27bae6f05b","price_dollars":"0.4100","delta_fp":"1000.00","side":"yes","ts":"2026-09-13T23:45:32.738577Z","ts_ms":1789343132738}}
{"type":"orderbook_delta","sid":1,"seq":157,"msg":{"market_ticker":"KXBTCD-26SEP1417-T76999.99","market_id":"9fc30aa6-9f6f-4d2c-abca-fd27bae6f05b","price_dollars":"0.5400","delta_fp":"-1000.00","side":"no","ts":"2026-09-13T23:45:32.743582Z","ts_ms":1789343132743}}
{"type":"orderbook_delta","sid":1,"seq":158,"msg":{"market_ticker":"KXBTCD-26SEP1417-T76999.99","market_id":"9fc30aa6-9f6f-4d2c-abca-fd27bae6f05b","price_dollars":"0.5500","delta_fp":"1000.00","side":"no","ts":"2026-09-13T23:45:32.743582Z","ts_ms":1789343132743}}
{"type":"orderbook_delta","sid":1,"seq":159,"msg":{"market_ticker":"KXBTCD-26SEP1417-T76999.99","market_id":"9fc30aa6-9f6f-4d2c-abca-fd27bae6f05b","price_dollars":"0.3700","delta_fp":"-100.00","side":"yes","ts":"2026-09-13T23:45:32.779104Z","ts_ms":1789343132779}}
{"type":"orderbook_delta","sid":1,"seq":160,"msg":{"market_ticker":"KXBTCD-26SEP1417-T76999.99","market_id":"9fc30aa6-9f6f-4d2c-abca-fd27bae6f05b","price_dollars":"0.4300","delta_fp":"100.00","side":"yes","ts":"2026-09-13T23:45:32.779104Z","ts_ms":1789343132779}}
{"type":"orderbook_delta","sid":1,"seq":161,"msg":{"market_ticker":"KXBTCD-26SEP1417-T76999.99","market_id":"9fc30aa6-9f6f-4d2c-abca-fd27bae6f05b","price_dollars":"0.4300","delta_fp":"-2.00","side":"yes","ts":"2026-09-13T23:45:32.838098Z","ts_ms":1789343132838}}
{"type":"orderbook_delta","sid":1,"seq":162,"msg":{"market_ticker":"KXBTCD-26SEP1417-T76999.99","market_id":"9fc30aa6-9f6f-4d2c-abca-fd27bae6f05b","price_dollars":"0.4200","delta_fp":"2.00","side":"yes","ts":"2026-09-13T23:45:32.838907Z","ts_ms":1789343132838}}
{"type":"orderbook_delta","sid":1,"seq":163,"msg":{"market_ticker":"KXBTCD-26SEP1417-T76999.99","market_id":"9fc30aa6-9f6f-4d2c-abca-fd27bae6f05b","price_dollars":"0.5500","delta_fp":"-1000.00","side":"no","ts":"2026-09-13T23:45:32.98604Z","ts_ms":1789343132986}}
{"type":"orderbook_delta","sid":1,"seq":164,"msg":{"market_ticker":"KXBTCD-26SEP1417-T76999.99","market_id":"9fc30aa6-9f6f-4d2c-abca-fd27bae6f05b","price_dollars":"0.5400","delta_fp":"1000.00","side":"no","ts":"2026-09-13T23:45:32.98604Z","ts_ms":1789343132986}}
{"type":"orderbook_delta","sid":1,"seq":165,"msg":{"market_ticker":"KXBTCD-26SEP1417-T76999.99","market_id":"9fc30aa6-9f6f-4d2c-abca-fd27bae6f05b","price_dollars":"0.4100","delta_fp":"-1000.00","side":"yes","ts":"2026-09-13T23:45:32.990381Z","ts_ms":1789343132990}}
{"type":"orderbook_delta","sid":1,"seq":166,"msg":{"market_ticker":"KXBTCD-26SEP1417-T76999.99","market_id":"9fc30aa6-9f6f-4d2c-abca-fd27bae6f05b","price_dollars":"0.4200","delta_fp":"1000.00","side":"yes","ts":"2026-09-13T23:45:32.990381Z","ts_ms":1789343132990}}
{"type":"orderbook_delta","sid":1,"seq":167,"msg":{"market_ticker":"KXBTCD-26SEP1417-T76999.99","market_id":"9fc30aa6-9f6f-4d2c-abca-fd27bae6f05b","price_dollars":"0.5500","delta_fp":"-1000.00","side":"no","ts":"2026-09-13T23:45:33.043689Z","ts_ms":1789343133043}}
{"type":"orderbook_delta","sid":1,"seq":168,"msg":{"market_ticker":"KXBTCD-26SEP1417-T76999.99","market_id":"9fc30aa6-9f6f-4d2c-abca-fd27bae6f05b","price_dollars":"0.5400","delta_fp":"1000.00","side":"no","ts":"2026-09-13T23:45:33.043689Z","ts_ms":1789343133043}}
{"type":"orderbook_delta","sid":1,"seq":169,"msg":{"market_ticker":"KXBTCD-26SEP1417-T76999.99","market_id":"9fc30aa6-9f6f-4d2c-abca-fd27bae6f05b","price_dollars":"0.4300","delta_fp":"-100.00","side":"yes","ts":"2026-09-13T23:45:33.051957Z","ts_ms":1789343133051}}
{"type":"orderbook_delta","sid":1,"seq":170,"msg":{"market_ticker":"KXBTCD-26SEP1417-T76999.99","market_id":"9fc30aa6-9f6f-4d2c-abca-fd27bae6f05b","price_dollars":"0.3700","delta_fp":"100.00","side":"yes","ts":"2026-09-13T23:45:33.051957Z","ts_ms":1789343133051}}
{"type":"orderbook_delta","sid":1,"seq":171,"msg":{"market_ticker":"KXBTCD-26SEP1417-T76999.99","market_id":"9fc30aa6-9f6f-4d2c-abca-fd27bae6f05b","price_dollars":"0.4100","delta_fp":"-1000.00","side":"yes","ts":"2026-09-13T23:45:33.055456Z","ts_ms":1789343133055}}
{"type":"orderbook_delta","sid":1,"seq":172,"msg":{"market_ticker":"KXBTCD-26SEP1417-T76999.99","market_id":"9fc30aa6-9f6f-4d2c-abca-fd27bae6f05b","price_dollars":"0.4200","delta_fp":"1000.00","side":"yes","ts":"2026-09-13T23:45:33.055456Z","ts_ms":1789343133055}}
{"type":"orderbook_delta","sid":1,"seq":173,"msg":{"market_ticker":"KXBTCD-26SEP1417-T76999.99","market_id":"9fc30aa6-9f6f-4d2c-abca-fd27bae6f05b","price_dollars":"0.4100","delta_fp":"-50.00","side":"yes","ts":"2026-09-13T23:45:33.122076Z","ts_ms":1789343133122}}
{"type":"orderbook_delta","sid":1,"seq":174,"msg":{"market_ticker":"KXBTCD-26SEP1417-T76999.99","market_id":"9fc30aa6-9f6f-4d2c-abca-fd27bae6f05b","price_dollars":"0.3200","delta_fp":"50.00","side":"yes","ts":"2026-09-13T23:45:33.12497Z","ts_ms":1789343133124}}
{"type":"orderbook_delta","sid":1,"seq":175,"msg":{"market_ticker":"KXBTCD-26SEP1417-T76999.99","market_id":"9fc30aa6-9f6f-4d2c-abca-fd27bae6f05b","price_dollars":"0.4400","delta_fp":"-50.00","side":"no","ts":"2026-09-13T23:45:33.12682Z","ts_ms":1789343133126}}
{"type":"orderbook_delta","sid":1,"seq":176,"msg":{"market_ticker":"KXBTCD-26SEP1417-T76999.99","market_id":"9fc30aa6-9f6f-4d2c-abca-fd27bae6f05b","price_dollars":"0.5300","delta_fp":"50.00","side":"no","ts":"2026-09-13T23:45:33.128373Z","ts_ms":1789343133128}}
{"type":"orderbook_delta","sid":1,"seq":177,"msg":{"market_ticker":"KXBTCD-26SEP1417-T76999.99","market_id":"9fc30aa6-9f6f-4d2c-abca-fd27bae6f05b","price_dollars":"0.4200","delta_fp":"-3000.00","side":"yes","ts":"2026-09-13T23:45:33.20786Z","ts_ms":1789343133207}}
{"type":"orderbook_delta","sid":1,"seq":178,"msg":{"market_ticker":"KXBTCD-26SEP1417-T76999.99","market_id":"9fc30aa6-9f6f-4d2c-abca-fd27bae6f05b","price_dollars":"0.4300","delta_fp":"3000.00","side":"yes","ts":"2026-09-13T23:45:33.20786Z","ts_ms":1789343133207}}
{"type":"orderbook_delta","sid":1,"seq":179,"msg":{"market_ticker":"KXBTCD-26SEP1417-T76999.99","market_id":"9fc30aa6-9f6f-4d2c-abca-fd27bae6f05b","price_dollars":"0.4200","delta_fp":"-1000.00","side":"yes","ts":"2026-09-13T23:45:33.692486Z","ts_ms":1789343133692}}
{"type":"orderbook_delta","sid":1,"seq":180,"msg":{"market_ticker":"KXBTCD-26SEP1417-T76999.99","market_id":"9fc30aa6-9f6f-4d2c-abca-fd27bae6f05b","price_dollars":"0.4100","delta_fp":"1000.00","side":"yes","ts":"2026-09-13T23:45:33.692486Z","ts_ms":1789343133692}}
{"type":"orderbook_delta","sid":1,"seq":181,"msg":{"market_ticker":"KXBTCD-26SEP1417-T76999.99","market_id":"9fc30aa6-9f6f-4d2c-abca-fd27bae6f05b","price_dollars":"0.5400","delta_fp":"-1000.00","side":"no","ts":"2026-09-13T23:45:33.702542Z","ts_ms":1789343133702}}
{"type":"orderbook_delta","sid":1,"seq":182,"msg":{"market_ticker":"KXBTCD-26SEP1417-T76999.99","market_id":"9fc30aa6-9f6f-4d2c-abca-fd27bae6f05b","price_dollars":"0.5500","delta_fp":"1000.00","side":"no","ts":"2026-09-13T23:45:33.702542Z","ts_ms":1789343133702}}
{"type":"orderbook_delta","sid":1,"seq":183,"msg":{"market_ticker":"KXBTCD-26SEP1417-T76999.99","market_id":"9fc30aa6-9f6f-4d2c-abca-fd27bae6f05b","price_dollars":"0.4200","delta_fp":"-1000.00","side":"yes","ts":"2026-09-13T23:45:33.703268Z","ts_ms":1789343133703}}
{"type":"orderbook_delta","sid":1,"seq":184,"msg":{"market_ticker":"KXBTCD-26SEP1417-T76999.99","market_id":"9fc30aa6-9f6f-4d2c-abca-fd27bae6f05b","price_dollars":"0.4100","delta_fp":"1000.00","side":"yes","ts":"2026-09-13T23:45:33.703268Z","ts_ms":1789343133703}}
{"type":"orderbook_delta","sid":1,"seq":185,"msg":{"market_ticker":"KXBTCD-26SEP1417-T76999.99","market_id":"9fc30aa6-9f6f-4d2c-abca-fd27bae6f05b","price_dollars":"0.5400","delta_fp":"-1000.00","side":"no","ts":"2026-09-13T23:45:33.704555Z","ts_ms":1789343133704}}
{"type":"orderbook_delta","sid":1,"seq":186,"msg":{"market_ticker":"KXBTCD-26SEP1417-T76999.99","market_id":"9fc30aa6-9f6f-4d2c-abca-fd27bae6f05b","price_dollars":"0.5500","delta_fp":"1000.00","side":"no","ts":"2026-09-13T23:45:33.704555Z","ts_ms":1789343133704}}
{"type":"orderbook_delta","sid":1,"seq":187,"msg":{"market_ticker":"KXBTCD-26SEP1417-T76999.99","market_id":"9fc30aa6-9f6f-4d2c-abca-fd27bae6f05b","price_dollars":"0.3700","delta_fp":"-100.00","side":"yes","ts":"2026-09-13T23:45:33.710676Z","ts_ms":1789343133710}}
{"type":"orderbook_delta","sid":1,"seq":188,"msg":{"market_ticker":"KXBTCD-26SEP1417-T76999.99","market_id":"9fc30aa6-9f6f-4d2c-abca-fd27bae6f05b","price_dollars":"0.4300","delta_fp":"100.00","side":"yes","ts":"2026-09-13T23:45:33.710676Z","ts_ms":1789343133710}}
{"type":"orderbook_delta","sid":1,"seq":189,"msg":{"market_ticker":"KXBTCD-26SEP1417-T76999.99","market_id":"9fc30aa6-9f6f-4d2c-abca-fd27bae6f05b","price_dollars":"0.4100","delta_fp":"-1000.00","side":"yes","ts":"2026-09-13T23:45:33.854632Z","ts_ms":1789343133854}}
{"type":"orderbook_delta","sid":1,"seq":190,"msg":{"market_ticker":"KXBTCD-26SEP1417-T76999.99","market_id":"9fc30aa6-9f6f-4d2c-abca-fd27bae6f05b","price_dollars":"0.4200","delta_fp":"1000.00","side":"yes","ts":"2026-09-13T23:45:33.854632Z","ts_ms":1789343133854}}
{"type":"orderbook_delta","sid":1,"seq":191,"msg":{"market_ticker":"KXBTCD-26SEP1417-T76999.99","market_id":"9fc30aa6-9f6f-4d2c-abca-fd27bae6f05b","price_dollars":"0.5500","delta_fp":"-1000.00","side":"no","ts":"2026-09-13T23:45:33.856217Z","ts_ms":1789343133856}}
{"type":"orderbook_delta","sid":1,"seq":192,"msg":{"market_ticker":"KXBTCD-26SEP1417-T76999.99","market_id":"9fc30aa6-9f6f-4d2c-abca-fd27bae6f05b","price_dollars":"0.5400","delta_fp":"1000.00","side":"no","ts":"2026-09-13T23:45:33.856217Z","ts_ms":1789343133856}}
{"type":"orderbook_delta","sid":1,"seq":193,"msg":{"market_ticker":"KXBTCD-26SEP1417-T76999.99","market_id":"9fc30aa6-9f6f-4d2c-abca-fd27bae6f05b","price_dollars":"0.5500","delta_fp":"-1000.00","side":"no","ts":"2026-09-13T23:45:34.010001Z","ts_ms":1789343134010}}
{"type":"orderbook_delta","sid":1,"seq":194,"msg":{"market_ticker":"KXBTCD-26SEP1417-T76999.99","market_id":"9fc30aa6-9f6f-4d2c-abca-fd27bae6f05b","price_dollars":"0.5400","delta_fp":"1000.00","side":"no","ts":"2026-09-13T23:45:34.010001Z","ts_ms":1789343134010}}
{"type":"orderbook_delta","sid":1,"seq":195,"msg":{"market_ticker":"KXBTCD-26SEP1417-T76999.99","market_id":"9fc30aa6-9f6f-4d2c-abca-fd27bae6f05b","price_dollars":"0.4300","delta_fp":"-100.00","side":"yes","ts":"2026-09-13T23:45:34.017394Z","ts_ms":1789343134017}}
{"type":"orderbook_delta","sid":1,"seq":196,"msg":{"market_ticker":"KXBTCD-26SEP1417-T76999.99","market_id":"9fc30aa6-9f6f-4d2c-abca-fd27bae6f05b","price_dollars":"0.3700","delta_fp":"100.00","side":"yes","ts":"2026-09-13T23:45:34.017394Z","ts_ms":1789343134017}}
{"type":"orderbook_delta","sid":1,"seq":197,"msg":{"market_ticker":"KXBTCD-26SEP1417-T76999.99","market_id":"9fc30aa6-9f6f-4d2c-abca-fd27bae6f05b","price_dollars":"0.4100","delta_fp":"-1000.00","side":"yes","ts":"2026-09-13T23:45:34.021695Z","ts_ms":1789343134021}}
{"type":"orderbook_delta","sid":1,"seq":198,"msg":{"market_ticker":"KXBTCD-26SEP1417-T76999.99","market_id":"9fc30aa6-9f6f-4d2c-abca-fd27bae6f05b","price_dollars":"0.4200","delta_fp":"1000.00","side":"yes","ts":"2026-09-13T23:45:34.021695Z","ts_ms":1789343134021}}
{"type":"orderbook_delta","sid":1,"seq":199,"msg":{"market_ticker":"KXBTCD-26SEP1417-T76999.99","market_id":"9fc30aa6-9f6f-4d2c-abca-fd27bae6f05b","price_dollars":"0.3700","delta_fp":"-100.00","side":"yes","ts":"2026-09-13T23:45:37.095023Z","ts_ms":1789343137095}}
{"type":"orderbook_delta","sid":1,"seq":200,"msg":{"market_ticker":"KXBTCD-26SEP1417-T76999.99","market_id":"9fc30aa6-9f6f-4d2c-abca-fd27bae6f05b","price_dollars":"0.4300","delta_fp":"100.00","side":"yes","ts":"2026-09-13T23:45:37.095023Z","ts_ms":1789343137095}}
{"type":"orderbook_delta","sid":1,"seq":201,"msg":{"market_ticker":"KXBTCD-26SEP1417-T76999.99","market_id":"9fc30aa6-9f6f-4d2c-abca-fd27bae6f05b","price_dollars":"0.3200","delta_fp":"-50.00","side":"yes","ts":"2026-09-13T23:45:37.197031Z","ts_ms":1789343137197}}
{"type":"orderbook_delta","sid":1,"seq":202,"msg":{"market_ticker":"KXBTCD-26SEP1417-T76999.99","market_id":"9fc30aa6-9f6f-4d2c-abca-fd27bae6f05b","price_dollars":"0.4100","delta_fp":"50.00","side":"yes","ts":"2026-09-13T23:45:37.200102Z","ts_ms":1789343137200}}
{"type":"orderbook_delta","sid":1,"seq":203,"msg":{"market_ticker":"KXBTCD-26SEP1417-T76999.99","market_id":"9fc30aa6-9f6f-4d2c-abca-fd27bae6f05b","price_dollars":"0.5300","delta_fp":"-50.00","side":"no","ts":"2026-09-13T23:45:37.208056Z","ts_ms":1789343137208}}
{"type":"orderbook_delta","sid":1,"seq":204,"msg":{"market_ticker":"KXBTCD-26SEP1417-T76999.99","market_id":"9fc30aa6-9f6f-4d2c-abca-fd27bae6f05b","price_dollars":"0.4400","delta_fp":"50.00","side":"no","ts":"2026-09-13T23:45:37.210228Z","ts_ms":1789343137210}}
{"type":"orderbook_delta","sid":1,"seq":205,"msg":{"market_ticker":"KXBTCD-26SEP1417-T76999.99","market_id":"9fc30aa6-9f6f-4d2c-abca-fd27bae6f05b","price_dollars":"0.4200","delta_fp":"-2.00","side":"yes","ts":"2026-09-13T23:45:37.822807Z","ts_ms":1789343137822}}
{"type":"orderbook_delta","sid":1,"seq":206,"msg":{"market_ticker":"KXBTCD-26SEP1417-T76999.99","market_id":"9fc30aa6-9f6f-4d2c-abca-fd27bae6f05b","price_dollars":"0.4300","delta_fp":"2.00","side":"yes","ts":"2026-09-13T23:45:37.82341Z","ts_ms":1789343137823}}
{"type":"orderbook_delta","sid":1,"seq":207,"msg":{"market_ticker":"KXBTCD-26SEP1417-T76999.99","market_id":"9fc30aa6-9f6f-4d2c-abca-fd27bae6f05b","price_dollars":"0.4300","delta_fp":"-2.00","side":"yes","ts":"2026-09-13T23:45:39.431476Z","ts_ms":1789343139431}}
{"type":"orderbook_delta","sid":1,"seq":208,"msg":{"market_ticker":"KXBTCD-26SEP1417-T76999.99","market_id":"9fc30aa6-9f6f-4d2c-abca-fd27bae6f05b","price_dollars":"0.4300","delta_fp":"2.00","side":"yes","ts":"2026-09-13T23:45:39.511835Z","ts_ms":1789343139511}}
{"type":"orderbook_delta","sid":1,"seq":209,"msg":{"market_ticker":"KXBTCD-26SEP1417-T76999.99","market_id":"9fc30aa6-9f6f-4d2c-abca-fd27bae6f05b","price_dollars":"0.4200","delta_fp":"377.00","side":"yes","ts":"2026-09-13T23:45:42.881136Z","ts_ms":1789343142881}}
{"type":"orderbook_delta","sid":1,"seq":210,"msg":{"market_ticker":"KXBTCD-26SEP1417-T76999.99","market_id":"9fc30aa6-9f6f-4d2c-abca-fd27bae6f05b","price_dollars":"0.4200","delta_fp":"-1000.00","side":"yes","ts":"2026-09-13T23:45:43.546122Z","ts_ms":1789343143546}}
{"type":"orderbook_delta","sid":1,"seq":211,"msg":{"market_ticker":"KXBTCD-26SEP1417-T76999.99","market_id":"9fc30aa6-9f6f-4d2c-abca-fd27bae6f05b","price_dollars":"0.5500","delta_fp":"-100.00","side":"no","ts":"2026-09-13T23:45:43.571932Z","ts_ms":1789343143571}}
{"type":"orderbook_delta","sid":1,"seq":212,"msg":{"market_ticker":"KXBTCD-26SEP1417-T76999.99","market_id":"9fc30aa6-9f6f-4d2c-abca-fd27bae6f05b","price_dollars":"0.5000","delta_fp":"100.00","side":"no","ts":"2026-09-13T23:45:43.571932Z","ts_ms":1789343143571}}
{"type":"orderbook_delta","sid":1,"seq":213,"msg":{"market_ticker":"KXBTCD-26SEP1417-T76999.99","market_id":"9fc30aa6-9f6f-4d2c-abca-fd27bae6f05b","price_dollars":"0.5500","delta_fp":"-5.00","side":"no","ts":"2026-09-13T23:45:43.582147Z","ts_ms":1789343143582}}
{"type":"orderbook_delta","sid":1,"seq":214,"msg":{"market_ticker":"KXBTCD-26SEP1417-T76999.99","market_id":"9fc30aa6-9f6f-4d2c-abca-fd27bae6f05b","price_dollars":"0.5400","delta_fp":"30.00","side":"no","ts":"2026-09-13T23:45:43.600568Z","ts_ms":1789343143600}}
{"type":"orderbook_delta","sid":1,"seq":215,"msg":{"market_ticker":"KXBTCD-26SEP1417-T76999.99","market_id":"9fc30aa6-9f6f-4d2c-abca-fd27bae6f05b","price_dollars":"0.5000","delta_fp":"-100.00","side":"no","ts":"2026-09-13T23:45:43.676552Z","ts_ms":1789343143676}}
{"type":"orderbook_delta","sid":1,"seq":216,"msg":{"market_ticker":"KXBTCD-26SEP1417-T76999.99","market_id":"9fc30aa6-9f6f-4d2c-abca-fd27bae6f05b","price_dollars":"0.5400","delta_fp":"100.00","side":"no","ts":"2026-09-13T23:45:43.676552Z","ts_ms":1789343143676}}
{"type":"orderbook_delta","sid":1,"seq":217,"msg":{"market_ticker":"KXBTCD-26SEP1417-T76999.99","market_id":"9fc30aa6-9f6f-4d2c-abca-fd27bae6f05b","price_dollars":"0.4000","delta_fp":"-5000.00","side":"yes","ts":"2026-09-13T23:45:43.761564Z","ts_ms":1789343143761}}
{"type":"orderbook_delta","sid":1,"seq":218,"msg":{"market_ticker":"KXBTCD-26SEP1417-T76999.99","market_id":"9fc30aa6-9f6f-4d2c-abca-fd27bae6f05b","price_dollars":"0.4300","delta_fp":"-2.00","side":"yes","ts":"2026-09-13T23:45:43.812402Z","ts_ms":1789343143812}}
{"type":"orderbook_delta","sid":1,"seq":219,"msg":{"market_ticker":"KXBTCD-26SEP1417-T76999.99","market_id":"9fc30aa6-9f6f-4d2c-abca-fd27bae6f05b","price_dollars":"0.4300","delta_fp":"2.00","side":"yes","ts":"2026-09-13T23:45:43.910761Z","ts_ms":1789343143910}}
{"type":"orderbook_delta","sid":1,"seq":220,"msg":{"market_ticker":"KXBTCD-26SEP1417-T76999.99","market_id":"9fc30aa6-9f6f-4d2c-abca-fd27bae6f05b","price_dollars":"0.5400","delta_fp":"-5000.00","side":"no","ts":"2026-09-13T23:45:44.080587Z","ts_ms":1789343144080}}
{"type":"orderbook_delta","sid":1,"seq":221,"msg":{"market_ticker":"KXBTCD-26SEP1417-T76999.99","market_id":"9fc30aa6-9f6f-4d2c-abca-fd27bae6f05b","price_dollars":"0.5400","delta_fp":"-100.00","side":"no","ts":"2026-09-13T23:45:44.138765Z","ts_ms":1789343144138}}
{"type":"orderbook_delta","sid":1,"seq":222,"msg":{"market_ticker":"KXBTCD-26SEP1417-T76999.99","market_id":"9fc30aa6-9f6f-4d2c-abca-fd27bae6f05b","price_dollars":"0.5500","delta_fp":"100.00","side":"no","ts":"2026-09-13T23:45:44.138765Z","ts_ms":1789343144138}}
{"type":"orderbook_delta","sid":1,"seq":223,"msg":{"market_ticker":"KXBTCD-26SEP1417-T76999.99","market_id":"9fc30aa6-9f6f-4d2c-abca-fd27bae6f05b","price_dollars":"0.4000","delta_fp":"-570.00","side":"yes","ts":"2026-09-13T23:45:44.209534Z","ts_ms":1789343144209}}
{"type":"orderbook_delta","sid":1,"seq":224,"msg":{"market_ticker":"KXBTCD-26SEP1417-T76999.99","market_id":"9fc30aa6-9f6f-4d2c-abca-fd27bae6f05b","price_dollars":"0.4400","delta_fp":"567.00","side":"yes","ts":"2026-09-13T23:45:44.209546Z","ts_ms":1789343144209}}
{"type":"orderbook_delta","sid":1,"seq":225,"msg":{"market_ticker":"KXBTCD-26SEP1417-T76999.99","market_id":"9fc30aa6-9f6f-4d2c-abca-fd27bae6f05b","price_dollars":"0.4300","delta_fp":"1000.00","side":"yes","ts":"2026-09-13T23:45:44.288748Z","ts_ms":1789343144288}}
{"type":"orderbook_delta","sid":1,"seq":226,"msg":{"market_ticker":"KXBTCD-26SEP1417-T76999.99","market_id":"9fc30aa6-9f6f-4d2c-abca-fd27bae6f05b","price_dollars":"0.5400","delta_fp":"-1000.00","side":"no","ts":"2026-09-13T23:45:44.855243Z","ts_ms":1789343144855}}
{"type":"orderbook_delta","sid":1,"seq":227,"msg":{"market_ticker":"KXBTCD-26SEP1417-T76999.99","market_id":"9fc30aa6-9f6f-4d2c-abca-fd27bae6f05b","price_dollars":"0.5300","delta_fp":"1000.00","side":"no","ts":"2026-09-13T23:45:44.855243Z","ts_ms":1789343144855}}
{"type":"orderbook_delta","sid":1,"seq":228,"msg":{"market_ticker":"KXBTCD-26SEP1417-T76999.99","market_id":"9fc30aa6-9f6f-4d2c-abca-fd27bae6f05b","price_dollars":"0.4300","delta_fp":"-3000.00","side":"yes","ts":"2026-09-13T23:45:44.856935Z","ts_ms":1789343144856}}
{"type":"orderbook_delta","sid":1,"seq":229,"msg":{"market_ticker":"KXBTCD-26SEP1417-T76999.99","market_id":"9fc30aa6-9f6f-4d2c-abca-fd27bae6f05b","price_dollars":"0.4400","delta_fp":"3000.00","side":"yes","ts":"2026-09-13T23:45:44.856935Z","ts_ms":1789343144856}}
{"type":"orderbook_delta","sid":1,"seq":230,"msg":{"market_ticker":"KXBTCD-26SEP1417-T76999.99","market_id":"9fc30aa6-9f6f-4d2c-abca-fd27bae6f05b","price_dollars":"0.4200","delta_fp":"-1000.00","side":"yes","ts":"2026-09-13T23:45:44.866798Z","ts_ms":1789343144866}}
{"type":"orderbook_delta","sid":1,"seq":231,"msg":{"market_ticker":"KXBTCD-26SEP1417-T76999.99","market_id":"9fc30aa6-9f6f-4d2c-abca-fd27bae6f05b","price_dollars":"0.4300","delta_fp":"1000.00","side":"yes","ts":"2026-09-13T23:45:44.866798Z","ts_ms":1789343144866}}
{"type":"orderbook_delta","sid":1,"seq":232,"msg":{"market_ticker":"KXBTCD-26SEP1417-T76999.99","market_id":"9fc30aa6-9f6f-4d2c-abca-fd27bae6f05b","price_dollars":"0.5400","delta_fp":"-1000.00","side":"no","ts":"2026-09-13T23:45:44.874463Z","ts_ms":1789343144874}}
{"type":"orderbook_delta","sid":1,"seq":233,"msg":{"market_ticker":"KXBTCD-26SEP1417-T76999.99","market_id":"9fc30aa6-9f6f-4d2c-abca-fd27bae6f05b","price_dollars":"0.5300","delta_fp":"1000.00","side":"no","ts":"2026-09-13T23:45:44.874463Z","ts_ms":1789343144874}}
{"type":"orderbook_delta","sid":1,"seq":234,"msg":{"market_ticker":"KXBTCD-26SEP1417-T76999.99","market_id":"9fc30aa6-9f6f-4d2c-abca-fd27bae6f05b","price_dollars":"0.4200","delta_fp":"-1000.00","side":"yes","ts":"2026-09-13T23:45:44.883329Z","ts_ms":1789343144883}}
{"type":"orderbook_delta","sid":1,"seq":235,"msg":{"market_ticker":"KXBTCD-26SEP1417-T76999.99","market_id":"9fc30aa6-9f6f-4d2c-abca-fd27bae6f05b","price_dollars":"0.4300","delta_fp":"1000.00","side":"yes","ts":"2026-09-13T23:45:44.883329Z","ts_ms":1789343144883}}
{"type":"orderbook_delta","sid":1,"seq":236,"msg":{"market_ticker":"KXBTCD-26SEP1417-T76999.99","market_id":"9fc30aa6-9f6f-4d2c-abca-fd27bae6f05b","price_dollars":"0.5500","delta_fp":"-100.00","side":"no","ts":"2026-09-13T23:45:44.883912Z","ts_ms":1789343144883}}
{"type":"orderbook_delta","sid":1,"seq":237,"msg":{"market_ticker":"KXBTCD-26SEP1417-T76999.99","market_id":"9fc30aa6-9f6f-4d2c-abca-fd27bae6f05b","price_dollars":"0.5000","delta_fp":"100.00","side":"no","ts":"2026-09-13T23:45:44.883912Z","ts_ms":1789343144883}}
{"type":"orderbook_delta","sid":1,"seq":238,"msg":{"market_ticker":"KXBTCD-26SEP1417-T76999.99","market_id":"9fc30aa6-9f6f-4d2c-abca-fd27bae6f05b","price_dollars":"0.4400","delta_fp":"-3000.00","side":"yes","ts":"2026-09-13T23:45:44.895653Z","ts_ms":1789343144895}}
{"type":"orderbook_delta","sid":1,"seq":239,"msg":{"market_ticker":"KXBTCD-26SEP1417-T76999.99","market_id":"9fc30aa6-9f6f-4d2c-abca-fd27bae6f05b","price_dollars":"0.4300","delta_fp":"3000.00","side":"yes","ts":"2026-09-13T23:45:44.895653Z","ts_ms":1789343144895}}
{"type":"orderbook_delta","sid":1,"seq":240,"msg":{"market_ticker":"KXBTCD-26SEP1417-T76999.99","market_id":"9fc30aa6-9f6f-4d2c-abca-fd27bae6f05b","price_dollars":"0.5400","delta_fp":"-30.00","side":"no","ts":"2026-09-13T23:45:44.90266Z","ts_ms":1789343144902}}
{"type":"orderbook_delta","sid":1,"seq":241,"msg":{"market_ticker":"KXBTCD-26SEP1417-T76999.99","market_id":"9fc30aa6-9f6f-4d2c-abca-fd27bae6f05b","price_dollars":"0.5300","delta_fp":"30.00","side":"no","ts":"2026-09-13T23:45:44.921201Z","ts_ms":1789343144921}}
{"type":"orderbook_delta","sid":1,"seq":242,"msg":{"market_ticker":"KXBTCD-26SEP1417-T76999.99","market_id":"9fc30aa6-9f6f-4d2c-abca-fd27bae6f05b","price_dollars":"0.5000","delta_fp":"-100.00","side":"no","ts":"2026-09-13T23:45:44.986592Z","ts_ms":1789343144986}}
{"type":"orderbook_delta","sid":1,"seq":243,"msg":{"market_ticker":"KXBTCD-26SEP1417-T76999.99","market_id":"9fc30aa6-9f6f-4d2c-abca-fd27bae6f05b","price_dollars":"0.5400","delta_fp":"100.00","side":"no","ts":"2026-09-13T23:45:44.986592Z","ts_ms":1789343144986}}
{"type":"orderbook_delta","sid":1,"seq":244,"msg":{"market_ticker":"KXBTCD-26SEP1417-T76999.99","market_id":"9fc30aa6-9f6f-4d2c-abca-fd27bae6f05b","price_dollars":"0.5300","delta_fp":"-30.00","side":"no","ts":"2026-09-13T23:45:45.007125Z","ts_ms":1789343145007}}
{"type":"orderbook_delta","sid":1,"seq":245,"msg":{"market_ticker":"KXBTCD-26SEP1417-T76999.99","market_id":"9fc30aa6-9f6f-4d2c-abca-fd27bae6f05b","price_dollars":"0.4300","delta_fp":"-2.00","side":"yes","ts":"2026-09-13T23:45:45.007802Z","ts_ms":1789343145007}}
{"type":"orderbook_delta","sid":1,"seq":246,"msg":{"market_ticker":"KXBTCD-26SEP1417-T76999.99","market_id":"9fc30aa6-9f6f-4d2c-abca-fd27bae6f05b","price_dollars":"0.5300","delta_fp":"-1000.00","side":"no","ts":"2026-09-13T23:45:45.086109Z","ts_ms":1789343145086}}
{"type":"orderbook_delta","sid":1,"seq":247,"msg":{"market_ticker":"KXBTCD-26SEP1417-T76999.99","market_id":"9fc30aa6-9f6f-4d2c-abca-fd27bae6f05b","price_dollars":"0.5400","delta_fp":"1000.00","side":"no","ts":"2026-09-13T23:45:45.086109Z","ts_ms":1789343145086}}
{"type":"orderbook_delta","sid":1,"seq":248,"msg":{"market_ticker":"KXBTCD-26SEP1417-T76999.99","market_id":"9fc30aa6-9f6f-4d2c-abca-fd27bae6f05b","price_dollars":"0.4300","delta_fp":"-1000.00","side":"yes","ts":"2026-09-13T23:45:45.092878Z","ts_ms":1789343145092}}
{"type":"orderbook_delta","sid":1,"seq":249,"msg":{"market_ticker":"KXBTCD-26SEP1417-T76999.99","market_id":"9fc30aa6-9f6f-4d2c-abca-fd27bae6f05b","price_dollars":"0.4200","delta_fp":"1000.00","side":"yes","ts":"2026-09-13T23:45:45.092878Z","ts_ms":1789343145092}}
{"type":"orderbook_delta","sid":1,"seq":250,"msg":{"market_ticker":"KXBTCD-26SEP1417-T76999.99","market_id":"9fc30aa6-9f6f-4d2c-abca-fd27bae6f05b","price_dollars":"0.4300","delta_fp":"2.00","side":"yes","ts":"2026-09-13T23:45:45.094456Z","ts_ms":1789343145094}}
{"type":"orderbook_delta","sid":1,"seq":251,"msg":{"market_ticker":"KXBTCD-26SEP1417-T76999.99","market_id":"9fc30aa6-9f6f-4d2c-abca-fd27bae6f05b","price_dollars":"0.5400","delta_fp":"30.00","side":"no","ts":"2026-09-13T23:45:45.104352Z","ts_ms":1789343145104}}
{"type":"orderbook_delta","sid":1,"seq":252,"msg":{"market_ticker":"KXBTCD-26SEP1417-T76999.99","market_id":"9fc30aa6-9f6f-4d2c-abca-fd27bae6f05b","price_dollars":"0.3100","delta_fp":"-182.00","side":"no","ts":"2026-09-13T23:45:45.150016Z","ts_ms":1789343145150}}
{"type":"orderbook_delta","sid":1,"seq":253,"msg":{"market_ticker":"KXBTCD-26SEP1417-T76999.99","market_id":"9fc30aa6-9f6f-4d2c-abca-fd27bae6f05b","price_dollars":"0.3000","delta_fp":"-193.00","side":"no","ts":"2026-09-13T23:45:45.15157Z","ts_ms":1789343145151}}
{"type":"orderbook_delta","sid":1,"seq":254,"msg":{"market_ticker":"KXBTCD-26SEP1417-T76999.99","market_id":"9fc30aa6-9f6f-4d2c-abca-fd27bae6f05b","price_dollars":"0.2700","delta_fp":"217.00","side":"no","ts":"2026-09-13T23:45:45.152189Z","ts_ms":1789343145152}}
{"type":"orderbook_delta","sid":1,"seq":255,"msg":{"market_ticker":"KXBTCD-26SEP1417-T76999.99","market_id":"9fc30aa6-9f6f-4d2c-abca-fd27bae6f05b","price_dollars":"0.2800","delta_fp":"144.00","side":"no","ts":"2026-09-13T23:45:45.152808Z","ts_ms":1789343145152}}
{"type":"orderbook_delta","sid":1,"seq":256,"msg":{"market_ticker":"KXBTCD-26SEP1417-T76999.99","market_id":"9fc30aa6-9f6f-4d2c-abca-fd27bae6f05b","price_dollars":"0.5300","delta_fp":"-1000.00","side":"no","ts":"2026-09-13T23:45:45.202691Z","ts_ms":1789343145202}}
{"type":"orderbook_delta","sid":1,"seq":257,"msg":{"market_ticker":"KXBTCD-26SEP1417-T76999.99","market_id":"9fc30aa6-9f6f-4d2c-abca-fd27bae6f05b","price_dollars":"0.5400","delta_fp":"1000.00","side":"no","ts":"2026-09-13T23:45:45.202691Z","ts_ms":1789343145202}}
{"type":"orderbook_delta","sid":1,"seq":258,"msg":{"market_ticker":"KXBTCD-26SEP1417-T76999.99","market_id":"9fc30aa6-9f6f-4d2c-abca-fd27bae6f05b","price_dollars":"0.4300","delta_fp":"-1000.00","side":"yes","ts":"2026-09-13T23:45:45.210771Z","ts_ms":1789343145210}}
{"type":"orderbook_delta","sid":1,"seq":259,"msg":{"market_ticker":"KXBTCD-26SEP1417-T76999.99","market_id":"9fc30aa6-9f6f-4d2c-abca-fd27bae6f05b","price_dollars":"0.4200","delta_fp":"1000.00","side":"yes","ts":"2026-09-13T23:45:45.210771Z","ts_ms":1789343145210}}
{"type":"orderbook_delta","sid":1,"seq":260,"msg":{"market_ticker":"KXBTCD-26SEP1417-T76999.99","market_id":"9fc30aa6-9f6f-4d2c-abca-fd27bae6f05b","price_dollars":"0.2600","delta_fp":"-3758.00","side":"no","ts":"2026-09-13T23:45:45.368511Z","ts_ms":1789343145368}}
{"type":"orderbook_delta","sid":1,"seq":261,"msg":{"market_ticker":"KXBTCD-26SEP1417-T76999.99","market_id":"9fc30aa6-9f6f-4d2c-abca-fd27bae6f05b","price_dollars":"0.0200","delta_fp":"26057.00","side":"no","ts":"2026-09-13T23:45:45.368511Z","ts_ms":1789343145368}}
{"type":"orderbook_delta","sid":1,"seq":262,"msg":{"market_ticker":"KXBTCD-26SEP1417-T76999.99","market_id":"9fc30aa6-9f6f-4d2c-abca-fd27bae6f05b","price_dollars":"0.0800","delta_fp":"5700.00","side":"no","ts":"2026-09-13T23:45:45.375779Z","ts_ms":1789343145375}}
{"type":"orderbook_delta","sid":1,"seq":263,"msg":{"market_ticker":"KXBTCD-26SEP1417-T76999.99","market_id":"9fc30aa6-9f6f-4d2c-abca-fd27bae6f05b","price_dollars":"0.1600","delta_fp":"8549.00","side":"no","ts":"2026-09-13T23:45:45.376397Z","ts_ms":1789343145376}}
{"type":"orderbook_delta","sid":1,"seq":264,"msg":{"market_ticker":"KXBTCD-26SEP1417-T76999.99","market_id":"9fc30aa6-9f6f-4d2c-abca-fd27bae6f05b","price_dollars":"0.2900","delta_fp":"3369.00","side":"no","ts":"2026-09-13T23:45:45.377011Z","ts_ms":1789343145377}}
{"type":"orderbook_delta","sid":1,"seq":265,"msg":{"market_ticker":"KXBTCD-26SEP1417-T76999.99","market_id":"9fc30aa6-9f6f-4d2c-abca-fd27bae6f05b","price_dollars":"0.4100","delta_fp":"5000.00","side":"yes","ts":"2026-09-13T23:45:45.691025Z","ts_ms":1789343145691}}
{"type":"orderbook_delta","sid":1,"seq":266,"msg":{"market_ticker":"KXBTCD-26SEP1417-T76999.99","market_id":"9fc30aa6-9f6f-4d2c-abca-fd27bae6f05b","price_dollars":"0.5300","delta_fp":"5000.00","side":"no","ts":"2026-09-13T23:45:46.015863Z","ts_ms":1789343146015}}
{"type":"orderbook_delta","sid":1,"seq":267,"msg":{"market_ticker":"KXBTCD-26SEP1417-T76999.99","market_id":"9fc30aa6-9f6f-4d2c-abca-fd27bae6f05b","price_dollars":"0.4300","delta_fp":"-2.00","side":"yes","ts":"2026-09-13T23:45:46.395207Z","ts_ms":1789343146395}}
{"type":"orderbook_delta","sid":1,"seq":268,"msg":{"market_ticker":"KXBTCD-26SEP1417-T76999.99","market_id":"9fc30aa6-9f6f-4d2c-abca-fd27bae6f05b","price_dollars":"0.4300","delta_fp":"2.00","side":"yes","ts":"2026-09-13T23:45:46.473255Z","ts_ms":1789343146473}}
{"type":"orderbook_delta","sid":1,"seq":269,"msg":{"market_ticker":"KXBTCD-26SEP1417-T76999.99","market_id":"9fc30aa6-9f6f-4d2c-abca-fd27bae6f05b","price_dollars":"0.4100","delta_fp":"568.00","side":"yes","ts":"2026-09-13T23:45:47.954312Z","ts_ms":1789343147954}}
{"type":"orderbook_delta","sid":1,"seq":270,"msg":{"market_ticker":"KXBTCD-26SEP1417-T76999.99","market_id":"9fc30aa6-9f6f-4d2c-abca-fd27bae6f05b","price_dollars":"0.4400","delta_fp":"-567.00","side":"yes","ts":"2026-09-13T23:45:47.955424Z","ts_ms":1789343147955}}
{"type":"orderbook_delta","sid":1,"seq":271,"msg":{"market_ticker":"KXBTCD-26SEP1417-T76999.99","market_id":"9fc30aa6-9f6f-4d2c-abca-fd27bae6f05b","price_dollars":"0.3900","delta_fp":"-4.00","side":"yes","ts":"2026-09-13T23:45:50.435799Z","ts_ms":1789343150435}}
{"type":"orderbook_delta","sid":1,"seq":272,"msg":{"market_ticker":"KXBTCD-26SEP1417-T76999.99","market_id":"9fc30aa6-9f6f-4d2c-abca-fd27bae6f05b","price_dollars":"0.5300","delta_fp":"-4.00","side":"no","ts":"2026-09-13T23:45:50.438891Z","ts_ms":1789343150438}}
{"type":"orderbook_delta","sid":1,"seq":273,"msg":{"market_ticker":"KXBTCD-26SEP1417-T76999.99","market_id":"9fc30aa6-9f6f-4d2c-abca-fd27bae6f05b","price_dollars":"0.4100","delta_fp":"4.00","side":"yes","ts":"2026-09-13T23:45:50.472558Z","ts_ms":1789343150472}}
{"type":"orderbook_delta","sid":1,"seq":274,"msg":{"market_ticker":"KXBTCD-26SEP1417-T76999.99","market_id":"9fc30aa6-9f6f-4d2c-abca-fd27bae6f05b","price_dollars":"0.5200","delta_fp":"4.00","side":"no","ts":"2026-09-13T23:45:50.475448Z","ts_ms":1789343150475}}
{"type":"orderbook_delta","sid":1,"seq":275,"msg":{"market_ticker":"KXBTCD-26SEP1417-T76999.99","market_id":"9fc30aa6-9f6f-4d2c-abca-fd27bae6f05b","price_dollars":"0.4300","delta_fp":"-100.00","side":"yes","ts":"2026-09-13T23:45:51.735038Z","ts_ms":1789343151735}}
{"type":"orderbook_delta","sid":1,"seq":276,"msg":{"market_ticker":"KXBTCD-26SEP1417-T76999.99","market_id":"9fc30aa6-9f6f-4d2c-abca-fd27bae6f05b","price_dollars":"0.5400","delta_fp":"-100.00","side":"no","ts":"2026-09-13T23:45:51.735837Z","ts_ms":1789343151735}}
{"type":"orderbook_delta","sid":1,"seq":277,"msg":{"market_ticker":"KXBTCD-26SEP1417-T76999.99","market_id":"9fc30aa6-9f6f-4d2c-abca-fd27bae6f05b","price_dollars":"0.4300","delta_fp":"100.00","side":"yes","ts":"2026-09-13T23:45:51.753703Z","ts_ms":1789343151753}}
{"type":"orderbook_delta","sid":1,"seq":278,"msg":{"market_ticker":"KXBTCD-26SEP1417-T76999.99","market_id":"9fc30aa6-9f6f-4d2c-abca-fd27bae6f05b","price_dollars":"0.5500","delta_fp":"100.00","side":"no","ts":"2026-09-13T23:45:51.754753Z","ts_ms":1789343151754}}
{"type":"orderbook_delta","sid":1,"seq":279,"msg":{"market_ticker":"KXBTCD-26SEP1417-T76999.99","market_id":"9fc30aa6-9f6f-4d2c-abca-fd27bae6f05b","price_dollars":"0.5500","delta_fp":"5.00","side":"no","ts":"2026-09-13T23:45:51.774362Z","ts_ms":1789343151774}}
{"type":"orderbook_delta","sid":1,"seq":280,"msg":{"market_ticker":"KXBTCD-26SEP1417-T76999.99","market_id":"9fc30aa6-9f6f-4d2c-abca-fd27bae6f05b","price_dollars":"0.5400","delta_fp":"-30.00","side":"no","ts":"2026-09-13T23:45:51.777565Z","ts_ms":1789343151777}}
{"type":"orderbook_delta","sid":1,"seq":281,"msg":{"market_ticker":"KXBTCD-26SEP1417-T76999.99","market_id":"9fc30aa6-9f6f-4d2c-abca-fd27bae6f05b","price_dollars":"0.4100","delta_fp":"-568.00","side":"yes","ts":"2026-09-13T23:45:51.881789Z","ts_ms":1789343151881}}
{"type":"orderbook_delta","sid":1,"seq":282,"msg":{"market_ticker":"KXBTCD-26SEP1417-T76999.99","market_id":"9fc30aa6-9f6f-4d2c-abca-fd27bae6f05b","price_dollars":"0.4300","delta_fp":"567.00","side":"yes","ts":"2026-09-13T23:45:51.882455Z","ts_ms":1789343151882}}
{"type":"orderbook_delta","sid":1,"seq":283,"msg":{"market_ticker":"KXBTCD-26SEP1417-T76999.99","market_id":"9fc30aa6-9f6f-4d2c-abca-fd27bae6f05b","price_dollars":"0.4300","delta_fp":"-567.00","side":"yes","ts":"2026-09-13T23:45:53.00383Z","ts_ms":1789343153003}}
{"type":"orderbook_delta","sid":1,"seq":284,"msg":{"market_ticker":"KXBTCD-26SEP1417-T76999.99","market_id":"9fc30aa6-9f6f-4d2c-abca-fd27bae6f05b","price_dollars":"0.4100","delta_fp":"568.00","side":"yes","ts":"2026-09-13T23:45:53.007049Z","ts_ms":1789343153007}}
{"type":"orderbook_delta","sid":1,"seq":285,"msg":{"market_ticker":"KXBTCD-26SEP1417-T76999.99","market_id":"9fc30aa6-9f6f-4d2c-abca-fd27bae6f05b","price_dollars":"0.4100","delta_fp":"-4.00","side":"yes","ts":"2026-09-13T23:45:57.033434Z","ts_ms":1789343157033}}
{"type":"orderbook_delta","sid":1,"seq":286,"msg":{"market_ticker":"KXBTCD-26SEP1417-T76999.99","market_id":"9fc30aa6-9f6f-4d2c-abca-fd27bae6f05b","price_dollars":"0.4000","delta_fp":"4.00","side":"yes","ts":"2026-09-13T23:45:57.033434Z","ts_ms":1789343157033}}
{"type":"orderbook_delta","sid":1,"seq":287,"msg":{"market_ticker":"KXBTCD-26SEP1417-T76999.99","market_id":"9fc30aa6-9f6f-4d2c-abca-fd27bae6f05b","price_dollars":"0.4000","delta_fp":"-4.00","side":"yes","ts":"2026-09-13T23:45:57.989634Z","ts_ms":1789343157989}}
{"type":"orderbook_delta","sid":1,"seq":288,"msg":{"market_ticker":"KXBTCD-26SEP1417-T76999.99","market_id":"9fc30aa6-9f6f-4d2c-abca-fd27bae6f05b","price_dollars":"0.3900","delta_fp":"4.00","side":"yes","ts":"2026-09-13T23:45:58.029762Z","ts_ms":1789343158029}}
{"type":"orderbook_delta","sid":1,"seq":289,"msg":{"market_ticker":"KXBTCD-26SEP1417-T76999.99","market_id":"9fc30aa6-9f6f-4d2c-abca-fd27bae6f05b","price_dollars":"0.5300","delta_fp":"-5000.00","side":"no","ts":"2026-09-13T23:45:58.894197Z","ts_ms":1789343158894}}
{"type":"orderbook_delta","sid":1,"seq":290,"msg":{"market_ticker":"KXBTCD-26SEP1417-T76999.99","market_id":"9fc30aa6-9f6f-4d2c-abca-fd27bae6f05b","price_dollars":"0.5400","delta_fp":"5000.00","side":"no","ts":"2026-09-13T23:46:00.926703Z","ts_ms":1789343160926}}
{"type":"orderbook_delta","sid":1,"seq":291,"msg":{"market_ticker":"KXBTCD-26SEP1417-T76999.99","market_id":"9fc30aa6-9f6f-4d2c-abca-fd27bae6f05b","price_dollars":"0.4300","delta_fp":"-100.00","side":"yes","ts":"2026-09-13T23:46:02.547209Z","ts_ms":1789343162547}}
{"type":"orderbook_delta","sid":1,"seq":292,"msg":{"market_ticker":"KXBTCD-26SEP1417-T76999.99","market_id":"9fc30aa6-9f6f-4d2c-abca-fd27bae6f05b","price_dollars":"0.3700","delta_fp":"100.00","side":"yes","ts":"2026-09-13T23:46:02.547209Z","ts_ms":1789343162547}}
{"type":"orderbook_delta","sid":1,"seq":293,"msg":{"market_ticker":"KXBTCD-26SEP1417-T76999.99","market_id":"9fc30aa6-9f6f-4d2c-abca-fd27bae6f05b","price_dollars":"0.3700","delta_fp":"-100.00","side":"yes","ts":"2026-09-13T23:46:02.567294Z","ts_ms":1789343162567}}
{"type":"orderbook_delta","sid":1,"seq":294,"msg":{"market_ticker":"KXBTCD-26SEP1417-T76999.99","market_id":"9fc30aa6-9f6f-4d2c-abca-fd27bae6f05b","price_dollars":"0.5500","delta_fp":"-100.00","side":"no","ts":"2026-09-13T23:46:02.567966Z","ts_ms":1789343162567}}
{"type":"orderbook_delta","sid":1,"seq":295,"msg":{"market_ticker":"KXBTCD-26SEP1417-T76999.99","market_id":"9fc30aa6-9f6f-4d2c-abca-fd27bae6f05b","price_dollars":"0.5500","delta_fp":"-5.00","side":"no","ts":"2026-09-13T23:46:02.593213Z","ts_ms":1789343162593}}
{"type":"orderbook_delta","sid":1,"seq":296,"msg":{"market_ticker":"KXBTCD-26SEP1417-T76999.99","market_id":"9fc30aa6-9f6f-4d2c-abca-fd27bae6f05b","price_dollars":"0.5400","delta_fp":"30.00","side":"no","ts":"2026-09-13T23:46:02.609143Z","ts_ms":1789343162609}}
{"type":"orderbook_delta","sid":1,"seq":297,"msg":{"market_ticker":"KXBTCD-26SEP1417-T76999.99","market_id":"9fc30aa6-9f6f-4d2c-abca-fd27bae6f05b","price_dollars":"0.4300","delta_fp":"100.00","side":"yes","ts":"2026-09-13T23:46:02.686818Z","ts_ms":1789343162686}}
{"type":"orderbook_delta","sid":1,"seq":298,"msg":{"market_ticker":"KXBTCD-26SEP1417-T76999.99","market_id":"9fc30aa6-9f6f-4d2c-abca-fd27bae6f05b","price_dollars":"0.5500","delta_fp":"100.00","side":"no","ts":"2026-09-13T23:46:02.687675Z","ts_ms":1789343162687}}
{"type":"orderbook_delta","sid":1,"seq":299,"msg":{"market_ticker":"KXBTCD-26SEP1417-T76999.99","market_id":"9fc30aa6-9f6f-4d2c-abca-fd27bae6f05b","price_dollars":"0.5500","delta_fp":"5.00","side":"no","ts":"2026-09-13T23:46:02.705531Z","ts_ms":1789343162705}}
{"type":"orderbook_delta","sid":1,"seq":300,"msg":{"market_ticker":"KXBTCD-26SEP1417-T76999.99","market_id":"9fc30aa6-9f6f-4d2c-abca-fd27bae6f05b","price_dollars":"0.5400","delta_fp":"-30.00","side":"no","ts":"2026-09-13T23:46:02.706475Z","ts_ms":1789343162706}}
{"type":"orderbook_delta","sid":1,"seq":301,"msg":{"market_ticker":"KXBTCD-26SEP1417-T76999.99","market_id":"9fc30aa6-9f6f-4d2c-abca-fd27bae6f05b","price_dollars":"0.4300","delta_fp":"-100.00","side":"yes","ts":"2026-09-13T23:46:02.841448Z","ts_ms":1789343162841}}
{"type":"orderbook_delta","sid":1,"seq":302,"msg":{"market_ticker":"KXBTCD-26SEP1417-T76999.99","market_id":"9fc30aa6-9f6f-4d2c-abca-fd27bae6f05b","price_dollars":"0.4100","delta_fp":"-50.00","side":"yes","ts":"2026-09-13T23:46:03.531444Z","ts_ms":1789343163531}}
{"type":"orderbook_delta","sid":1,"seq":303,"msg":{"market_ticker":"KXBTCD-26SEP1417-T76999.99","market_id":"9fc30aa6-9f6f-4d2c-abca-fd27bae6f05b","price_dollars":"0.3200","delta_fp":"50.00","side":"yes","ts":"2026-09-13T23:46:03.533121Z","ts_ms":1789343163533}}
{"type":"orderbook_delta","sid":1,"seq":304,"msg":{"market_ticker":"KXBTCD-26SEP1417-T76999.99","market_id":"9fc30aa6-9f6f-4d2c-abca-fd27bae6f05b","price_dollars":"0.4400","delta_fp":"-50.00","side":"no","ts":"2026-09-13T23:46:03.534627Z","ts_ms":1789343163534}}
{"type":"orderbook_delta","sid":1,"seq":305,"msg":{"market_ticker":"KXBTCD-26SEP1417-T76999.99","market_id":"9fc30aa6-9f6f-4d2c-abca-fd27bae6f05b","price_dollars":"0.5300","delta_fp":"50.00","side":"no","ts":"2026-09-13T23:46:03.536055Z","ts_ms":1789343163536}}
{"type":"orderbook_delta","sid":1,"seq":306,"msg":{"market_ticker":"KXBTCD-26SEP1417-T76999.99","market_id":"9fc30aa6-9f6f-4d2c-abca-fd27bae6f05b","price_dollars":"0.3200","delta_fp":"-50.00","side":"yes","ts":"2026-09-13T23:46:03.58147Z","ts_ms":1789343163581}}
{"type":"orderbook_delta","sid":1,"seq":307,"msg":{"market_ticker":"KXBTCD-26SEP1417-T76999.99","market_id":"9fc30aa6-9f6f-4d2c-abca-fd27bae6f05b","price_dollars":"0.4100","delta_fp":"50.00","side":"yes","ts":"2026-09-13T23:46:03.5829Z","ts_ms":1789343163582}}
{"type":"orderbook_delta","sid":1,"seq":308,"msg":{"market_ticker":"KXBTCD-26SEP1417-T76999.99","market_id":"9fc30aa6-9f6f-4d2c-abca-fd27bae6f05b","price_dollars":"0.5300","delta_fp":"-50.00","side":"no","ts":"2026-09-13T23:46:03.584701Z","ts_ms":1789343163584}}
{"type":"orderbook_delta","sid":1,"seq":309,"msg":{"market_ticker":"KXBTCD-26SEP1417-T76999.99","market_id":"9fc30aa6-9f6f-4d2c-abca-fd27bae6f05b","price_dollars":"0.4400","delta_fp":"50.00","side":"no","ts":"2026-09-13T23:46:03.585921Z","ts_ms":1789343163585}}
{"type":"orderbook_delta","sid":1,"seq":310,"msg":{"market_ticker":"KXBTCD-26SEP1417-T76999.99","market_id":"9fc30aa6-9f6f-4d2c-abca-fd27bae6f05b","price_dollars":"0.4300","delta_fp":"100.00","side":"yes","ts":"2026-09-13T23:46:03.841906Z","ts_ms":1789343163841}}
{"type":"orderbook_delta","sid":1,"seq":311,"msg":{"market_ticker":"KXBTCD-26SEP1417-T76999.99","market_id":"9fc30aa6-9f6f-4d2c-abca-fd27bae6f05b","price_dollars":"0.5500","delta_fp":"-100.00","side":"no","ts":"2026-09-13T23:46:06.197577Z","ts_ms":1789343166197}}
{"type":"orderbook_delta","sid":1,"seq":312,"msg":{"market_ticker":"KXBTCD-26SEP1417-T76999.99","market_id":"9fc30aa6-9f6f-4d2c-abca-fd27bae6f05b","price_dollars":"0.5000","delta_fp":"100.00","side":"no","ts":"2026-09-13T23:46:06.197577Z","ts_ms":1789343166197}}
{"type":"orderbook_delta","sid":1,"seq":313,"msg":{"market_ticker":"KXBTCD-26SEP1417-T76999.99","market_id":"9fc30aa6-9f6f-4d2c-abca-fd27bae6f05b","price_dollars":"0.5500","delta_fp":"-5.00","side":"no","ts":"2026-09-13T23:46:06.209365Z","ts_ms":1789343166209}}
{"type":"orderbook_delta","sid":1,"seq":314,"msg":{"market_ticker":"KXBTCD-26SEP1417-T76999.99","market_id":"9fc30aa6-9f6f-4d2c-abca-fd27bae6f05b","price_dollars":"0.4200","delta_fp":"-1000.00","side":"yes","ts":"2026-09-13T23:46:06.223219Z","ts_ms":1789343166223}}
{"type":"orderbook_delta","sid":1,"seq":315,"msg":{"market_ticker":"KXBTCD-26SEP1417-T76999.99","market_id":"9fc30aa6-9f6f-4d2c-abca-fd27bae6f05b","price_dollars":"0.4300","delta_fp":"1000.00","side":"yes","ts":"2026-09-13T23:46:06.223219Z","ts_ms":1789343166223}}
{"type":"orderbook_delta","sid":1,"seq":316,"msg":{"market_ticker":"KXBTCD-26SEP1417-T76999.99","market_id":"9fc30aa6-9f6f-4d2c-abca-fd27bae6f05b","price_dollars":"0.5400","delta_fp":"-1000.00","side":"no","ts":"2026-09-13T23:46:06.240449Z","ts_ms":1789343166240}}
{"type":"orderbook_delta","sid":1,"seq":317,"msg":{"market_ticker":"KXBTCD-26SEP1417-T76999.99","market_id":"9fc30aa6-9f6f-4d2c-abca-fd27bae6f05b","price_dollars":"0.5300","delta_fp":"1000.00","side":"no","ts":"2026-09-13T23:46:06.240449Z","ts_ms":1789343166240}}
{"type":"orderbook_delta","sid":1,"seq":318,"msg":{"market_ticker":"KXBTCD-26SEP1417-T76999.99","market_id":"9fc30aa6-9f6f-4d2c-abca-fd27bae6f05b","price_dollars":"0.5400","delta_fp":"30.00","side":"no","ts":"2026-09-13T23:46:06.24669Z","ts_ms":1789343166246}}
{"type":"orderbook_delta","sid":1,"seq":319,"msg":{"market_ticker":"KXBTCD-26SEP1417-T76999.99","market_id":"9fc30aa6-9f6f-4d2c-abca-fd27bae6f05b","price_dollars":"0.4200","delta_fp":"-1000.00","side":"yes","ts":"2026-09-13T23:46:06.301397Z","ts_ms":1789343166301}}
{"type":"orderbook_delta","sid":1,"seq":320,"msg":{"market_ticker":"KXBTCD-26SEP1417-T76999.99","market_id":"9fc30aa6-9f6f-4d2c-abca-fd27bae6f05b","price_dollars":"0.4300","delta_fp":"1000.00","side":"yes","ts":"2026-09-13T23:46:06.301397Z","ts_ms":1789343166301}}
{"type":"orderbook_delta","sid":1,"seq":321,"msg":{"market_ticker":"KXBTCD-26SEP1417-T76999.99","market_id":"9fc30aa6-9f6f-4d2c-abca-fd27bae6f05b","price_dollars":"0.5000","delta_fp":"-100.00","side":"no","ts":"2026-09-13T23:46:06.301543Z","ts_ms":1789343166301}}
{"type":"orderbook_delta","sid":1,"seq":322,"msg":{"market_ticker":"KXBTCD-26SEP1417-T76999.99","market_id":"9fc30aa6-9f6f-4d2c-abca-fd27bae6f05b","price_dollars":"0.5400","delta_fp":"100.00","side":"no","ts":"2026-09-13T23:46:06.301543Z","ts_ms":1789343166301}}
{"type":"orderbook_delta","sid":1,"seq":323,"msg":{"market_ticker":"KXBTCD-26SEP1417-T76999.99","market_id":"9fc30aa6-9f6f-4d2c-abca-fd27bae6f05b","price_dollars":"0.5300","delta_fp":"-1000.00","side":"no","ts":"2026-09-13T23:46:06.32052Z","ts_ms":1789343166320}}
{"type":"orderbook_delta","sid":1,"seq":324,"msg":{"market_ticker":"KXBTCD-26SEP1417-T76999.99","market_id":"9fc30aa6-9f6f-4d2c-abca-fd27bae6f05b","price_dollars":"0.5200","delta_fp":"1000.00","side":"no","ts":"2026-09-13T23:46:06.32052Z","ts_ms":1789343166320}}
{"type":"orderbook_delta","sid":1,"seq":325,"msg":{"market_ticker":"KXBTCD-26SEP1417-T76999.99","market_id":"9fc30aa6-9f6f-4d2c-abca-fd27bae6f05b","price_dollars":"0.5400","delta_fp":"-1000.00","side":"no","ts":"2026-09-13T23:46:06.369296Z","ts_ms":1789343166369}}
{"type":"orderbook_delta","sid":1,"seq":326,"msg":{"market_ticker":"KXBTCD-26SEP1417-T76999.99","market_id":"9fc30aa6-9f6f-4d2c-abca-fd27bae6f05b","price_dollars":"0.5300","delta_fp":"1000.00","side":"no","ts":"2026-09-13T23:46:06.369296Z","ts_ms":1789343166369}}
{"type":"orderbook_delta","sid":1,"seq":327,"msg":{"market_ticker":"KXBTCD-26SEP1417-T76999.99","market_id":"9fc30aa6-9f6f-4d2c-abca-fd27bae6f05b","price_dollars":"0.5400","delta_fp":"-30.00","side":"no","ts":"2026-09-13T23:46:06.42762Z","ts_ms":1789343166427}}
{"type":"orderbook_delta","sid":1,"seq":328,"msg":{"market_ticker":"KXBTCD-26SEP1417-T76999.99","market_id":"9fc30aa6-9f6f-4d2c-abca-fd27bae6f05b","price_dollars":"0.4300","delta_fp":"-2.00","side":"yes","ts":"2026-09-13T23:46:06.435586Z","ts_ms":1789343166435}}
{"type":"orderbook_delta","sid":1,"seq":329,"msg":{"market_ticker":"KXBTCD-26SEP1417-T76999.99","market_id":"9fc30aa6-9f6f-4d2c-abca-fd27bae6f05b","price_dollars":"0.5400","delta_fp":"-5000.00","side":"no","ts":"2026-09-13T23:46:06.476145Z","ts_ms":1789343166476}}
{"type":"orderbook_delta","sid":1,"seq":330,"msg":{"market_ticker":"KXBTCD-26SEP1417-T76999.99","market_id":"9fc30aa6-9f6f-4d2c-abca-fd27bae6f05b","price_dollars":"0.4300","delta_fp":"-100.00","side":"yes","ts":"2026-09-13T23:46:06.482055Z","ts_ms":1789343166482}}
{"type":"orderbook_delta","sid":1,"seq":331,"msg":{"market_ticker":"KXBTCD-26SEP1417-T76999.99","market_id":"9fc30aa6-9f6f-4d2c-abca-fd27bae6f05b","price_dollars":"0.4400","delta_fp":"100.00","side":"yes","ts":"2026-09-13T23:46:06.482055Z","ts_ms":1789343166482}}
{"type":"orderbook_delta","sid":1,"seq":332,"msg":{"market_ticker":"KXBTCD-26SEP1417-T76999.99","market_id":"9fc30aa6-9f6f-4d2c-abca-fd27bae6f05b","price_dollars":"0.4400","delta_fp":"-100.00","side":"yes","ts":"2026-09-13T23:46:06.490738Z","ts_ms":1789343166490}}
{"type":"orderbook_delta","sid":1,"seq":333,"msg":{"market_ticker":"KXBTCD-26SEP1417-T76999.99","market_id":"9fc30aa6-9f6f-4d2c-abca-fd27bae6f05b","price_dollars":"0.3800","delta_fp":"100.00","side":"yes","ts":"2026-09-13T23:46:06.490738Z","ts_ms":1789343166490}}
{"type":"orderbook_delta","sid":1,"seq":334,"msg":{"market_ticker":"KXBTCD-26SEP1417-T76999.99","market_id":"9fc30aa6-9f6f-4d2c-abca-fd27bae6f05b","price_dollars":"0.4300","delta_fp":"-5.00","side":"yes","ts":"2026-09-13T23:46:06.499042Z","ts_ms":1789343166499}}
{"type":"orderbook_delta","sid":1,"seq":335,"msg":{"market_ticker":"KXBTCD-26SEP1417-T76999.99","market_id":"9fc30aa6-9f6f-4d2c-abca-fd27bae6f05b","price_dollars":"0.4400","delta_fp":"5.00","side":"yes","ts":"2026-09-13T23:46:06.499356Z","ts_ms":1789343166499}}
{"type":"orderbook_delta","sid":1,"seq":336,"msg":{"market_ticker":"KXBTCD-26SEP1417-T76999.99","market_id":"9fc30aa6-9f6f-4d2c-abca-fd27bae6f05b","price_dollars":"0.4400","delta_fp":"-5.00","side":"yes","ts":"2026-09-13T23:46:06.51991Z","ts_ms":1789343166519}}
{"type":"orderbook_delta","sid":1,"seq":337,"msg":{"market_ticker":"KXBTCD-26SEP1417-T76999.99","market_id":"9fc30aa6-9f6f-4d2c-abca-fd27bae6f05b","price_dollars":"0.4300","delta_fp":"2.00","side":"yes","ts":"2026-09-13T23:46:06.520469Z","ts_ms":1789343166520}}
{"type":"orderbook_delta","sid":1,"seq":338,"msg":{"market_ticker":"KXBTCD-26SEP1417-T76999.99","market_id":"9fc30aa6-9f6f-4d2c-abca-fd27bae6f05b","price_dollars":"0.4300","delta_fp":"30.00","side":"yes","ts":"2026-09-13T23:46:06.535911Z","ts_ms":1789343166535}}
{"type":"orderbook_delta","sid":1,"seq":339,"msg":{"market_ticker":"KXBTCD-26SEP1417-T76999.99","market_id":"9fc30aa6-9f6f-4d2c-abca-fd27bae6f05b","price_dollars":"0.3300","delta_fp":"-50.00","side":"yes","ts":"2026-09-13T23:46:06.53649Z","ts_ms":1789343166536}}
{"type":"orderbook_delta","sid":1,"seq":340,"msg":{"market_ticker":"KXBTCD-26SEP1417-T76999.99","market_id":"9fc30aa6-9f6f-4d2c-abca-fd27bae6f05b","price_dollars":"0.4200","delta_fp":"50.00","side":"yes","ts":"2026-09-13T23:46:06.537716Z","ts_ms":1789343166537}}
{"type":"orderbook_delta","sid":1,"seq":341,"msg":{"market_ticker":"KXBTCD-26SEP1417-T76999.99","market_id":"9fc30aa6-9f6f-4d2c-abca-fd27bae6f05b","price_dollars":"0.5200","delta_fp":"-50.00","side":"no","ts":"2026-09-13T23:46:06.538929Z","ts_ms":1789343166538}}
{"type":"orderbook_delta","sid":1,"seq":342,"msg":{"market_ticker":"KXBTCD-26SEP1417-T76999.99","market_id":"9fc30aa6-9f6f-4d2c-abca-fd27bae6f05b","price_dollars":"0.4300","delta_fp":"50.00","side":"no","ts":"2026-09-13T23:46:06.540148Z","ts_ms":1789343166540}}
{"type":"orderbook_delta","sid":1,"seq":343,"msg":{"market_ticker":"KXBTCD-26SEP1417-T76999.99","market_id":"9fc30aa6-9f6f-4d2c-abca-fd27bae6f05b","price_dollars":"0.3800","delta_fp":"-100.00","side":"yes","ts":"2026-09-13T23:46:06.597888Z","ts_ms":1789343166597}}
{"type":"orderbook_delta","sid":1,"seq":344,"msg":{"market_ticker":"KXBTCD-26SEP1417-T76999.99","market_id":"9fc30aa6-9f6f-4d2c-abca-fd27bae6f05b","price_dollars":"0.4300","delta_fp":"100.00","side":"yes","ts":"2026-09-13T23:46:06.597888Z","ts_ms":1789343166597}}
{"type":"orderbook_delta","sid":1,"seq":345,"msg":{"market_ticker":"KXBTCD-26SEP1417-T76999.99","market_id":"9fc30aa6-9f6f-4d2c-abca-fd27bae6f05b","price_dollars":"0.5400","delta_fp":"-100.00","side":"no","ts":"2026-09-13T23:46:06.677923Z","ts_ms":1789343166677}}
{"type":"orderbook_delta","sid":1,"seq":346,"msg":{"market_ticker":"KXBTCD-26SEP1417-T76999.99","market_id":"9fc30aa6-9f6f-4d2c-abca-fd27bae6f05b","price_dollars":"0.4900","delta_fp":"100.00","side":"no","ts":"2026-09-13T23:46:06.677923Z","ts_ms":1789343166677}}
{"type":"orderbook_delta","sid":1,"seq":347,"msg":{"market_ticker":"KXBTCD-26SEP1417-T76999.99","market_id":"9fc30aa6-9f6f-4d2c-abca-fd27bae6f05b","price_dollars":"0.5300","delta_fp":"30.00","side":"no","ts":"2026-09-13T23:46:06.699582Z","ts_ms":1789343166699}}
{"type":"orderbook_delta","sid":1,"seq":348,"msg":{"market_ticker":"KXBTCD-26SEP1417-T76999.99","market_id":"9fc30aa6-9f6f-4d2c-abca-fd27bae6f05b","price_dollars":"0.4300","delta_fp":"-100.00","side":"yes","ts":"2026-09-13T23:46:06.702661Z","ts_ms":1789343166702}}
{"type":"orderbook_delta","sid":1,"seq":349,"msg":{"market_ticker":"KXBTCD-26SEP1417-T76999.99","market_id":"9fc30aa6-9f6f-4d2c-abca-fd27bae6f05b","price_dollars":"0.4400","delta_fp":"100.00","side":"yes","ts":"2026-09-13T23:46:06.702661Z","ts_ms":1789343166702}}
{"type":"orderbook_delta","sid":1,"seq":350,"msg":{"market_ticker":"KXBTCD-26SEP1417-T76999.99","market_id":"9fc30aa6-9f6f-4d2c-abca-fd27bae6f05b","price_dollars":"0.4400","delta_fp":"5.00","side":"yes","ts":"2026-09-13T23:46:06.719893Z","ts_ms":1789343166719}}
{"type":"orderbook_delta","sid":1,"seq":351,"msg":{"market_ticker":"KXBTCD-26SEP1417-T76999.99","market_id":"9fc30aa6-9f6f-4d2c-abca-fd27bae6f05b","price_dollars":"0.4300","delta_fp":"-30.00","side":"yes","ts":"2026-09-13T23:46:06.726831Z","ts_ms":1789343166726}}
{"type":"orderbook_delta","sid":1,"seq":352,"msg":{"market_ticker":"KXBTCD-26SEP1417-T76999.99","market_id":"9fc30aa6-9f6f-4d2c-abca-fd27bae6f05b","price_dollars":"0.4100","delta_fp":"-568.00","side":"yes","ts":"2026-09-13T23:46:06.732207Z","ts_ms":1789343166732}}
{"type":"orderbook_delta","sid":1,"seq":353,"msg":{"market_ticker":"KXBTCD-26SEP1417-T76999.99","market_id":"9fc30aa6-9f6f-4d2c-abca-fd27bae6f05b","price_dollars":"0.4400","delta_fp":"566.00","side":"yes","ts":"2026-09-13T23:46:06.765073Z","ts_ms":1789343166765}}
{"type":"orderbook_delta","sid":1,"seq":354,"msg":{"market_ticker":"KXBTCD-26SEP1417-T76999.99","market_id":"9fc30aa6-9f6f-4d2c-abca-fd27bae6f05b","price_dollars":"0.4100","delta_fp":"-5000.00","side":"yes","ts":"2026-09-13T23:46:06.770046Z","ts_ms":1789343166770}}
{"type":"orderbook_delta","sid":1,"seq":355,"msg":{"market_ticker":"KXBTCD-26SEP1417-T76999.99","market_id":"9fc30aa6-9f6f-4d2c-abca-fd27bae6f05b","price_dollars":"0.4300","delta_fp":"-3000.00","side":"yes","ts":"2026-09-13T23:46:06.772562Z","ts_ms":1789343166772}}
{"type":"orderbook_delta","sid":1,"seq":356,"msg":{"market_ticker":"KXBTCD-26SEP1417-T76999.99","market_id":"9fc30aa6-9f6f-4d2c-abca-fd27bae6f05b","price_dollars":"0.4400","delta_fp":"3000.00","side":"yes","ts":"2026-09-13T23:46:06.772562Z","ts_ms":1789343166772}}
{"type":"orderbook_delta","sid":1,"seq":357,"msg":{"market_ticker":"KXBTCD-26SEP1417-T76999.99","market_id":"9fc30aa6-9f6f-4d2c-abca-fd27bae6f05b","price_dollars":"0.4900","delta_fp":"-100.00","side":"no","ts":"2026-09-13T23:46:06.779661Z","ts_ms":1789343166779}}
{"type":"orderbook_delta","sid":1,"seq":358,"msg":{"market_ticker":"KXBTCD-26SEP1417-T76999.99","market_id":"9fc30aa6-9f6f-4d2c-abca-fd27bae6f05b","price_dollars":"0.5400","delta_fp":"100.00","side":"no","ts":"2026-09-13T23:46:06.779661Z","ts_ms":1789343166779}}
{"type":"orderbook_delta","sid":1,"seq":359,"msg":{"market_ticker":"KXBTCD-26SEP1417-T76999.99","market_id":"9fc30aa6-9f6f-4d2c-abca-fd27bae6f05b","price_dollars":"0.5400","delta_fp":"-100.00","side":"no","ts":"2026-09-13T23:46:06.790379Z","ts_ms":1789343166790}}
{"type":"orderbook_delta","sid":1,"seq":360,"msg":{"market_ticker":"KXBTCD-26SEP1417-T76999.99","market_id":"9fc30aa6-9f6f-4d2c-abca-fd27bae6f05b","price_dollars":"0.4900","delta_fp":"100.00","side":"no","ts":"2026-09-13T23:46:06.790379Z","ts_ms":1789343166790}}
{"type":"orderbook_delta","sid":1,"seq":361,"msg":{"market_ticker":"KXBTCD-26SEP1417-T76999.99","market_id":"9fc30aa6-9f6f-4d2c-abca-fd27bae6f05b","price_dollars":"0.5300","delta_fp":"-30.00","side":"no","ts":"2026-09-13T23:46:06.808095Z","ts_ms":1789343166808}}
{"type":"orderbook_delta","sid":1,"seq":362,"msg":{"market_ticker":"KXBTCD-26SEP1417-T76999.99","market_id":"9fc30aa6-9f6f-4d2c-abca-fd27bae6f05b","price_dollars":"0.5300","delta_fp":"30.00","side":"no","ts":"2026-09-13T23:46:06.835015Z","ts_ms":1789343166835}}
{"type":"orderbook_delta","sid":1,"seq":363,"msg":{"market_ticker":"KXBTCD-26SEP1417-T76999.99","market_id":"9fc30aa6-9f6f-4d2c-abca-fd27bae6f05b","price_dollars":"0.4900","delta_fp":"-100.00","side":"no","ts":"2026-09-13T23:46:06.897025Z","ts_ms":1789343166897}}
{"type":"orderbook_delta","sid":1,"seq":364,"msg":{"market_ticker":"KXBTCD-26SEP1417-T76999.99","market_id":"9fc30aa6-9f6f-4d2c-abca-fd27bae6f05b","price_dollars":"0.5300","delta_fp":"100.00","side":"no","ts":"2026-09-13T23:46:06.897025Z","ts_ms":1789343166897}}
{"type":"orderbook_delta","sid":1,"seq":365,"msg":{"market_ticker":"KXBTCD-26SEP1417-T76999.99","market_id":"9fc30aa6-9f6f-4d2c-abca-fd27bae6f05b","price_dollars":"0.4400","delta_fp":"187.00","side":"yes","ts":"2026-09-13T23:46:06.991785Z","ts_ms":1789343166991}}
{"type":"orderbook_delta","sid":1,"seq":366,"msg":{"market_ticker":"KXBTCD-26SEP1417-T76999.99","market_id":"9fc30aa6-9f6f-4d2c-abca-fd27bae6f05b","price_dollars":"0.4300","delta_fp":"-568.00","side":"yes","ts":"2026-09-13T23:46:06.99276Z","ts_ms":1789343166992}}
{"type":"orderbook_delta","sid":1,"seq":367,"msg":{"market_ticker":"KXBTCD-26SEP1417-T76999.99","market_id":"9fc30aa6-9f6f-4d2c-abca-fd27bae6f05b","price_dollars":"0.5300","delta_fp":"-100.00","side":"no","ts":"2026-09-13T23:46:06.997867Z","ts_ms":1789343166997}}
{"type":"orderbook_delta","sid":1,"seq":368,"msg":{"market_ticker":"KXBTCD-26SEP1417-T76999.99","market_id":"9fc30aa6-9f6f-4d2c-abca-fd27bae6f05b","price_dollars":"0.5400","delta_fp":"100.00","side":"no","ts":"2026-09-13T23:46:06.997867Z","ts_ms":1789343166997}}
{"type":"orderbook_delta","sid":1,"seq":369,"msg":{"market_ticker":"KXBTCD-26SEP1417-T76999.99","market_id":"9fc30aa6-9f6f-4d2c-abca-fd27bae6f05b","price_dollars":"0.5300","delta_fp":"-30.00","side":"no","ts":"2026-09-13T23:46:07.018337Z","ts_ms":1789343167018}}
{"type":"orderbook_delta","sid":1,"seq":370,"msg":{"market_ticker":"KXBTCD-26SEP1417-T76999.99","market_id":"9fc30aa6-9f6f-4d2c-abca-fd27bae6f05b","price_dollars":"0.5200","delta_fp":"-462.00","side":"no","ts":"2026-09-13T23:46:07.018504Z","ts_ms":1789343167018}}
{"type":"orderbook_delta","sid":1,"seq":371,"msg":{"market_ticker":"KXBTCD-26SEP1417-T76999.99","market_id":"9fc30aa6-9f6f-4d2c-abca-fd27bae6f05b","price_dollars":"0.4400","delta_fp":"-566.00","side":"yes","ts":"2026-09-13T23:46:07.036998Z","ts_ms":1789343167036}}
{"type":"orderbook_delta","sid":1,"seq":372,"msg":{"market_ticker":"KXBTCD-26SEP1417-T76999.99","market_id":"9fc30aa6-9f6f-4d2c-abca-fd27bae6f05b","price_dollars":"0.4500","delta_fp":"564.00","side":"yes","ts":"2026-09-13T23:46:07.040123Z","ts_ms":1789343167040}}
{"type":"orderbook_delta","sid":1,"seq":373,"msg":{"market_ticker":"KXBTCD-26SEP1417-T76999.99","market_id":"9fc30aa6-9f6f-4d2c-abca-fd27bae6f05b","price_dollars":"0.4300","delta_fp":"-2.00","side":"yes","ts":"2026-09-13T23:46:07.062057Z","ts_ms":1789343167062}}
{"type":"orderbook_delta","sid":1,"seq":374,"msg":{"market_ticker":"KXBTCD-26SEP1417-T76999.99","market_id":"9fc30aa6-9f6f-4d2c-abca-fd27bae6f05b","price_dollars":"0.4400","delta_fp":"2.00","side":"yes","ts":"2026-09-13T23:46:07.062448Z","ts_ms":1789343167062}}
{"type":"orderbook_delta","sid":1,"seq":375,"msg":{"market_ticker":"KXBTCD-26SEP1417-T76999.99","market_id":"9fc30aa6-9f6f-4d2c-abca-fd27bae6f05b","price_dollars":"0.4400","delta_fp":"-2.00","side":"yes","ts":"2026-09-13T23:46:07.714377Z","ts_ms":1789343167714}}
{"type":"orderbook_delta","sid":1,"seq":376,"msg":{"market_ticker":"KXBTCD-26SEP1417-T76999.99","market_id":"9fc30aa6-9f6f-4d2c-abca-fd27bae6f05b","price_dollars":"0.4400","delta_fp":"2.00","side":"yes","ts":"2026-09-13T23:46:07.801136Z","ts_ms":1789343167801}}
{"type":"orderbook_delta","sid":1,"seq":377,"msg":{"market_ticker":"KXBTCD-26SEP1417-T76999.99","market_id":"9fc30aa6-9f6f-4d2c-abca-fd27bae6f05b","price_dollars":"0.2900","delta_fp":"-3369.00","side":"no","ts":"2026-09-13T23:46:07.94405Z","ts_ms":1789343167944}}
{"type":"orderbook_delta","sid":1,"seq":378,"msg":{"market_ticker":"KXBTCD-26SEP1417-T76999.99","market_id":"9fc30aa6-9f6f-4d2c-abca-fd27bae6f05b","price_dollars":"0.2800","delta_fp":"3489.00","side":"no","ts":"2026-09-13T23:46:07.94405Z","ts_ms":1789343167944}}
{"type":"orderbook_delta","sid":1,"seq":379,"msg":{"market_ticker":"KXBTCD-26SEP1417-T76999.99","market_id":"9fc30aa6-9f6f-4d2c-abca-fd27bae6f05b","price_dollars":"0.3900","delta_fp":"-4.00","side":"yes","ts":"2026-09-13T23:46:08.597436Z","ts_ms":1789343168597}}
{"type":"orderbook_delta","sid":1,"seq":380,"msg":{"market_ticker":"KXBTCD-26SEP1417-T76999.99","market_id":"9fc30aa6-9f6f-4d2c-abca-fd27bae6f05b","price_dollars":"0.2800","delta_fp":"-144.00","side":"no","ts":"2026-09-13T23:46:08.607673Z","ts_ms":1789343168607}}
{"type":"orderbook_delta","sid":1,"seq":381,"msg":{"market_ticker":"KXBTCD-26SEP1417-T76999.99","market_id":"9fc30aa6-9f6f-4d2c-abca-fd27bae6f05b","price_dollars":"0.2700","delta_fp":"-217.00","side":"no","ts":"2026-09-13T23:46:08.609018Z","ts_ms":1789343168609}}
{"type":"orderbook_delta","sid":1,"seq":382,"msg":{"market_ticker":"KXBTCD-26SEP1417-T76999.99","market_id":"9fc30aa6-9f6f-4d2c-abca-fd27bae6f05b","price_dollars":"0.1700","delta_fp":"203.00","side":"no","ts":"2026-09-13T23:46:08.60963Z","ts_ms":1789343168609}}
{"type":"orderbook_delta","sid":1,"seq":383,"msg":{"market_ticker":"KXBTCD-26SEP1417-T76999.99","market_id":"9fc30aa6-9f6f-4d2c-abca-fd27bae6f05b","price_dollars":"0.1800","delta_fp":"148.00","side":"no","ts":"2026-09-13T23:46:08.610244Z","ts_ms":1789343168610}}
{"type":"orderbook_delta","sid":1,"seq":384,"msg":{"market_ticker":"KXBTCD-26SEP1417-T76999.99","market_id":"9fc30aa6-9f6f-4d2c-abca-fd27bae6f05b","price_dollars":"0.4100","delta_fp":"4.00","side":"yes","ts":"2026-09-13T23:46:08.642906Z","ts_ms":1789343168642}}
{"type":"orderbook_delta","sid":1,"seq":385,"msg":{"market_ticker":"KXBTCD-26SEP1417-T76999.99","market_id":"9fc30aa6-9f6f-4d2c-abca-fd27bae6f05b","price_dollars":"0.0200","delta_fp":"-26057.00","side":"no","ts":"2026-09-13T23:46:08.688181Z","ts_ms":1789343168688}}
{"type":"orderbook_delta","sid":1,"seq":386,"msg":{"market_ticker":"KXBTCD-26SEP1417-T76999.99","market_id":"9fc30aa6-9f6f-4d2c-abca-fd27bae6f05b","price_dollars":"0.0800","delta_fp":"-5700.00","side":"no","ts":"2026-09-13T23:46:08.688629Z","ts_ms":1789343168688}}
{"type":"orderbook_delta","sid":1,"seq":387,"msg":{"market_ticker":"KXBTCD-26SEP1417-T76999.99","market_id":"9fc30aa6-9f6f-4d2c-abca-fd27bae6f05b","price_dollars":"0.1600","delta_fp":"-8549.00","side":"no","ts":"2026-09-13T23:46:08.689003Z","ts_ms":1789343168689}}
{"type":"orderbook_delta","sid":1,"seq":388,"msg":{"market_ticker":"KXBTCD-26SEP1417-T76999.99","market_id":"9fc30aa6-9f6f-4d2c-abca-fd27bae6f05b","price_dollars":"0.2800","delta_fp":"-3489.00","side":"no","ts":"2026-09-13T23:46:08.695781Z","ts_ms":1789343168695}}
{"type":"orderbook_delta","sid":1,"seq":389,"msg":{"market_ticker":"KXBTCD-26SEP1417-T76999.99","market_id":"9fc30aa6-9f6f-4d2c-abca-fd27bae6f05b","price_dollars":"0.2600","delta_fp":"3758.00","side":"no","ts":"2026-09-13T23:46:08.695781Z","ts_ms":1789343168695}}
{"type":"orderbook_delta","sid":1,"seq":390,"msg":{"market_ticker":"KXBTCD-26SEP1417-T76999.99","market_id":"9fc30aa6-9f6f-4d2c-abca-fd27bae6f05b","price_dollars":"0.4200","delta_fp":"5000.00","side":"yes","ts":"2026-09-13T23:46:08.964196Z","ts_ms":1789343168964}}
{"type":"orderbook_delta","sid":1,"seq":391,"msg":{"market_ticker":"KXBTCD-26SEP1417-T76999.99","market_id":"9fc30aa6-9f6f-4d2c-abca-fd27bae6f05b","price_dollars":"0.5200","delta_fp":"5000.00","side":"no","ts":"2026-09-13T23:46:09.271762Z","ts_ms":1789343169271}}
{"type":"orderbook_delta","sid":1,"seq":392,"msg":{"market_ticker":"KXBTCD-26SEP1417-T76999.99","market_id":"9fc30aa6-9f6f-4d2c-abca-fd27bae6f05b","price_dollars":"0.4500","delta_fp":"-564.00","side":"yes","ts":"2026-09-13T23:46:09.736242Z","ts_ms":1789343169736}}
{"type":"orderbook_delta","sid":1,"seq":393,"msg":{"market_ticker":"KXBTCD-26SEP1417-T76999.99","market_id":"9fc30aa6-9f6f-4d2c-abca-fd27bae6f05b","price_dollars":"0.5400","delta_fp":"-100.00","side":"no","ts":"2026-09-13T23:46:09.746039Z","ts_ms":1789343169746}}
{"type":"orderbook_delta","sid":1,"seq":394,"msg":{"market_ticker":"KXBTCD-26SEP1417-T76999.99","market_id":"9fc30aa6-9f6f-4d2c-abca-fd27bae6f05b","price_dollars":"0.4900","delta_fp":"100.00","side":"no","ts":"2026-09-13T23:46:09.746039Z","ts_ms":1789343169746}}
{"type":"orderbook_delta","sid":1,"seq":395,"msg":{"market_ticker":"KXBTCD-26SEP1417-T76999.99","market_id":"9fc30aa6-9f6f-4d2c-abca-fd27bae6f05b","price_dollars":"0.4300","delta_fp":"567.00","side":"yes","ts":"2026-09-13T23:46:09.755396Z","ts_ms":1789343169755}}
{"type":"orderbook_delta","sid":1,"seq":396,"msg":{"market_ticker":"KXBTCD-26SEP1417-T76999.99","market_id":"9fc30aa6-9f6f-4d2c-abca-fd27bae6f05b","price_dollars":"0.4900","delta_fp":"-100.00","side":"no","ts":"2026-09-13T23:46:09.853416Z","ts_ms":1789343169853}}
{"type":"orderbook_delta","sid":1,"seq":397,"msg":{"market_ticker":"KXBTCD-26SEP1417-T76999.99","market_id":"9fc30aa6-9f6f-4d2c-abca-fd27bae6f05b","price_dollars":"0.5300","delta_fp":"100.00","side":"no","ts":"2026-09-13T23:46:09.853416Z","ts_ms":1789343169853}}
{"type":"orderbook_delta","sid":1,"seq":398,"msg":{"market_ticker":"KXBTCD-26SEP1417-T76999.99","market_id":"9fc30aa6-9f6f-4d2c-abca-fd27bae6f05b","price_dollars":"0.4300","delta_fp":"-1000.00","side":"yes","ts":"2026-09-13T23:46:12.989024Z","ts_ms":1789343172989}}
{"type":"orderbook_delta","sid":1,"seq":399,"msg":{"market_ticker":"KXBTCD-26SEP1417-T76999.99","market_id":"9fc30aa6-9f6f-4d2c-abca-fd27bae6f05b","price_dollars":"0.4400","delta_fp":"1000.00","side":"yes","ts":"2026-09-13T23:46:12.989024Z","ts_ms":1789343172989}}
{"type":"orderbook_delta","sid":1,"seq":400,"msg":{"market_ticker":"KXBTCD-26SEP1417-T76999.99","market_id":"9fc30aa6-9f6f-4d2c-abca-fd27bae6f05b","price_dollars":"0.4300","delta_fp":"-1000.00","side":"yes","ts":"2026-09-13T23:46:12.993335Z","ts_ms":1789343172993}}
{"type":"orderbook_delta","sid":1,"seq":401,"msg":{"market_ticker":"KXBTCD-26SEP1417-T76999.99","market_id":"9fc30aa6-9f6f-4d2c-abca-fd27bae6f05b","price_dollars":"0.4400","delta_fp":"1000.00","side":"yes","ts":"2026-09-13T23:46:12.993335Z","ts_ms":1789343172993}}
{"type":"orderbook_delta","sid":1,"seq":402,"msg":{"market_ticker":"KXBTCD-26SEP1417-T76999.99","market_id":"9fc30aa6-9f6f-4d2c-abca-fd27bae6f05b","price_dollars":"0.5300","delta_fp":"-1000.00","side":"no","ts":"2026-09-13T23:46:13.000542Z","ts_ms":1789343173000}}
{"type":"orderbook_delta","sid":1,"seq":403,"msg":{"market_ticker":"KXBTCD-26SEP1417-T76999.99","market_id":"9fc30aa6-9f6f-4d2c-abca-fd27bae6f05b","price_dollars":"0.5200","delta_fp":"1000.00","side":"no","ts":"2026-09-13T23:46:13.000542Z","ts_ms":1789343173000}}
{"type":"orderbook_delta","sid":1,"seq":404,"msg":{"market_ticker":"KXBTCD-26SEP1417-T76999.99","market_id":"9fc30aa6-9f6f-4d2c-abca-fd27bae6f05b","price_dollars":"0.4300","delta_fp":"-1000.00","side":"yes","ts":"2026-09-13T23:46:13.007541Z","ts_ms":1789343173007}}
{"type":"orderbook_delta","sid":1,"seq":405,"msg":{"market_ticker":"KXBTCD-26SEP1417-T76999.99","market_id":"9fc30aa6-9f6f-4d2c-abca-fd27bae6f05b","price_dollars":"0.4400","delta_fp":"1000.00","side":"yes","ts":"2026-09-13T23:46:13.007541Z","ts_ms":1789343173007}}
{"type":"orderbook_delta","sid":1,"seq":406,"msg":{"market_ticker":"KXBTCD-26SEP1417-T76999.99","market_id":"9fc30aa6-9f6f-4d2c-abca-fd27bae6f05b","price_dollars":"0.5300","delta_fp":"-1000.00","side":"no","ts":"2026-09-13T23:46:13.013504Z","ts_ms":1789343173013}}
{"type":"orderbook_delta","sid":1,"seq":407,"msg":{"market_ticker":"KXBTCD-26SEP1417-T76999.99","market_id":"9fc30aa6-9f6f-4d2c-abca-fd27bae6f05b","price_dollars":"0.5200","delta_fp":"1000.00","side":"no","ts":"2026-09-13T23:46:13.013504Z","ts_ms":1789343173013}}
{"type":"orderbook_delta","sid":1,"seq":408,"msg":{"market_ticker":"KXBTCD-26SEP1417-T76999.99","market_id":"9fc30aa6-9f6f-4d2c-abca-fd27bae6f05b","price_dollars":"0.4400","delta_fp":"187.00","side":"yes","ts":"2026-09-13T23:46:13.1866Z","ts_ms":1789343173186}}
{"type":"orderbook_delta","sid":1,"seq":409,"msg":{"market_ticker":"KXBTCD-26SEP1417-T76999.99","market_id":"9fc30aa6-9f6f-4d2c-abca-fd27bae6f05b","price_dollars":"0.4300","delta_fp":"-567.00","side":"yes","ts":"2026-09-13T23:46:13.187364Z","ts_ms":1789343173187}}
{"type":"orderbook_delta","sid":1,"seq":410,"msg":{"market_ticker":"KXBTCD-26SEP1417-T76999.99","market_id":"9fc30aa6-9f6f-4d2c-abca-fd27bae6f05b","price_dollars":"0.4500","delta_fp":"564.00","side":"yes","ts":"2026-09-13T23:46:15.815893Z","ts_ms":1789343175815}}
{"type":"orderbook_delta","sid":1,"seq":411,"msg":{"market_ticker":"KXBTCD-26SEP1417-T76999.99","market_id":"9fc30aa6-9f6f-4d2c-abca-fd27bae6f05b","price_dollars":"0.4400","delta_fp":"-187.00","side":"yes","ts":"2026-09-13T23:46:15.816285Z","ts_ms":1789343175816}}
{"type":"orderbook_delta","sid":1,"seq":412,"msg":{"market_ticker":"KXBTCD-26SEP1417-T76999.99","market_id":"9fc30aa6-9f6f-4d2c-abca-fd27bae6f05b","price_dollars":"0.3400","delta_fp":"-50.00","side":"yes","ts":"2026-09-13T23:46:15.89674Z","ts_ms":1789343175896}}
{"type":"orderbook_delta","sid":1,"seq":413,"msg":{"market_ticker":"KXBTCD-26SEP1417-T76999.99","market_id":"9fc30aa6-9f6f-4d2c-abca-fd27bae6f05b","price_dollars":"0.4300","delta_fp":"50.00","side":"yes","ts":"2026-09-13T23:46:15.898644Z","ts_ms":1789343175898}}
{"type":"orderbook_delta","sid":1,"seq":414,"msg":{"market_ticker":"KXBTCD-26SEP1417-T76999.99","market_id":"9fc30aa6-9f6f-4d2c-abca-fd27bae6f05b","price_dollars":"0.5100","delta_fp":"-50.00","side":"no","ts":"2026-09-13T23:46:15.899814Z","ts_ms":1789343175899}}
{"type":"orderbook_delta","sid":1,"seq":415,"msg":{"market_ticker":"KXBTCD-26SEP1417-T76999.99","market_id":"9fc30aa6-9f6f-4d2c-abca-fd27bae6f05b","price_dollars":"0.4200","delta_fp":"50.00","side":"no","ts":"2026-09-13T23:46:15.901169Z","ts_ms":1789343175901}}
{"type":"orderbook_delta","sid":1,"seq":416,"msg":{"market_ticker":"KXBTCD-26SEP1417-T76999.99","market_id":"9fc30aa6-9f6f-4d2c-abca-fd27bae6f05b","price_dollars":"0.4300","delta_fp":"-50.00","side":"yes","ts":"2026-09-13T23:46:16.086156Z","ts_ms":1789343176086}}
{"type":"orderbook_delta","sid":1,"seq":417,"msg":{"market_ticker":"KXBTCD-26SEP1417-T76999.99","market_id":"9fc30aa6-9f6f-4d2c-abca-fd27bae6f05b","price_dollars":"0.3400","delta_fp":"50.00","side":"yes","ts":"2026-09-13T23:46:16.087385Z","ts_ms":1789343176087}}
{"type":"orderbook_delta","sid":1,"seq":418,"msg":{"market_ticker":"KXBTCD-26SEP1417-T76999.99","market_id":"9fc30aa6-9f6f-4d2c-abca-fd27bae6f05b","price_dollars":"0.4200","delta_fp":"-50.00","side":"no","ts":"2026-09-13T23:46:16.088588Z","ts_ms":1789343176088}}
{"type":"orderbook_delta","sid":1,"seq":419,"msg":{"market_ticker":"KXBTCD-26SEP1417-T76999.99","market_id":"9fc30aa6-9f6f-4d2c-abca-fd27bae6f05b","price_dollars":"0.5100","delta_fp":"50.00","side":"no","ts":"2026-09-13T23:46:16.090042Z","ts_ms":1789343176090}}
{"type":"orderbook_delta","sid":1,"seq":420,"msg":{"market_ticker":"KXBTCD-26SEP1417-T76999.99","market_id":"9fc30aa6-9f6f-4d2c-abca-fd27bae6f05b","price_dollars":"0.5200","delta_fp":"-1000.00","side":"no","ts":"2026-09-13T23:46:16.420957Z","ts_ms":1789343176420}}
{"type":"orderbook_delta","sid":1,"seq":421,"msg":{"market_ticker":"KXBTCD-26SEP1417-T76999.99","market_id":"9fc30aa6-9f6f-4d2c-abca-fd27bae6f05b","price_dollars":"0.5300","delta_fp":"1000.00","side":"no","ts":"2026-09-13T23:46:16.420957Z","ts_ms":1789343176420}}
{"type":"orderbook_delta","sid":1,"seq":422,"msg":{"market_ticker":"KXBTCD-26SEP1417-T76999.99","market_id":"9fc30aa6-9f6f-4d2c-abca-fd27bae6f05b","price_dollars":"0.5300","delta_fp":"-100.00","side":"no","ts":"2026-09-13T23:46:16.428245Z","ts_ms":1789343176428}}
{"type":"orderbook_delta","sid":1,"seq":423,"msg":{"market_ticker":"KXBTCD-26SEP1417-T76999.99","market_id":"9fc30aa6-9f6f-4d2c-abca-fd27bae6f05b","price_dollars":"0.5400","delta_fp":"100.00","side":"no","ts":"2026-09-13T23:46:16.428245Z","ts_ms":1789343176428}}
{"type":"orderbook_delta","sid":1,"seq":424,"msg":{"market_ticker":"KXBTCD-26SEP1417-T76999.99","market_id":"9fc30aa6-9f6f-4d2c-abca-fd27bae6f05b","price_dollars":"0.5300","delta_fp":"-1000.00","side":"no","ts":"2026-09-13T23:46:16.434775Z","ts_ms":1789343176434}}
{"type":"orderbook_delta","sid":1,"seq":425,"msg":{"market_ticker":"KXBTCD-26SEP1417-T76999.99","market_id":"9fc30aa6-9f6f-4d2c-abca-fd27bae6f05b","price_dollars":"0.5400","delta_fp":"-100.00","side":"no","ts":"2026-09-13T23:46:16.442259Z","ts_ms":1789343176442}}
{"type":"orderbook_delta","sid":1,"seq":426,"msg":{"market_ticker":"KXBTCD-26SEP1417-T76999.99","market_id":"9fc30aa6-9f6f-4d2c-abca-fd27bae6f05b","price_dollars":"0.4900","delta_fp":"100.00","side":"no","ts":"2026-09-13T23:46:16.442259Z","ts_ms":1789343176442}}
{"type":"orderbook_delta","sid":1,"seq":427,"msg":{"market_ticker":"KXBTCD-26SEP1417-T76999.99","market_id":"9fc30aa6-9f6f-4d2c-abca-fd27bae6f05b","price_dollars":"0.4500","delta_fp":"-564.00","side":"yes","ts":"2026-09-13T23:46:16.474534Z","ts_ms":1789343176474}}
{"type":"orderbook_delta","sid":1,"seq":428,"msg":{"market_ticker":"KXBTCD-26SEP1417-T76999.99","market_id":"9fc30aa6-9f6f-4d2c-abca-fd27bae6f05b","price_dollars":"0.4300","delta_fp":"566.00","side":"yes","ts":"2026-09-13T23:46:16.476961Z","ts_ms":1789343176476}}
{"type":"orderbook_delta","sid":1,"seq":429,"msg":{"market_ticker":"KXBTCD-26SEP1417-T76999.99","market_id":"9fc30aa6-9f6f-4d2c-abca-fd27bae6f05b","price_dollars":"0.5200","delta_fp":"1000.00","side":"no","ts":"2026-09-13T23:46:16.483618Z","ts_ms":1789343176483}}
{"type":"orderbook_delta","sid":1,"seq":430,"msg":{"market_ticker":"KXBTCD-26SEP1417-T76999.99","market_id":"9fc30aa6-9f6f-4d2c-abca-fd27bae6f05b","price_dollars":"0.4900","delta_fp":"-100.00","side":"no","ts":"2026-09-13T23:46:16.546819Z","ts_ms":1789343176546}}
{"type":"orderbook_delta","sid":1,"seq":431,"msg":{"market_ticker":"KXBTCD-26SEP1417-T76999.99","market_id":"9fc30aa6-9f6f-4d2c-abca-fd27bae6f05b","price_dollars":"0.5300","delta_fp":"100.00","side":"no","ts":"2026-09-13T23:46:16.546819Z","ts_ms":1789343176546}}
{"type":"orderbook_delta","sid":1,"seq":432,"msg":{"market_ticker":"KXBTCD-26SEP1417-T76999.99","market_id":"9fc30aa6-9f6f-4d2c-abca-fd27bae6f05b","price_dollars":"0.4400","delta_fp":"187.00","side":"yes","ts":"2026-09-13T23:46:16.648045Z","ts_ms":1789343176648}}
{"type":"orderbook_delta","sid":1,"seq":433,"msg":{"market_ticker":"KXBTCD-26SEP1417-T76999.99","market_id":"9fc30aa6-9f6f-4d2c-abca-fd27bae6f05b","price_dollars":"0.4300","delta_fp":"-566.00","side":"yes","ts":"2026-09-13T23:46:16.651696Z","ts_ms":1789343176651}}
{"type":"orderbook_delta","sid":1,"seq":434,"msg":{"market_ticker":"KXBTCD-26SEP1417-T76999.99","market_id":"9fc30aa6-9f6f-4d2c-abca-fd27bae6f05b","price_dollars":"0.5200","delta_fp":"-1000.00","side":"no","ts":"2026-09-13T23:46:18.932403Z","ts_ms":1789343178932}}
{"type":"orderbook_delta","sid":1,"seq":435,"msg":{"market_ticker":"KXBTCD-26SEP1417-T76999.99","market_id":"9fc30aa6-9f6f-4d2c-abca-fd27bae6f05b","price_dollars":"0.5300","delta_fp":"1000.00","side":"no","ts":"2026-09-13T23:46:18.932403Z","ts_ms":1789343178932}}
{"type":"orderbook_delta","sid":1,"seq":436,"msg":{"market_ticker":"KXBTCD-26SEP1417-T76999.99","market_id":"9fc30aa6-9f6f-4d2c-abca-fd27bae6f05b","price_dollars":"0.4400","delta_fp":"-1000.00","side":"yes","ts":"2026-09-13T23:46:18.936568Z","ts_ms":1789343178936}}
{"type":"orderbook_delta","sid":1,"seq":437,"msg":{"market_ticker":"KXBTCD-26SEP1417-T76999.99","market_id":"9fc30aa6-9f6f-4d2c-abca-fd27bae6f05b","price_dollars":"0.4300","delta_fp":"1000.00","side":"yes","ts":"2026-09-13T23:46:18.936568Z","ts_ms":1789343178936}}
{"type":"orderbook_delta","sid":1,"seq":438,"msg":{"market_ticker":"KXBTCD-26SEP1417-T76999.99","market_id":"9fc30aa6-9f6f-4d2c-abca-fd27bae6f05b","price_dollars":"0.5200","delta_fp":"-1000.00","side":"no","ts":"2026-09-13T23:46:19.479591Z","ts_ms":1789343179479}}
{"type":"orderbook_delta","sid":1,"seq":439,"msg":{"market_ticker":"KXBTCD-26SEP1417-T76999.99","market_id":"9fc30aa6-9f6f-4d2c-abca-fd27bae6f05b","price_dollars":"0.5300","delta_fp":"1000.00","side":"no","ts":"2026-09-13T23:46:19.479591Z","ts_ms":1789343179479}}
{"type":"orderbook_delta","sid":1,"seq":440,"msg":{"market_ticker":"KXBTCD-26SEP1417-T76999.99","market_id":"9fc30aa6-9f6f-4d2c-abca-fd27bae6f05b","price_dollars":"0.5300","delta_fp":"-1000.00","side":"no","ts":"2026-09-13T23:46:19.490429Z","ts_ms":1789343179490}}
{"type":"orderbook_delta","sid":1,"seq":441,"msg":{"market_ticker":"KXBTCD-26SEP1417-T76999.99","market_id":"9fc30aa6-9f6f-4d2c-abca-fd27bae6f05b","price_dollars":"0.5200","delta_fp":"1000.00","side":"no","ts":"2026-09-13T23:46:19.490429Z","ts_ms":1789343179490}}
{"type":"orderbook_delta","sid":1,"seq":442,"msg":{"market_ticker":"KXBTCD-26SEP1417-T76999.99","market_id":"9fc30aa6-9f6f-4d2c-abca-fd27bae6f05b","price_dollars":"0.5300","delta_fp":"-1000.00","side":"no","ts":"2026-09-13T23:46:19.49274Z","ts_ms":1789343179492}}
{"type":"orderbook_delta","sid":1,"seq":443,"msg":{"market_ticker":"KXBTCD-26SEP1417-T76999.99","market_id":"9fc30aa6-9f6f-4d2c-abca-fd27bae6f05b","price_dollars":"0.4300","delta_fp":"-1000.00","side":"yes","ts":"2026-09-13T23:46:19.494212Z","ts_ms":1789343179494}}
{"type":"orderbook_delta","sid":1,"seq":444,"msg":{"market_ticker":"KXBTCD-26SEP1417-T76999.99","market_id":"9fc30aa6-9f6f-4d2c-abca-fd27bae6f05b","price_dollars":"0.4400","delta_fp":"1000.00","side":"yes","ts":"2026-09-13T23:46:19.494212Z","ts_ms":1789343179494}}
{"type":"orderbook_delta","sid":1,"seq":445,"msg":{"market_ticker":"KXBTCD-26SEP1417-T76999.99","market_id":"9fc30aa6-9f6f-4d2c-abca-fd27bae6f05b","price_dollars":"0.5300","delta_fp":"1000.00","side":"no","ts":"2026-09-13T23:46:20.085253Z","ts_ms":1789343180085}}
{"type":"orderbook_delta","sid":1,"seq":446,"msg":{"market_ticker":"KXBTCD-26SEP1417-T76999.99","market_id":"9fc30aa6-9f6f-4d2c-abca-fd27bae6f05b","price_dollars":"0.4400","delta_fp":"-1000.00","side":"yes","ts":"2026-09-13T23:46:20.093382Z","ts_ms":1789343180093}}
{"type":"orderbook_delta","sid":1,"seq":447,"msg":{"market_ticker":"KXBTCD-26SEP1417-T76999.99","market_id":"9fc30aa6-9f6f-4d2c-abca-fd27bae6f05b","price_dollars":"0.4300","delta_fp":"1000.00","side":"yes","ts":"2026-09-13T23:46:20.093382Z","ts_ms":1789343180093}}
{"type":"orderbook_delta","sid":1,"seq":448,"msg":{"market_ticker":"KXBTCD-26SEP1417-T76999.99","market_id":"9fc30aa6-9f6f-4d2c-abca-fd27bae6f05b","price_dollars":"0.5200","delta_fp":"-1000.00","side":"no","ts":"2026-09-13T23:46:20.097375Z","ts_ms":1789343180097}}
{"type":"orderbook_delta","sid":1,"seq":449,"msg":{"market_ticker":"KXBTCD-26SEP1417-T76999.99","market_id":"9fc30aa6-9f6f-4d2c-abca-fd27bae6f05b","price_dollars":"0.5300","delta_fp":"1000.00","side":"no","ts":"2026-09-13T23:46:20.097375Z","ts_ms":1789343180097}}
{"type":"orderbook_delta","sid":1,"seq":450,"msg":{"market_ticker":"KXBTCD-26SEP1417-T76999.99","market_id":"9fc30aa6-9f6f-4d2c-abca-fd27bae6f05b","price_dollars":"0.4400","delta_fp":"-1000.00","side":"yes","ts":"2026-09-13T23:46:20.0976Z","ts_ms":1789343180097}}
{"type":"orderbook_delta","sid":1,"seq":451,"msg":{"market_ticker":"KXBTCD-26SEP1417-T76999.99","market_id":"9fc30aa6-9f6f-4d2c-abca-fd27bae6f05b","price_dollars":"0.4300","delta_fp":"1000.00","side":"yes","ts":"2026-09-13T23:46:20.0976Z","ts_ms":1789343180097}}
{"type":"orderbook_delta","sid":1,"seq":452,"msg":{"market_ticker":"KXBTCD-26SEP1417-T76999.99","market_id":"9fc30aa6-9f6f-4d2c-abca-fd27bae6f05b","price_dollars":"0.4300","delta_fp":"566.00","side":"yes","ts":"2026-09-13T23:46:22.058686Z","ts_ms":1789343182058}}
{"type":"orderbook_delta","sid":1,"seq":453,"msg":{"market_ticker":"KXBTCD-26SEP1417-T76999.99","market_id":"9fc30aa6-9f6f-4d2c-abca-fd27bae6f05b","price_dollars":"0.4400","delta_fp":"-187.00","side":"yes","ts":"2026-09-13T23:46:22.060145Z","ts_ms":1789343182060}}
{"type":"orderbook_delta","sid":1,"seq":454,"msg":{"market_ticker":"KXBTCD-26SEP1417-T76999.99","market_id":"9fc30aa6-9f6f-4d2c-abca-fd27bae6f05b","price_dollars":"0.4400","delta_fp":"-100.00","side":"yes","ts":"2026-09-13T23:46:23.728291Z","ts_ms":1789343183728}}
{"type":"orderbook_delta","sid":1,"seq":455,"msg":{"market_ticker":"KXBTCD-26SEP1417-T76999.99","market_id":"9fc30aa6-9f6f-4d2c-abca-fd27bae6f05b","price_dollars":"0.5300","delta_fp":"-100.00","side":"no","ts":"2026-09-13T23:46:23.729587Z","ts_ms":1789343183729}}
{"type":"orderbook_delta","sid":1,"seq":456,"msg":{"market_ticker":"KXBTCD-26SEP1417-T76999.99","market_id":"9fc30aa6-9f6f-4d2c-abca-fd27bae6f05b","price_dollars":"0.4400","delta_fp":"100.00","side":"yes","ts":"2026-09-13T23:46:23.73866Z","ts_ms":1789343183738}}
{"type":"orderbook_delta","sid":1,"seq":457,"msg":{"market_ticker":"KXBTCD-26SEP1417-T76999.99","market_id":"9fc30aa6-9f6f-4d2c-abca-fd27bae6f05b","price_dollars":"0.5400","delta_fp":"100.00","side":"no","ts":"2026-09-13T23:46:23.740634Z","ts_ms":1789343183740}}
{"type":"orderbook_delta","sid":1,"seq":458,"msg":{"market_ticker":"KXBTCD-26SEP1417-T76999.99","market_id":"9fc30aa6-9f6f-4d2c-abca-fd27bae6f05b","price_dollars":"0.4400","delta_fp":"187.00","side":"yes","ts":"2026-09-13T23:46:23.760714Z","ts_ms":1789343183760}}
{"type":"orderbook_delta","sid":1,"seq":459,"msg":{"market_ticker":"KXBTCD-26SEP1417-T76999.99","market_id":"9fc30aa6-9f6f-4d2c-abca-fd27bae6f05b","price_dollars":"0.4300","delta_fp":"-566.00","side":"yes","ts":"2026-09-13T23:46:23.762503Z","ts_ms":1789343183762}}
{"type":"orderbook_delta","sid":1,"seq":460,"msg":{"market_ticker":"KXBTCD-26SEP1417-T76999.99","market_id":"9fc30aa6-9f6f-4d2c-abca-fd27bae6f05b","price_dollars":"0.4300","delta_fp":"566.00","side":"yes","ts":"2026-09-13T23:46:26.937285Z","ts_ms":1789343186937}}
{"type":"orderbook_delta","sid":1,"seq":461,"msg":{"market_ticker":"KXBTCD-26SEP1417-T76999.99","market_id":"9fc30aa6-9f6f-4d2c-abca-fd27bae6f05b","price_dollars":"0.4400","delta_fp":"-187.00","side":"yes","ts":"2026-09-13T23:46:26.939628Z","ts_ms":1789343186939}}
